<?xml version="1.0" ?>
<!-- =================================================================================== -->
<!-- |    This document was autogenerated by xacro from rolling_joint_model.urdf.xacro | -->
<!-- |    EDITING THIS FILE BY HAND IS NOT RECOMMENDED                                 | -->
<!-- =================================================================================== -->
<robot name="rolling_joint_model" xmlns:xacro="http://www.ros.org/wiki/xacro">
  <!-- Defaults are new in Indigo, so obviously they don't work in Kinetic -->
  <!-- <xacro:arg name="r0" default="0.2"/> -->
  <!-- <xacro:arg name="r1" default="0.1"/> -->
  <material name="grey">
    <color rgba="0.7 0.7 0.7 1"/>
  </material>
  <material name="black">
    <color rgba="0.0 0.0 0.0 1"/>
   </material>

   <!--dart needs world link in order to represent the base-->
  <link name="world"/>
  <joint name="world_joint" type="fixed">
        <parent link="world"/>
        <child link="link0"/>
        <origin xyz="0 0 0" rpy="0 0 0"/>
  </joint>

  <link name="link0">
    <inertial>
      <origin rpy="0 0 0" xyz="0 0 0.5"/>
      <mass value="10"/>
      <inertia ixx="0.1" ixy="0" ixz="0" iyy="0.1" iyz="0" izz="0.01"/>
    </inertial>
    <visual>
      <origin rpy="0 0 0" xyz="0 0 0.5"/>
      <geometry>
        <box size="0.2 0.2 1.0"/>
      </geometry>
      <material name="grey"/>
    </visual>
    <visual>
      <origin rpy="0 1.57079632679 0" xyz="0 0 1"/>
      <geometry>
        <cylinder length="0.2" radius="0.1"/>
      </geometry>
      <material name="grey"/>
    </visual>
  </link>
  <!--===========================Link 1===========================-->
  <joint name="joint_name__roll__j0" type="revolute">
    <origin rpy="0 0 0" xyz="0.000 0.000 1.000"/>
    <parent link="link0"/>
    <child link="link1"/>
    <axis xyz="1 0 0"/>
    <limit effort="100000" lower="-1.57079632679" upper="1.57079632679" velocity="100000"/>
  </joint>
  <link name="link1">
    <inertial>
      <origin rpy="0  0  0" xyz="0  0  0.1"/>
      <mass value="1"/>
      <inertia ixx="0.01" ixy="0" ixz="0" iyy="0.01" iyz="0" izz="0.001"/>
    </inertial>
    <visual>
      <origin rpy="0  0  0" xyz="0  0  0.1"/>
      <geometry>
        <box size="0.22  0.02  0.2"/>
      </geometry>
      <material name="black"/>
    </visual>
  </link>
  <!--===========================Link 2===========================-->
  <joint name="joint_name__roll__j1" type="revolute">
    <origin rpy="0 0 0" xyz="0  0  0.2"/>
    <parent link="link1"/>
    <child link="link2"/>
    <axis xyz="1 0 0"/>
    <limit effort="100000" lower="-1.57079632679" upper="1.57079632679" velocity="100000"/>
    <!-- <mimic joint="joint__roll__j0" multiplier="1.0"/> -->
  </joint>
  <link name="link2">
    <inertial>
      <origin rpy="0 0 0" xyz="0.000 0.000 0.250"/>
      <mass value="0.5"/>
      <inertia ixx="0.01" ixy="0" ixz="0" iyy="0.01" iyz="0" izz="0.001"/>
    </inertial>
    <visual>
      <origin rpy="0 1.57079632679 0" xyz="0 0 0"/>
      <geometry>
        <cylinder length="0.2" radius="0.1"/>
      </geometry>
      <material name="grey"/>
    </visual>
    <visual>
      <origin rpy="0  0  0" xyz="0.0  0.0  0.4"/>
      <geometry>
        <box size="0.2  0.2  0.8"/>
      </geometry>
      <material name="grey"/>
    </visual>
  </link>
  <!--===========================END EFFECTOR===========================-->
  <joint name="end_effector" type="fixed">
    <origin rpy="0  0  0" xyz="0.0  0.0  0.8"/>
    <parent link="link2"/>
    <child link="end_effector"/>
  </joint>
  <link name="end_effector">
    <inertial>
      <origin rpy="0 0 0" xyz="0.000 0.000 0.000"/>
      <mass value="1"/>
      <inertia ixx="0.001" ixy="0" ixz="0" iyy="0.01" iyz="0" izz="0.01"/>
    </inertial>
    <visual>
      <origin rpy="0.000 0.000 0.000" xyz="0.000 0.000 0.000"/>
      <geometry>
        <sphere radius="0.200"/>
      </geometry>
      <material name="black"/>
    </visual>
  </link>
</robot>

