<robot name="qdh_sim">
    <link name="world"/>
    <joint name="floating_base" type="floating">
        <parent link="world"/>
        <child link="Torso"/>
        <origin rpy="0 0 0" xyz="0 0 0"/>
    </joint>
    <link name="Torso">
        <visual>
            <origin xyz="0 0 0" rpy="0 -0 0"/>
            <geometry>
                <mesh filename="package://meshes/qdh/torso_link__list_0esqkzdovwypiw_handles_visual.stl"/>
            </geometry>
            <material name="torso_link__list_0esqkzdovwypiw_handles_material">
                <color rgba="0.825 0.825 0.825 1.0"/>
            </material>
        </visual>
        <collision>
            <origin xyz="0 0 0" rpy="0 -0 0"/>
            <geometry>
                <mesh filename="package://meshes/qdh/torso_link__list_0esqkzdovwypiw_handles_visual.stl"/>
            </geometry>
            <material name="torso_link__list_0esqkzdovwypiw_handles_material">
                <color rgba="0.825 0.825 0.825 1.0"/>
            </material>
        </collision>
        <inertial>
            <origin xyz="-0.0070853 -0.00077995 0.305367" rpy="0 0 0"/>
            <mass value="9.66101"/>
            <inertia ixx="0.210194" ixy="-0.000189954" ixz="0.000812552" iyy="0.159276" iyz="0.000880618" izz="0.0739857"/>
        </inertial>
    </link>
    <!--=============================== l_hip_ie (l_hip_ie_link) ===========================-->
    <joint name="l_hip_ie" type="revolute">
        <origin xyz="-6.73073e-16 0.125 4.14512e-15" rpy="4.17028e-15 9.52016e-15 2.63721e-15"/>
        <parent link="Torso"/>
        <child link="l_hip_ie_link"/>
        <axis xyz="0 -0.258819 0.965926"/>
        <limit effort="70.0" velocity="4.1" lower="-0.436332" upper="0.436332"/>
        <joint_properties friction="0.0"/>
    </joint>
    <link name="l_hip_ie_link">
        <visual>
            <origin xyz="0 0 0" rpy="0 -0 0"/>
            <geometry>
                <mesh filename="package://meshes/qdh/l_hip_ie_link_visual.stl"/>
            </geometry>
            <material name="l_hip_ie_link_material">
                <color rgba="0.15 0.15 0.15 1.0"/>
            </material>
        </visual>
        <collision>
            <origin xyz="0 0 0" rpy="0 -0 0"/>
            <geometry>
                <mesh filename="package://meshes/qdh/l_hip_ie_link_visual.stl"/>
            </geometry>
            <material name="l_hip_ie_link_material">
                <color rgba="0.15 0.15 0.15 1.0"/>
            </material>
        </collision>
        <inertial>
            <origin xyz="-0.0943142 -0.00563666 0.0217333" rpy="0 0 0"/>
            <mass value="3.88766"/>
            <inertia ixx="0.0172409" ixy="0.00129646" ixz="-0.00629149" iyy="0.0190041" iyz="0.00203646" izz="0.0121399"/>
        </inertial>
    </link>
    <!--=============================== l_hip_aa (l_hip_aa_link) ===========================-->
    <joint name="l_hip_aa" type="revolute">
        <origin xyz="-4.64906e-16 -1.38778e-17 -4.29344e-17" rpy="3.46945e-18 -9.46465e-15 4.64906e-16"/>
        <parent link="l_hip_ie_link"/>
        <child link="l_hip_aa_link"/>
        <axis xyz="1 0 0"/>
        <limit effort="150.0" velocity="16.33" lower="-0.222529" upper="0.746128"/>
        <joint_properties friction="0.0"/>
    </joint>
    <link name="l_hip_aa_link">
        <visual>
            <origin xyz="0 0 0" rpy="0 -0 0"/>
            <geometry>
                <mesh filename="package://meshes/qdh/l_hip_aa_link_visual.stl"/>
            </geometry>
            <material name="l_hip_aa_link_material">
                <color rgba="0.15 0.15 0.15 1.0"/>
            </material>
        </visual>
        <collision>
            <origin xyz="0 0 0" rpy="0 -0 0"/>
            <geometry>
                <mesh filename="package://meshes/qdh/l_hip_aa_link_visual.stl"/>
            </geometry>
            <material name="l_hip_aa_link_material">
                <color rgba="0.15 0.15 0.15 1.0"/>
            </material>
        </collision>
        <inertial>
            <origin xyz="-0.0422296 0.0159628 -0.000545945" rpy="0 0 0"/>
            <mass value="0.56437"/>
            <inertia ixx="0.00116246" ixy="-0.000251036" ixz="-1.75649e-05" iyy="0.00129812" iyz="-2.22834e-06" izz="0.00145023"/>
        </inertial>
    </link>
    <!--=============================== l_hip_fe (l_thigh_link) ===========================-->
    <joint name="l_hip_fe" type="revolute">
        <origin xyz="-6.93889e-18 -1.38778e-16 7.88861e-31" rpy="-3.46945e-18 9.45077e-15 5.21284e-16"/>
        <parent link="l_hip_aa_link"/>
        <child link="l_thigh_link"/>
        <axis xyz="0 1 0"/>
        <limit effort="250.0" velocity="16.33" lower="-1.91986" upper="0.47822"/>
        <joint_properties friction="0.0"/>
    </joint>
    <link name="l_thigh_link">
        <visual>
            <origin xyz="0 0 0" rpy="0 -0 0"/>
            <geometry>
                <mesh filename="package://meshes/qdh/l_thigh_link_visual.stl"/>
            </geometry>
            <material name="l_thigh_link_material">
                <color rgba="0.15 0.15 0.15 1.0"/>
            </material>
        </visual>
        <collision>
            <origin xyz="0 0 0" rpy="0 -0 0"/>
            <geometry>
                <mesh filename="package://meshes/qdh/l_thigh_link_visual.stl"/>
            </geometry>
            <material name="l_thigh_link_material">
                <color rgba="0.15 0.15 0.15 1.0"/>
            </material>
        </collision>
        <inertial>
            <origin xyz="0.015491 -0.00182256 -0.132842" rpy="0 0 0"/>
            <mass value="9.03181"/>
            <inertia ixx="0.162797" ixy="-4.95823e-06" ixz="0.00528444" iyy="0.164674" iyz="0.018121" izz="0.0247698"/>
        </inertial>
    </link>
    <!--=============================== l_knee_fe (l_shin_link) ===========================-->
    <joint name="l_knee_fe" type="revolute">
        <origin xyz="4.79478e-15 0 -0.42" rpy="6.93889e-18 -1.06429e-14 -4.79519e-15"/>
        <parent link="l_thigh_link"/>
        <child link="l_shin_link"/>
        <axis xyz="0 1 0"/>
        <limit effort="250.0" velocity="16.33" lower="0.20" upper="2.3911"/>
        <joint_properties friction="0.0"/>
    </joint>
    <link name="l_shin_link">
        <visual>
            <origin xyz="0 0 0" rpy="0 -0 0"/>
            <geometry>
                <mesh filename="package://meshes/qdh/l_shin_link_visual.stl"/>
            </geometry>
            <material name="l_shin_link_material">
                <color rgba="0.825 0.825 0.825 1.0"/>
            </material>
        </visual>
        <collision>
            <origin xyz="0 0 0" rpy="0 -0 0"/>
            <geometry>
                <mesh filename="package://meshes/qdh/l_shin_link_visual.stl"/>
            </geometry>
            <material name="l_shin_link_material">
                <color rgba="0.825 0.825 0.825 1.0"/>
            </material>
        </collision>
        <inertial>
            <origin xyz="0.00249008 0.00787388 -0.140454" rpy="0 0 0"/>
            <mass value="2.68236"/>
            <inertia ixx="0.0522156" ixy="0.000183498" ixz="-0.000229201" iyy="0.05289" iyz="-0.00159302" izz="0.00373055"/>
        </inertial>
    </link>
    <!--=============================== l_ankle_fe (l_foot_link) ===========================-->
    <joint name="l_ankle_fe" type="revolute">
        <origin xyz="5.14352e-17 2.77556e-17 -0.42" rpy="-1.38667e-31 -1.71977e-30 1.21778e-15"/>
        <parent link="l_shin_link"/>
        <child link="l_foot_link"/>
        <axis xyz="0 1 0"/>
        <limit effort="90.0" velocity="5.7" lower="-1.23918" upper="0.436332"/>
        <joint_properties friction="0.0"/>
    </joint>
    <link name="l_foot_link">
        <visual>
            <origin xyz="0 0 0" rpy="0 -0 0"/>
            <geometry>
                <mesh filename="package://meshes/qdh/l_foot.stl"/>
            </geometry>
            <material name="l_foot_link_material">
                <color rgba="0.15 0.15 0.15 1.0"/>
            </material>
        </visual>
        <collision>
            <origin xyz="0 0 0" rpy="0 -0 0"/>
            <geometry>
                <mesh filename="package://meshes/qdh/l_foot.stl"/>
            </geometry>
            <material name="l_foot_link_material">
                <color rgba="0.15 0.15 0.15 1.0"/>
            </material>
        </collision>
        <inertial>
            <origin xyz="0.013374 0.00030601 -0.00411765" rpy="0 0 0"/>
            <mass value="0.635937"/>
            <inertia ixx="0.00323459" ixy="4.92056e-06" ixz="0.00131781" iyy="0.00476818" iyz="8.06811e-06" izz="0.00172715"/>
        </inertial>
    </link>
    <!--=============================== l_shldr_fe (l_shoulder_fe_link) ===========================-->
    <joint name="l_shldr_fe" type="revolute">
        <origin xyz="2.74905e-15 0.23 0.5" rpy="3.26951e-14 -2.90001e-16 6.44063e-16"/>
        <parent link="Torso"/>
        <child link="l_shoulder_fe_link"/>
        <axis xyz="0 0.866025 0.5"/>
        <limit effort="70.0" velocity="4.1" lower="-3.14159" upper="0.785398"/>
        <joint_properties friction="0.0"/>
    </joint>
    <link name="l_shoulder_fe_link">
        <visual>
            <origin xyz="0 0 0" rpy="0 -0 0"/>
            <geometry>
                <mesh filename="package://meshes/qdh/l_shoulder_fe_link_visual.stl"/>
            </geometry>
            <material name="l_shoulder_fe_link_material">
                <color rgba="0.15 0.15 0.15 1.0"/>
            </material>
        </visual>
        <collision>
            <origin xyz="0 0 0" rpy="0 -0 0"/>
            <geometry>
                <mesh filename="package://meshes/qdh/l_shoulder_fe_link_visual.stl"/>
            </geometry>
            <material name="l_shoulder_fe_link_material">
                <color rgba="0.15 0.15 0.15 1.0"/>
            </material>
        </collision>
        <inertial>
            <origin xyz="-0.00917748 -0.0357269 -0.0197728" rpy="0 0 0"/>
            <mass value="1.46854"/>
            <inertia ixx="0.00528789" ixy="0.000293975" ixz="4.48609e-05" iyy="0.00246679" iyz="-0.00165798" izz="0.00414294"/>
        </inertial>
    </link>
    <!--=============================== l_shldr_aa (l_bicep_link) ===========================-->
    <joint name="l_shldr_aa" type="revolute">
        <origin xyz="-5.42342e-31 0 5.55112e-17" rpy="-4.0637e-17 1.23467e-16 5.05971e-15"/>
        <parent link="l_shoulder_fe_link"/>
        <child link="l_bicep_link"/>
        <axis xyz="1 0 0"/>
        <limit effort="70.0" velocity="4.1" lower="0" upper="2.0944"/>
        <joint_properties friction="0.0"/>
    </joint>
    <link name="l_bicep_link">
        <visual>
            <origin xyz="0 0 0" rpy="0 -0 0"/>
            <geometry>
                <mesh filename="package://meshes/qdh/l_bicep_link_visual.stl"/>
            </geometry>
            <material name="l_bicep_link_material">
                <color rgba="0.825 0.825 0.825 1.0"/>
            </material>
        </visual>
        <collision>
            <origin xyz="0 0 0" rpy="0 -0 0"/>
            <geometry>
                <mesh filename="package://meshes/qdh/l_bicep_link_visual.stl"/>
            </geometry>
            <material name="l_bicep_link_material">
                <color rgba="0.825 0.825 0.825 1.0"/>
            </material>
        </collision>
        <inertial>
            <origin xyz="0.00192337 -0.00700952 -0.222911" rpy="0 0 0"/>
            <mass value="1.52298"/>
            <inertia ixx="0.0190226" ixy="-0.000148002" ixz="-0.00189385" iyy="0.0190689" iyz="-0.000808217" izz="0.00125113"/>
        </inertial>
    </link>
    <!--=============================== l_elbow_fe (l_forearm_link) ===========================-->
    <joint name="l_elbow_fe" type="revolute">
        <origin xyz="-1.45767e-16 5.55112e-17 -0.3" rpy="1.15644e-16 -4.79014e-17 4.58463e-17"/>
        <parent link="l_bicep_link"/>
        <child link="l_forearm_link"/>
        <axis xyz="0.382683 0.92388 0"/>
        <limit effort="70.0" velocity="4.1" lower="-2.26893" upper="-0.20"/>
        <joint_properties friction="0.0"/>
    </joint>
    <link name="l_forearm_link">
        <visual>
            <origin xyz="0 0 0" rpy="0 -0 0"/>
            <geometry>
                <mesh filename="package://meshes/qdh/l_forearm_link_visual.stl"/>
            </geometry>
            <material name="l_forearm_link_material">
                <color rgba="0.15 0.15 0.15 1.0"/>
            </material>
        </visual>
        <collision>
            <origin xyz="0 0 0" rpy="0 -0 0"/>
            <geometry>
                <mesh filename="package://meshes/qdh/l_forearm_link_collision.stl"/>
            </geometry>
            <material name="l_forearm_link_material">
                <color rgba="0.15 0.15 0.15 1.0"/>
            </material>
        </collision>
        <inertial>
            <origin xyz="0.00440832 0.0112981 -0.127919" rpy="0 0 0"/>
            <mass value="0.59276"/>
            <inertia ixx="0.00769343" ixy="-6.15743e-05" ixz="-0.00028427" iyy="0.00765896" iyz="-0.000620791" izz="0.000365679"/>
        </inertial>
    </link>
    <!--=============================== r_hip_ie (r_hip_ie_link) ===========================-->
    <joint name="r_hip_ie" type="revolute">
        <origin xyz="-6.66134e-16 -0.125 -4.13165e-15" rpy="5.39846e-15 6.71685e-15 -1.73819e-15"/>
        <parent link="Torso"/>
        <child link="r_hip_ie_link"/>
        <axis xyz="0 0.258819 0.965926"/>
        <limit effort="70.0" velocity="4.1" lower="-0.436332" upper="0.436332"/>
        <joint_properties friction="0.0"/>
    </joint>
    <link name="r_hip_ie_link">
        <visual>
            <origin xyz="0 0 0" rpy="0 -0 0"/>
            <geometry>
                <mesh filename="package://meshes/qdh/r_hip_ie_link_visual.stl"/>
            </geometry>
            <material name="r_hip_ie_link_material">
                <color rgba="0.15 0.15 0.15 1.0"/>
            </material>
        </visual>
        <collision>
            <origin xyz="0 0 0" rpy="0 -0 0"/>
            <geometry>
                <mesh filename="package://meshes/qdh/r_hip_ie_link_visual.stl"/>
            </geometry>
            <material name="r_hip_ie_link_material">
                <color rgba="0.15 0.15 0.15 1.0"/>
            </material>
        </collision>
        <inertial>
            <origin xyz="-0.0943197 0.00566348 0.0217261" rpy="0 0 0"/>
            <mass value="3.88766"/>
            <inertia ixx="0.0172409" ixy="-0.00164736" ixz="-0.00638115" iyy="0.0188509" iyz="-0.00179793" izz="0.012285"/>
        </inertial>
    </link>
    <!--=============================== r_hip_aa (r_hip_aa_link) ===========================-->
    <joint name="r_hip_aa" type="revolute">
        <origin xyz="1.85728e-15 -3.05311e-16 -1.33225e-17" rpy="-1.20717e-15 8.38165e-31 1.98543e-14"/>
        <parent link="r_hip_ie_link"/>
        <child link="r_hip_aa_link"/>
        <axis xyz="1 0 0"/>
        <limit effort="150.0" velocity="16.33" lower="-0.746128" upper="0.222529"/>
        <joint_properties friction="0.0"/>
    </joint>
    <link name="r_hip_aa_link">
        <visual>
            <origin xyz="0 0 0" rpy="0 -0 0"/>
            <geometry>
                <mesh filename="package://meshes/qdh/r_hip_aa_link_visual.stl"/>
            </geometry>
            <material name="r_hip_aa_link_material">
                <color rgba="0.15 0.15 0.15 1.0"/>
            </material>
        </visual>
        <collision>
            <origin xyz="0 0 0" rpy="0 -0 0"/>
            <geometry>
                <mesh filename="package://meshes/qdh/r_hip_aa_link_visual.stl"/>
            </geometry>
            <material name="r_hip_aa_link_material">
                <color rgba="0.15 0.15 0.15 1.0"/>
            </material>
        </collision>
        <inertial>
            <origin xyz="-0.0422296 -0.0159628 -0.000545918" rpy="0 0 0"/>
            <mass value="0.56437"/>
            <inertia ixx="0.00116246" ixy="0.000251036" ixz="-1.75616e-05" iyy="0.00129812" iyz="2.22305e-06" izz="0.00145023"/>
        </inertial>
    </link>
    <!--=============================== r_hip_fe (r_thigh_link) ===========================-->
    <joint name="r_hip_fe" type="revolute">
        <origin xyz="1.77494e-30 6.93889e-17 7.88861e-31" rpy="1.14492e-15 4.40776e-29 -2.00065e-14"/>
        <parent link="r_hip_aa_link"/>
        <child link="r_thigh_link"/>
        <axis xyz="0 1 0"/>
        <limit effort="250.0" velocity="16.33" lower="-1.91986" upper="0.47822"/>
        <joint_properties friction="0.0"/>
    </joint>
    <link name="r_thigh_link">
        <visual>
            <origin xyz="0 0 0" rpy="0 -0 0"/>
            <geometry>
                <mesh filename="package://meshes/qdh/r_thigh_link_visual.stl"/>
            </geometry>
            <material name="r_thigh_link_material">
                <color rgba="0.15 0.15 0.15 1.0"/>
            </material>
        </visual>
        <collision>
            <origin xyz="0 0 0" rpy="0 -0 0"/>
            <geometry>
                <mesh filename="package://meshes/qdh/r_thigh_link_visual.stl"/>
            </geometry>
            <material name="r_thigh_link_material">
                <color rgba="0.15 0.15 0.15 1.0"/>
            </material>
        </collision>
        <inertial>
            <origin xyz="0.0155133 0.00283279 -0.132977" rpy="0 0 0"/>
            <mass value="9.04699"/>
            <inertia ixx="0.162256" ixy="0.000152769" ixz="0.00495391" iyy="0.165145" iyz="-0.0194312" izz="0.0238239"/>
        </inertial>
    </link>
    <!--=============================== r_knee_fe (r_shin_link) ===========================-->
    <joint name="r_knee_fe" type="revolute">
        <origin xyz="2.05502e-15 2.35922e-16 -0.42" rpy="-3.15228e-30 -7.85346e-15 7.18647e-16"/>
        <parent link="r_thigh_link"/>
        <child link="r_shin_link"/>
        <axis xyz="0 1 0"/>
        <limit effort="250.0" velocity="16.33" lower="0.20" upper="2.3911"/>
        <joint_properties friction="0.0"/>
    </joint>
    <link name="r_shin_link">
        <visual>
            <origin xyz="0 0 0" rpy="0 -0 0"/>
            <geometry>
                <mesh filename="package://meshes/qdh/r_shin_link_visual.stl"/>
            </geometry>
            <material name="r_shin_link_material">
                <color rgba="0.825 0.825 0.825 1.0"/>
            </material>
        </visual>
        <collision>
            <origin xyz="0 0 0" rpy="0 -0 0"/>
            <geometry>
                <mesh filename="package://meshes/qdh/r_shin_link_visual.stl"/>
            </geometry>
            <material name="r_shin_link_material">
                <color rgba="0.825 0.825 0.825 1.0"/>
            </material>
        </collision>
        <inertial>
            <origin xyz="0.0025067 -0.00787681 -0.14045" rpy="0 0 0"/>
            <mass value="2.68136"/>
            <inertia ixx="0.052222" ixy="-0.00018324" ixz="-0.000229" iyy="0.0529629" iyz="0.00153641" izz="0.00366534"/>
        </inertial>
    </link>
    <!--=============================== r_ankle_fe (r_foot_link) ===========================-->
    <joint name="r_ankle_fe" type="revolute">
        <origin xyz="5.14352e-17 -1.38778e-17 -0.42" rpy="-4.41202e-16 5.36482e-31 -3.74048e-16"/>
        <parent link="r_shin_link"/>
        <child link="r_foot_link"/>
        <axis xyz="0 1 0"/>
        <limit effort="90.0" velocity="5.7" lower="-1.23918" upper="0.436332"/>
        <joint_properties friction="0.0"/>
    </joint>
    <link name="r_foot_link">
        <visual>
            <origin xyz="0 0 0" rpy="0 -0 0"/>
            <geometry>
                <mesh filename="package://meshes/qdh/r_foot.stl"/>
            </geometry>
            <material name="r_foot_link_material">
                <color rgba="0.15 0.15 0.15 1.0"/>
            </material>
        </visual>
        <collision>
            <origin xyz="0 0 0" rpy="0 -0 0"/>
            <geometry>
                <mesh filename="package://meshes/qdh/r_foot.stl"/>
            </geometry>
            <material name="r_foot_link_material">
                <color rgba="0.15 0.15 0.15 1.0"/>
            </material>
        </collision>
        <inertial>
            <origin xyz="0.013374 0.000688182 -0.00411766" rpy="0 0 0"/>
            <mass value="0.635937"/>
            <inertia ixx="0.00335464" ixy="2.41978e-06" ixz="0.00131781" iyy="0.0047682" iyz="-1.01355e-05" izz="0.00184718"/>
        </inertial>
    </link>
    <!--=============================== r_shldr_fe (r_shoulder_fe_link) ===========================-->
    <joint name="r_shldr_fe" type="revolute">
        <origin xyz="-6.68881e-16 -0.23 0.5" rpy="4.03308e-14 -1.13661e-15 -1.94317e-15"/>
        <parent link="Torso"/>
        <child link="r_shoulder_fe_link"/>
        <axis xyz="0 0.866025 -0.5"/>
        <limit effort="70.0" velocity="4.1" lower="-3.14159" upper="0.785398"/>
        <joint_properties friction="0.0"/>
    </joint>
    <link name="r_shoulder_fe_link">
        <visual>
            <origin xyz="0 0 0" rpy="0 -0 0"/>
            <geometry>
                <mesh filename="package://meshes/qdh/r_shoulder_fe_link_visual.stl"/>
            </geometry>
            <material name="r_shoulder_fe_link_material">
                <color rgba="0.15 0.15 0.15 1.0"/>
            </material>
        </visual>
        <collision>
            <origin xyz="0 0 0" rpy="0 -0 0"/>
            <geometry>
                <mesh filename="package://meshes/qdh/r_shoulder_fe_link_visual.stl"/>
            </geometry>
            <material name="r_shoulder_fe_link_material">
                <color rgba="0.15 0.15 0.15 1.0"/>
            </material>
        </collision>
        <inertial>
            <origin xyz="-0.0090987 0.0361138 -0.020018" rpy="0 0 0"/>
            <mass value="1.48115"/>
            <inertia ixx="0.00532871" ixy="-0.000397234" ixz="0.000217234" iyy="0.00219548" iyz="0.00183657" izz="0.00445731"/>
        </inertial>
    </link>
    <!--=============================== r_shldr_aa (r_bicep_link) ===========================-->
    <joint name="r_shldr_aa" type="revolute">
        <origin xyz="1.57772e-30 0 0" rpy="-7.37813e-30 4.76066e-30 7.71378e-16"/>
        <parent link="r_shoulder_fe_link"/>
        <child link="r_bicep_link"/>
        <axis xyz="1 0 0"/>
        <limit effort="70.0" velocity="4.1" lower="-2.0944" upper="0"/>
        <joint_properties friction="0.0"/>
    </joint>
    <link name="r_bicep_link">
        <visual>
            <origin xyz="0 0 0" rpy="0 -0 0"/>
            <geometry>
                <mesh filename="package://meshes/qdh/r_bicep_link_visual.stl"/>
            </geometry>
            <material name="r_bicep_link_material">
                <color rgba="0.825 0.825 0.825 1.0"/>
            </material>
        </visual>
        <collision>
            <origin xyz="0 0 0" rpy="0 -0 0"/>
            <geometry>
                <mesh filename="package://meshes/qdh/r_bicep_link_visual.stl"/>
            </geometry>
            <material name="r_bicep_link_material">
                <color rgba="0.825 0.825 0.825 1.0"/>
            </material>
        </collision>
        <inertial>
            <origin xyz="0.00187408 0.00698445 -0.222884" rpy="0 0 0"/>
            <mass value="1.52098"/>
            <inertia ixx="0.0190211" ixy="0.000148305" ixz="-0.00189478" iyy="0.0190681" iyz="0.00080802" izz="0.00125111"/>
        </inertial>
    </link>
    <!--=============================== r_elbow_fe (r_forearm_link) ===========================-->
    <joint name="r_elbow_fe" type="revolute">
        <origin xyz="2.6361e-18 2.77556e-17 -0.3" rpy="8.1274e-17 -2.912e-17 3.50326e-15"/>
        <parent link="r_bicep_link"/>
        <child link="r_forearm_link"/>
        <axis xyz="-0.382683 0.92388 0"/>
        <limit effort="70.0" velocity="4.1" lower="-2.26893" upper="-0.20"/>
        <joint_properties friction="0.0"/>
    </joint>
    <link name="r_forearm_link">
        <visual>
            <origin xyz="0 0 0" rpy="0 -0 0"/>
            <geometry>
                <mesh filename="package://meshes/qdh/r_forearm_link_visual.stl"/>
            </geometry>
            <material name="r_forearm_link_material">
                <color rgba="0.15 0.15 0.15 1.0"/>
            </material>
        </visual>
        <collision>
            <origin xyz="0 0 0" rpy="0 -0 0"/>
            <geometry>
                <mesh filename="package://meshes/qdh/r_forearm_link_collision.stl"/>
            </geometry>
            <material name="r_forearm_link_material">
                <color rgba="0.15 0.15 0.15 1.0"/>
            </material>
        </collision>
        <inertial>
            <origin xyz="0.00440586 -0.011299 -0.127919" rpy="0 0 0"/>
            <mass value="0.592759"/>
            <inertia ixx="0.00769343" ixy="6.15674e-05" ixz="-0.000284234" iyy="0.00765892" iyz="0.00062084" izz="0.000365712"/>
        </inertial>
    </link>
    <link name="IMU">
        <inertial>
            <mass value="0.0001"/>
            <origin rpy="0 0 0" xyz="0.0 0.0 0.0"/>
            <inertia ixx="0.00000001" ixy="0" ixz="0" iyy="0.00000001" iyz="0" izz="0.00000001"/>
        </inertial>
    </link>
    <joint name="IMU" type="fixed">
        <origin rpy="0 3.1415926 1.5714" xyz="-0.0 -0.00 0.13"/>
        <parent link="Torso"/>
        <child link="IMU"/>
    </joint>
    <link name="lToe">
        <inertial>
            <origin rpy="0 0 0" xyz="0 0 0"/>
            <mass value="0.0001"/>
            <inertia ixx="9.9999999999999995e-07" ixy="0" ixz="0" iyy="9.9999999999999995e-07" iyz="0" izz="9.9999999999999995e-07"/>
        </inertial>
        <!-- <collision>
      <origin rpy="0 -0 0" xyz="-0.039 0 0.005"/>
      <geometry>
        <box size="0.08 0.065 0.011"/>
      </geometry>
    </collision> -->
    </link>
    <joint name="lToe" type="fixed">
        <origin rpy="0 0 0" xyz="0.13 0 -0.0725"/>
        <parent link="l_foot_link"/>
        <child link="lToe"/>
    </joint>
    <link name="lHeel">
        <inertial>
            <origin rpy="0 0 0" xyz="0 0 0"/>
            <mass value="0.0001"/>
            <inertia ixx="9.9999999999999995e-07" ixy="0" ixz="0" iyy="9.9999999999999995e-07" iyz="0" izz="9.9999999999999995e-07"/>
        </inertial>
        <!-- <collision>
      <origin rpy="0 -0 0" xyz="0.039 0 0.005"/>
      <geometry>
        <box size="0.08 0.065 0.011"/>
      </geometry>
    </collision> -->
    </link>
    <joint name="lHeel" type="fixed">
        <origin rpy="0 0 0" xyz="-0.03 0 -0.0725"/>
        <parent link="l_foot_link"/>
        <child link="lHeel"/>
    </joint>
    <joint name="l_foot_contact_frame" type="fixed">
        <origin rpy="0 0 0" xyz="0 0 -0.0725"/>
        <parent link="l_foot_link"/>
        <child link="lFoot"/>
    </joint>
    <link name="lFoot">
        <inertial>
            <origin rpy="0 0 0" xyz="0 0 0"/>
            <mass value="1e-9"/>
            <inertia ixx="0" ixy="0" ixz="0" iyy="0" iyz="0" izz="0"/>
        </inertial>
    </link>
    <link name="rToe">
        <inertial>
            <origin rpy="0 0 0" xyz="0 0 0"/>
            <mass value="0.0001"/>
            <inertia ixx="9.9999999999999995e-07" ixy="0" ixz="0" iyy="9.9999999999999995e-07" iyz="0" izz="9.9999999999999995e-07"/>
        </inertial>
        <!-- <collision>
      <origin rpy="0 -0 0" xyz="-0.039 0 0.005"/>
      <geometry>
        <box size="0.08 0.065 0.011"/>
      </geometry>
    </collision> -->
    </link>
    <joint name="rToe" type="fixed">
        <origin rpy="0 0 0" xyz="0.13 0 -0.0725"/>
        <parent link="r_foot_link"/>
        <child link="rToe"/>
    </joint>
    <link name="rHeel">
        <inertial>
            <origin rpy="0 0 0" xyz="0 0 0"/>
            <mass value="0.0001"/>
            <inertia ixx="9.9999999999999995e-07" ixy="0" ixz="0" iyy="9.9999999999999995e-07" iyz="0" izz="9.9999999999999995e-07"/>
        </inertial>
        <!-- <collision>
      <origin rpy="0 -0 0" xyz="0.039 0 0.005"/>
      <geometry>
        <box size="0.08 0.065 0.011"/>
      </geometry>
    </collision> -->
    </link>
    <joint name="rHeel" type="fixed">
        <origin rpy="0 0 0" xyz="-0.03 0 -0.0725"/>
        <parent link="r_foot_link"/>
        <child link="rHeel"/>
    </joint>
    <joint name="r_foot_contact_frame" type="fixed">
        <origin rpy="0 0 0" xyz="0 0 -0.0725"/>
        <parent link="r_foot_link"/>
        <child link="rFoot"/>
    </joint>
    <link name="rFoot">
        <inertial>
            <origin rpy="0 0 0" xyz="0 0 0"/>
            <mass value="1e-9"/>
            <inertia ixx="0" ixy="0" ixz="0" iyy="0" iyz="0" izz="0"/>
        </inertial>
    </link>
    <link name="lHand">
        <inertial>
            <origin rpy="0 0 0" xyz="0 0 0"/>
            <mass value="0.000001"/>
            <inertia ixx="0" ixy="0" ixz="0" iyy="0" iyz="0" izz="0"/>
        </inertial>
    </link>
    <joint name="lHand" type="fixed">
        <origin rpy="0 0 0" xyz="0 0 -0.3"/>
        <parent link="l_forearm_link"/>
        <child link="lHand"/>
    </joint>
    <link name="rHand">
        <inertial>
            <origin rpy="0 0 0" xyz="0 0 0"/>
            <mass value="0.000001"/>
            <inertia ixx="0" ixy="0" ixz="0" iyy="0" iyz="0" izz="0"/>
        </inertial>
    </link>
    <joint name="rHand" type="fixed">
        <origin rpy="0 0 0" xyz="0 0 -0.3"/>
        <parent link="r_forearm_link"/>
        <child link="rHand"/>
    </joint>
    <!--=============================== oak-d ===========================-->
    <!--<link name="oakd_chest_front"/>-->
    <!--<joint name="oak_center_joint" type="fixed">-->
        <!--<parent link="Torso"/>-->
        <!--<child link="oakd_chest_front"/>-->
        <!--<origin rpy="0 0.785398 0" xyz="0.083 0 0.475"/>-->
    <!--</joint>-->
     <!--device Center -->
    <!--<link name="oak_model_origin">-->
        <!--<visual>-->
            <!--<origin xyz="0 0 0" rpy="0 0 0"/>-->
            <!--<geometry>-->
                <!--<mesh filename="package://depthai_model_meshes/meshes/OAK-D-PRO.stl"/>-->
            <!--</geometry>-->
            <!--<material name="mat">-->
                <!--<color rgba="0.8 0.8 0.8 0.8"/>-->
            <!--</material>-->
        <!--</visual>-->
    <!--</link>-->
    <!--<joint name="oak_model_origin_joint" type="fixed">-->
        <!--<parent link="oakd_chest_front"/>-->
        <!--<child link="oak_model_origin"/>-->
        <!--<origin xyz="0 0 0" rpy="1.5708 0 1.5708"/>-->
    <!--</joint>-->
     <!--IMU -->
    <!--<link name="oak_imu_frame"/>-->
    <!--<joint name="oak_imu_joint" type="fixed">-->
        <!--<parent link="oakd_chest_front"/>-->
        <!--<child link="oak_imu_frame"/>-->
        <!--<origin xyz="0.0 -0.015 -0.013662" rpy="0 1.5708 0"/>-->
    <!--</joint>-->
     <!--RGB Camera -->
    <!--<link name="oak_rgb_camera_frame"/>-->
    <!--<joint name="oak_rgb_camera_joint" type="fixed">-->
        <!--<parent link="oakd_chest_front"/>-->
        <!--<child link="oak_rgb_camera_frame"/>-->
        <!--<origin xyz="0 0 0" rpy="0 0 0"/>-->
    <!--</joint>-->
    <!--<link name="oak_rgb_camera_optical_frame"/>-->
    <!--<joint name="oak_rgb_camera_optical_joint" type="fixed">-->
        <!--<origin xyz="0 0 0" rpy="-1.57079632679  0.0 -1.57079632679 "/>-->
        <!--<parent link="oak_rgb_camera_frame"/>-->
        <!--<child link="oak_rgb_camera_optical_frame"/>-->
    <!--</joint>-->
     <!--Left Camera -->
    <!--<link name="oak_left_camera_frame"/>-->
    <!--<joint name="oak_left_camera_joint" type="fixed">-->
        <!--<parent link="oakd_chest_front"/>-->
        <!--<child link="oak_left_camera_frame"/>-->
        <!--<origin xyz="0 0.0375 0" rpy="0 0 0"/>-->
    <!--</joint>-->
    <!--<link name="oak_left_camera_optical_frame"/>-->
    <!--<joint name="oak_left_camera_optical_joint" type="fixed">-->
        <!--<origin xyz="0 0 0" rpy="-1.57079632679  0.0 -1.57079632679 "/>-->
        <!--<parent link="oak_left_camera_frame"/>-->
        <!--<child link="oak_left_camera_optical_frame"/>-->
    <!--</joint>-->
     <!--right Camera -->
    <!--<link name="oak_right_camera_frame"/>-->
    <!--<joint name="oak_right_camera_joint" type="fixed">-->
        <!--<parent link="oakd_chest_front"/>-->
        <!--<child link="oak_right_camera_frame"/>-->
        <!--<origin xyz="0 -0.0375 0" rpy="0 0 0"/>-->
    <!--</joint>-->
    <!--<link name="oak_right_camera_optical_frame"/>-->
    <!--<joint name="oak_right_camera_optical_joint" type="fixed">-->
        <!--<origin xyz="0 0 0" rpy="-1.57079632679  0.0 -1.57079632679 "/>-->
        <!--<parent link="oak_right_camera_frame"/>-->
        <!--<child link="oak_right_camera_optical_frame"/>-->
    <!--</joint>-->
    <gazebo>
        <plugin filename="ign_cortex_control_plugin" name="aptk::sim::IgnControlPlugin">
            <control_rate>1000</control_rate>
        </plugin>
        <plugin filename="ignition-gazebo-imu-system" name="ignition::gazebo::systems::Imu"/>
        <plugin filename="ignition-gazebo-odometry-publisher-system" name="ignition::gazebo::systems::OdometryPublisher">
            <dimensions>3</dimensions>
            <odom_publish_frequency>1000</odom_publish_frequency>
        </plugin>
    </gazebo>
    <gazebo reference="IMU">
        <sensor name="IMU" type="imu">
            <always_on>1</always_on>
            <update_rate>1000</update_rate>
            <visualize>true</visualize>
            <topic>imu_link</topic>
            <imu>
                <angular_velocity>
                    <x>
                        <noise type="gaussian">
                            <mean>0.0</mean>
                            <stddev>2e-4</stddev>
                            <bias_mean>0.0000075</bias_mean>
                            <bias_stddev>0.0000008</bias_stddev>
                        </noise>
                    </x>
                    <y>
                        <noise type="gaussian">
                            <mean>0.0</mean>
                            <stddev>2e-4</stddev>
                            <bias_mean>0.0000075</bias_mean>
                            <bias_stddev>0.0000008</bias_stddev>
                        </noise>
                    </y>
                    <z>
                        <noise type="gaussian">
                            <mean>0.0</mean>
                            <stddev>2e-4</stddev>
                            <bias_mean>0.0000075</bias_mean>
                            <bias_stddev>0.0000008</bias_stddev>
                        </noise>
                    </z>
                </angular_velocity>
                <linear_acceleration>
                    <x>
                        <noise type="gaussian">
                            <mean>0.0</mean>
                            <stddev>1.7e-2</stddev>
                            <bias_mean>0.1</bias_mean>
                            <bias_stddev>0.001</bias_stddev>
                        </noise>
                    </x>
                    <y>
                        <noise type="gaussian">
                            <mean>0.0</mean>
                            <stddev>1.7e-2</stddev>
                            <bias_mean>0.1</bias_mean>
                            <bias_stddev>0.001</bias_stddev>
                        </noise>
                    </y>
                    <z>
                        <noise type="gaussian">
                            <mean>0.0</mean>
                            <stddev>1.7e-2</stddev>
                            <bias_mean>0.1</bias_mean>
                            <bias_stddev>0.001</bias_stddev>
                        </noise>
                    </z>
                </linear_acceleration>
            </imu>
        </sensor>
    </gazebo>
</robot>
