<?xml version="1.0" ?>
<!-- =================================================================================== -->
<!-- |    This document was autogenerated by xacro from /home/apptronik/catkin_ws/src/apptronik_core/97_projects/alpha/models/alpha_lite_model/urdf/old/alpha_lite_model_pdr_v2_rotary.urdf.xacro | -->
<!-- |    EDITING THIS FILE BY HAND IS NOT RECOMMENDED                                 | -->
<!-- =================================================================================== -->
<robot name="alpha_lite_model_pdr_v2_rotary">
    <link name="world"/>
    <joint name="floating_base" type="floating">
        <parent link="world"/>
        <child link="IMU"/>
        <origin rpy="0 0 0" xyz="0 0 0"/>
    </joint>
    <!-- Insert IMU and configure it -->
    <gazebo>
        <plugin filename="ign_cortex_control_plugin" name="aptk::sim::IgnControlPlugin">
            <control_rate>1000</control_rate>
        </plugin>
        <plugin filename="ignition-gazebo-imu-system" name="ignition::gazebo::systems::Imu"/>
        <plugin filename="ignition-gazebo-odometry-publisher-system" name="ignition::gazebo::systems::OdometryPublisher">
            <dimensions>3</dimensions>
            <odom_publish_frequency>1000</odom_publish_frequency>
        </plugin>
    </gazebo>
    <link name="IMU">
        <inertial>
            <mass value="0.0001"/>
            <origin rpy="0 0 0" xyz="0.0 0.0 0.0"/>
            <inertia ixx="0.00000001" ixy="0" ixz="0" iyy="0.00000001" iyz="0" izz="0.00000001"/>
        </inertial>
    </link>
    <joint name="IMU" type="fixed">
        <origin rpy="0 3.1415926 1.5714" xyz="-0.0 -0.00 0.13"/>
        <parent link="torso_link"/>
        <child link="IMU"/>
    </joint>
    <gazebo reference="IMU">
        <sensor name="IMU" type="imu">
            <always_on>1</always_on>
            <update_rate>1000</update_rate>
            <visualize>true</visualize>
            <topic>imu_link</topic>
            <imu>
                <angular_velocity>
                    <x>
                        <noise type="gaussian">
                            <mean>0.0</mean>
                            <stddev>2e-4</stddev>
                            <bias_mean>0.0000075</bias_mean>
                            <bias_stddev>0.0000008</bias_stddev>
                        </noise>
                    </x>
                    <y>
                        <noise type="gaussian">
                            <mean>0.0</mean>
                            <stddev>2e-4</stddev>
                            <bias_mean>0.0000075</bias_mean>
                            <bias_stddev>0.0000008</bias_stddev>
                        </noise>
                    </y>
                    <z>
                        <noise type="gaussian">
                            <mean>0.0</mean>
                            <stddev>2e-4</stddev>
                            <bias_mean>0.0000075</bias_mean>
                            <bias_stddev>0.0000008</bias_stddev>
                        </noise>
                    </z>
                </angular_velocity>
                <linear_acceleration>
                    <x>
                        <noise type="gaussian">
                            <mean>0.0</mean>
                            <stddev>1.7e-2</stddev>
                            <bias_mean>0.1</bias_mean>
                            <bias_stddev>0.001</bias_stddev>
                        </noise>
                    </x>
                    <y>
                        <noise type="gaussian">
                            <mean>0.0</mean>
                            <stddev>1.7e-2</stddev>
                            <bias_mean>0.1</bias_mean>
                            <bias_stddev>0.001</bias_stddev>
                        </noise>
                    </y>
                    <z>
                        <noise type="gaussian">
                            <mean>0.0</mean>
                            <stddev>1.7e-2</stddev>
                            <bias_mean>0.1</bias_mean>
                            <bias_stddev>0.001</bias_stddev>
                        </noise>
                    </z>
                </linear_acceleration>
            </imu>
        </sensor>
    </gazebo>
    <joint name="floating_base_joint" type="fixed">
        <origin rpy="0.0 0.0 0.0" xyz="0.0 0.0 0.0"/>
        <parent link="torso_link"/>
        <child link="base_link"/>
    </joint>
    <link name="base_link"/>
    <!-- TODO: Remove this base_footprint and have it get published as a braodcasted tf -->
    <joint name="base_footprint_joint" type="fixed">
        <origin rpy="0.0 0.0 0.0" xyz="0.0 0.0 0.0"/>
        <parent link="torso_link"/>
        <child link="base_footprint"/>
    </joint>
    <link name="base_footprint"/>
    <link name="torso_link">
        <visual>
            <origin rpy="0 -0 0" xyz="0 0 0"/>
            <geometry>
                <mesh filename="package://alpha_lite_model_meshes/meshes/pdr_v2/torso_link_collision_hull.stl"/>
            </geometry>
            <material name="torso_link_material">
                <color rgba="0.41387 0.415171 0.413092 1.0"/>
            </material>
        </visual>
        <collision>
            <origin rpy="0 -0 0" xyz="0 0 0"/>
            <geometry>
                <mesh filename="package://alpha_lite_model_meshes/meshes/pdr_v2/torso_link_collision_hull.stl"/>
            </geometry>
            <material name="torso_link_material">
                <color rgba="0.5 0.5 0.5 1.0"/>
            </material>
        </collision>
        <inertial>
            <origin rpy="0 0 0" xyz="-0.0392963 -0.000228439 0.178965"/>
            <mass value="11.9261"/>
            <inertia ixx="0.147883" ixy="-6.14997e-05" ixz="0.00540181" iyy="0.160322" iyz="0.000289262" izz="0.102232"/>
        </inertial>
    </link>
    <!--=============================== torso_l1i_roll (torso_l1i_roll_link) ===========================-->
    <joint name="torso_l1i_roll" type="fixed">
        <origin rpy="-0.164571 -0.29552 2.19254e-15" xyz="-0.127031 0.1125 0.244818"/>
        <parent link="torso_link"/>
        <child link="torso_l1i_roll_link"/>
    </joint>
    <link name="torso_l1i_roll_link">
        <inertial>
            <origin rpy="0 0 0" xyz="0 0 0"/>
            <mass value="0.0001"/>
            <inertia ixx="9.9999999999999995e-07" ixy="0" ixz="0" iyy="9.9999999999999995e-07" iyz="0" izz="9.9999999999999995e-07"/>
        </inertial>
    </link>
    <!--=============================== torso_l1i_pitch (torso_l1i_pitch_link) ===========================-->
    <joint name="torso_l1i_pitch" type="fixed">
        <origin rpy="-3.14159 1.5708 0" xyz="1.38778e-17 -1.38778e-17 5.55112e-17"/>
        <parent link="torso_l1i_roll_link"/>
        <child link="torso_l1i_pitch_link"/>
    </joint>
    <link name="torso_l1i_pitch_link">
        <visual>
            <origin rpy="0 -0 0" xyz="0 0 0"/>
            <geometry>
                <mesh filename="package://alpha_lite_model_meshes/meshes/pdr_v2/torso_l1i_pitch_link_collision_hull.stl"/>
            </geometry>
            <material name="torso_l1i_pitch_link_material">
                <color rgba="0.647059 0.647059 0.647059 1.0"/>
            </material>
        </visual>
        <collision>
            <origin rpy="0 -0 0" xyz="0 0 0"/>
            <geometry>
                <mesh filename="package://alpha_lite_model_meshes/meshes/pdr_v2/torso_l1i_pitch_link_collision_hull.stl"/>
            </geometry>
            <material name="torso_l1i_pitch_link_material">
                <color rgba="0.5 0.5 0.5 1.0"/>
            </material>
        </collision>
        <inertial>
            <origin rpy="0 0 0" xyz="0.103018 9.28819e-06 0.00025801"/>
            <mass value="0.785"/>
            <inertia ixx="0.000287605" ixy="6.41759e-07" ixz="1.44488e-05" iyy="0.00245437" iyz="-1.21859e-07" izz="0.00245075"/>
        </inertial>
    </link>
    <!--=============================== torso_l1 (torso_l1_link) ===========================-->
    <joint name="torso_l1" type="fixed">
        <origin rpy="-1.5708 -4.40028e-16 1.04913e-15" xyz="0.2449 1.38778e-16 6.93889e-18"/>
        <parent link="torso_l1i_pitch_link"/>
        <child link="torso_l1_link"/>
    </joint>
    <link name="torso_l1_link">
        <visual>
            <origin rpy="0 -0 0" xyz="0 0 0"/>
            <geometry>
                <mesh filename="package://alpha_lite_model_meshes/meshes/pdr_v2/torso_l1_link_collision_hull.stl"/>
            </geometry>
            <material name="torso_l1_link_material">
                <color rgba="0.647059 0.647059 0.647059 1.0"/>
            </material>
        </visual>
        <collision>
            <origin rpy="0 -0 0" xyz="0 0 0"/>
            <geometry>
                <mesh filename="package://alpha_lite_model_meshes/meshes/pdr_v2/torso_l1_link_collision_hull.stl"/>
            </geometry>
            <material name="torso_l1_link_material">
                <color rgba="0.5 0.5 0.5 1.0"/>
            </material>
        </collision>
        <inertial>
            <origin rpy="0 0 0" xyz="-0.064709 -1.00701e-16 -1.49321e-16"/>
            <mass value="0.122"/>
            <inertia ixx="3.75405e-06" ixy="-1.43136e-21" ixz="-2.85306e-21" iyy="0.000142764" iyz="1.29857e-12" izz="0.000142587"/>
        </inertial>
    </link>
    <!--=============================== torso_l1o_roll (torso_l1o_roll_link) ===========================-->
    <joint name="torso_l1o_roll" type="fixed">
        <origin rpy="-1.86632 1.5708 0" xyz="6.93889e-18 0 1.38778e-17"/>
        <parent link="torso_l1_link"/>
        <child link="torso_l1o_roll_link"/>
    </joint>
    <link name="torso_l1o_roll_link">
        <inertial>
            <origin rpy="0 0 0" xyz="0 0 0"/>
            <mass value="0.0001"/>
            <inertia ixx="9.9999999999999995e-07" ixy="0" ixz="0" iyy="9.9999999999999995e-07" iyz="0" izz="9.9999999999999995e-07"/>
        </inertial>
    </link>
    <!--=============================== torso_l2i_roll (torso_l2i_roll_link) ===========================-->
    <joint name="torso_l2i_roll" type="fixed">
        <origin rpy="-2.97702 -0.29552 2.19934e-15" xyz="-0.127031 -0.1125 0.244818"/>
        <parent link="torso_link"/>
        <child link="torso_l2i_roll_link"/>
    </joint>
    <link name="torso_l2i_roll_link">
        <inertial>
            <origin rpy="0 0 0" xyz="0 0 0"/>
            <mass value="0.0001"/>
            <inertia ixx="9.9999999999999995e-07" ixy="0" ixz="0" iyy="9.9999999999999995e-07" iyz="0" izz="9.9999999999999995e-07"/>
        </inertial>
    </link>
    <!--=============================== torso_l2i_pitch (torso_l2i_pitch_link) ===========================-->
    <joint name="torso_l2i_pitch" type="fixed">
        <origin rpy="3.14159 -1.5708 0" xyz="2.77556e-17 0 5.55112e-17"/>
        <parent link="torso_l2i_roll_link"/>
        <child link="torso_l2i_pitch_link"/>
    </joint>
    <link name="torso_l2i_pitch_link">
        <visual>
            <origin rpy="0 -0 0" xyz="0 0 0"/>
            <geometry>
                <mesh filename="package://alpha_lite_model_meshes/meshes/pdr_v2/torso_l2i_pitch_link_collision_hull.stl"/>
            </geometry>
            <material name="torso_l2i_pitch_link_material">
                <color rgba="0.647059 0.647059 0.647059 1.0"/>
            </material>
        </visual>
        <collision>
            <origin rpy="0 -0 0" xyz="0 0 0"/>
            <geometry>
                <mesh filename="package://alpha_lite_model_meshes/meshes/pdr_v2/torso_l2i_pitch_link_collision_hull.stl"/>
            </geometry>
            <material name="torso_l2i_pitch_link_material">
                <color rgba="0.5 0.5 0.5 1.0"/>
            </material>
        </collision>
        <inertial>
            <origin rpy="0 0 0" xyz="0.103018 9.28819e-06 0.00025801"/>
            <mass value="0.785"/>
            <inertia ixx="0.000287605" ixy="6.41759e-07" ixz="1.44488e-05" iyy="0.00245437" iyz="-1.21859e-07" izz="0.00245075"/>
        </inertial>
    </link>
    <!--=============================== torso_l2 (torso_l2_link) ===========================-->
    <joint name="torso_l2" type="fixed">
        <origin rpy="-1.5708 -6.69364e-16 -1.1217e-15" xyz="0.2449 1.80411e-16 -3.46945e-17"/>
        <parent link="torso_l2i_pitch_link"/>
        <child link="torso_l2_link"/>
    </joint>
    <link name="torso_l2_link">
        <visual>
            <origin rpy="0 -0 0" xyz="0 0 0"/>
            <geometry>
                <mesh filename="package://alpha_lite_model_meshes/meshes/pdr_v2/torso_l2_link_collision_hull.stl"/>
            </geometry>
            <material name="torso_l2_link_material">
                <color rgba="0.647059 0.647059 0.647059 1.0"/>
            </material>
        </visual>
        <collision>
            <origin rpy="0 -0 0" xyz="0 0 0"/>
            <geometry>
                <mesh filename="package://alpha_lite_model_meshes/meshes/pdr_v2/torso_l2_link_collision_hull.stl"/>
            </geometry>
            <material name="torso_l2_link_material">
                <color rgba="0.5 0.5 0.5 1.0"/>
            </material>
        </collision>
        <inertial>
            <origin rpy="0 0 0" xyz="-0.064709 -9.43223e-17 -1.82387e-16"/>
            <mass value="0.122"/>
            <inertia ixx="3.75405e-06" ixy="3.47226e-21" ixz="4.13767e-21" iyy="0.000142764" iyz="1.29857e-12" izz="0.000142587"/>
        </inertial>
    </link>
    <!--=============================== torso_l2o_roll (torso_l2o_roll_link) ===========================-->
    <joint name="torso_l2o_roll" type="fixed">
        <origin rpy="-1.28724 1.5708 0" xyz="6.93889e-18 -2.77556e-17 0"/>
        <parent link="torso_l2_link"/>
        <child link="torso_l2o_roll_link"/>
    </joint>
    <link name="torso_l2o_roll_link">
        <inertial>
            <origin rpy="0 0 0" xyz="0 0 0"/>
            <mass value="0.0001"/>
            <inertia ixx="9.9999999999999995e-07" ixy="0" ixz="0" iyy="9.9999999999999995e-07" iyz="0" izz="9.9999999999999995e-07"/>
        </inertial>
    </link>
    <!--=============================== r_shoulder_l1i_roll (r_shoulder_l1i_roll_link) ===========================-->
    <joint name="r_shoulder_l1i_roll" type="fixed">
        <origin rpy="-0.134013 -1.26386 1.5708" xyz="0.005 -0.009 0.232"/>
        <parent link="torso_link"/>
        <child link="r_shoulder_l1i_roll_link"/>
    </joint>
    <link name="r_shoulder_l1i_roll_link">
        <inertial>
            <origin rpy="0 0 0" xyz="0 0 0"/>
            <mass value="0.0001"/>
            <inertia ixx="9.9999999999999995e-07" ixy="0" ixz="0" iyy="9.9999999999999995e-07" iyz="0" izz="9.9999999999999995e-07"/>
        </inertial>
    </link>
    <!--=============================== r_shoulder_l1i_pitch (r_shoulder_l1i_pitch_link) ===========================-->
    <joint name="r_shoulder_l1i_pitch" type="fixed">
        <origin rpy="-3.14159 -1.56976 -3.14159" xyz="-8.32667e-17 1.73472e-18 0"/>
        <parent link="r_shoulder_l1i_roll_link"/>
        <child link="r_shoulder_l1i_pitch_link"/>
    </joint>
    <link name="r_shoulder_l1i_pitch_link">
        <visual>
            <origin rpy="0 -0 0" xyz="0 0 0"/>
            <geometry>
                <mesh filename="package://alpha_lite_model_meshes/meshes/pdr_v2/r_shoulder_l1i_pitch_link_collision_hull.stl"/>
            </geometry>
            <material name="r_shoulder_l1i_pitch_link_material">
                <color rgba="0.647059 0.647059 0.647059 1.0"/>
            </material>
        </visual>
        <collision>
            <origin rpy="0 -0 0" xyz="0 0 0"/>
            <geometry>
                <mesh filename="package://alpha_lite_model_meshes/meshes/pdr_v2/r_shoulder_l1i_pitch_link_collision_hull.stl"/>
            </geometry>
            <material name="r_shoulder_l1i_pitch_link_material">
                <color rgba="0.5 0.5 0.5 1.0"/>
            </material>
        </collision>
        <inertial>
            <origin rpy="0 0 0" xyz="0.0721686 -9.72709e-08 0.000423139"/>
            <mass value="0.464999"/>
            <inertia ixx="0.0001157" ixy="-3.88685e-09" ixz="1.27075e-05" iyy="0.000889385" iyz="1.06918e-09" izz="0.000887036"/>
        </inertial>
    </link>
    <!--=============================== r_shoulder_l1 (r_shoulder_l1_link) ===========================-->
    <joint name="r_shoulder_l1" type="fixed">
        <origin rpy="3.14159 -9.58648e-16 1.60197e-17" xyz="0.1775 -5.20417e-18 -9.65412e-05"/>
        <parent link="r_shoulder_l1i_pitch_link"/>
        <child link="r_shoulder_l1_link"/>
    </joint>
    <link name="r_shoulder_l1_link">
        <visual>
            <origin rpy="0 -0 0" xyz="0 0 0"/>
            <geometry>
                <mesh filename="package://alpha_lite_model_meshes/meshes/pdr_v2/r_shoulder_l1_link_collision_hull.stl"/>
            </geometry>
            <material name="r_shoulder_l1_link_material">
                <color rgba="0.647059 0.647059 0.647059 1.0"/>
            </material>
        </visual>
        <collision>
            <origin rpy="0 -0 0" xyz="0 0 0"/>
            <geometry>
                <mesh filename="package://alpha_lite_model_meshes/meshes/pdr_v2/r_shoulder_l1_link_collision_hull.stl"/>
            </geometry>
            <material name="r_shoulder_l1_link_material">
                <color rgba="0.5 0.5 0.5 1.0"/>
            </material>
        </collision>
        <inertial>
            <origin rpy="0 0 0" xyz="-0.0465845 -2.91316e-06 9.65401e-05"/>
            <mass value="0.052"/>
            <inertia ixx="9.28093e-07" ixy="-4.88361e-09" ixz="1.78019e-12" iyy="3.84625e-05" iyz="2.6656e-13" izz="3.84087e-05"/>
        </inertial>
    </link>
    <!--=============================== r_shoulder_l1o_roll (r_shoulder_l1o_roll_link) ===========================-->
    <joint name="r_shoulder_l1o_roll" type="fixed">
        <origin rpy="2.13851e-14 1.5708 0" xyz="-5.55112e-17 2.55004e-15 -2.77556e-17"/>
        <parent link="r_shoulder_l1_link"/>
        <child link="r_shoulder_l1o_roll_link"/>
    </joint>
    <link name="r_shoulder_l1o_roll_link">
        <inertial>
            <origin rpy="0 0 0" xyz="0 0 0"/>
            <mass value="0.0001"/>
            <inertia ixx="9.9999999999999995e-07" ixy="0" ixz="0" iyy="9.9999999999999995e-07" iyz="0" izz="9.9999999999999995e-07"/>
        </inertial>
    </link>
    <!--=============================== r_shoulder_l2i_roll (r_shoulder_l2i_roll_link) ===========================-->
    <joint name="r_shoulder_l2i_roll" type="fixed">
        <origin rpy="-3.00758 -1.26386 1.5708" xyz="-0.105 -0.009 0.232"/>
        <parent link="torso_link"/>
        <child link="r_shoulder_l2i_roll_link"/>
    </joint>
    <link name="r_shoulder_l2i_roll_link">
        <inertial>
            <origin rpy="0 0 0" xyz="0 0 0"/>
            <mass value="0.0001"/>
            <inertia ixx="9.9999999999999995e-07" ixy="0" ixz="0" iyy="9.9999999999999995e-07" iyz="0" izz="9.9999999999999995e-07"/>
        </inertial>
    </link>
    <!--=============================== r_shoulder_l2i_pitch (r_shoulder_l2i_pitch_link) ===========================-->
    <joint name="r_shoulder_l2i_pitch" type="fixed">
        <origin rpy="3.14159 1.5708 0" xyz="-2.77556e-17 2.77556e-17 -1.38778e-17"/>
        <parent link="r_shoulder_l2i_roll_link"/>
        <child link="r_shoulder_l2i_pitch_link"/>
    </joint>
    <link name="r_shoulder_l2i_pitch_link">
        <visual>
            <origin rpy="0 -0 0" xyz="0 0 0"/>
            <geometry>
                <mesh filename="package://alpha_lite_model_meshes/meshes/pdr_v2/r_shoulder_l2i_pitch_link_collision_hull.stl"/>
            </geometry>
            <material name="r_shoulder_l2i_pitch_link_material">
                <color rgba="0.647059 0.647059 0.647059 1.0"/>
            </material>
        </visual>
        <collision>
            <origin rpy="0 -0 0" xyz="0 0 0"/>
            <geometry>
                <mesh filename="package://alpha_lite_model_meshes/meshes/pdr_v2/r_shoulder_l2i_pitch_link_collision_hull.stl"/>
            </geometry>
            <material name="r_shoulder_l2i_pitch_link_material">
                <color rgba="0.5 0.5 0.5 1.0"/>
            </material>
        </collision>
        <inertial>
            <origin rpy="0 0 0" xyz="0.0721686 -9.72709e-08 0.000423139"/>
            <mass value="0.464999"/>
            <inertia ixx="0.0001157" ixy="-3.88685e-09" ixz="1.27075e-05" iyy="0.000889385" iyz="1.06918e-09" izz="0.000887036"/>
        </inertial>
    </link>
    <!--=============================== r_shoulder_l2 (r_shoulder_l2_link) ===========================-->
    <joint name="r_shoulder_l2" type="fixed">
        <origin rpy="-8.18498e-16 -1.98996e-16 7.91645e-17" xyz="0.1775 2.77556e-17 -9.65412e-05"/>
        <parent link="r_shoulder_l2i_pitch_link"/>
        <child link="r_shoulder_l2_link"/>
    </joint>
    <link name="r_shoulder_l2_link">
        <visual>
            <origin rpy="0 -0 0" xyz="0 0 0"/>
            <geometry>
                <mesh filename="package://alpha_lite_model_meshes/meshes/pdr_v2/r_shoulder_l2_link_collision_hull.stl"/>
            </geometry>
            <material name="r_shoulder_l2_link_material">
                <color rgba="0.647059 0.647059 0.647059 1.0"/>
            </material>
        </visual>
        <collision>
            <origin rpy="0 -0 0" xyz="0 0 0"/>
            <geometry>
                <mesh filename="package://alpha_lite_model_meshes/meshes/pdr_v2/r_shoulder_l2_link_collision_hull.stl"/>
            </geometry>
            <material name="r_shoulder_l2_link_material">
                <color rgba="0.5 0.5 0.5 1.0"/>
            </material>
        </collision>
        <inertial>
            <origin rpy="0 0 0" xyz="-0.0465845 -2.91316e-06 9.65401e-05"/>
            <mass value="0.052"/>
            <inertia ixx="9.28093e-07" ixy="-4.88361e-09" ixz="1.78019e-12" iyy="3.84625e-05" iyz="2.6656e-13" izz="3.84087e-05"/>
        </inertial>
    </link>
    <!--=============================== r_shoulder_l2o_roll (r_shoulder_l2o_roll_link) ===========================-->
    <joint name="r_shoulder_l2o_roll" type="fixed">
        <origin rpy="-1.62395 1.5708 0" xyz="-2.77556e-17 2.53964e-15 -2.77556e-17"/>
        <parent link="r_shoulder_l2_link"/>
        <child link="r_shoulder_l2o_roll_link"/>
    </joint>
    <link name="r_shoulder_l2o_roll_link">
        <inertial>
            <origin rpy="0 0 0" xyz="0 0 0"/>
            <mass value="0.0001"/>
            <inertia ixx="9.9999999999999995e-07" ixy="0" ixz="0" iyy="9.9999999999999995e-07" iyz="0" izz="9.9999999999999995e-07"/>
        </inertial>
    </link>
    <!--=============================== l_shoulder_l2i_roll (l_shoulder_l2i_roll_link) ===========================-->
    <joint name="l_shoulder_l2i_roll" type="fixed">
        <origin rpy="-0.134013 -1.26386 -1.5708" xyz="-0.105 0.009 0.232"/>
        <parent link="torso_link"/>
        <child link="l_shoulder_l2i_roll_link"/>
    </joint>
    <link name="l_shoulder_l2i_roll_link">
        <inertial>
            <origin rpy="0 0 0" xyz="0 0 0"/>
            <mass value="0.0001"/>
            <inertia ixx="9.9999999999999995e-07" ixy="0" ixz="0" iyy="9.9999999999999995e-07" iyz="0" izz="9.9999999999999995e-07"/>
        </inertial>
    </link>
    <!--=============================== l_shoulder_l2i_pitch (l_shoulder_l2i_pitch_link) ===========================-->
    <joint name="l_shoulder_l2i_pitch" type="fixed">
        <origin rpy="-3.14159 -1.56976 4.00307e-13" xyz="2.77556e-17 1.38778e-17 -1.38778e-17"/>
        <parent link="l_shoulder_l2i_roll_link"/>
        <child link="l_shoulder_l2i_pitch_link"/>
    </joint>
    <link name="l_shoulder_l2i_pitch_link">
        <visual>
            <origin rpy="0 -0 0" xyz="0 0 0"/>
            <geometry>
                <mesh filename="package://alpha_lite_model_meshes/meshes/pdr_v2/l_shoulder_l2i_pitch_link_collision_hull.stl"/>
            </geometry>
            <material name="l_shoulder_l2i_pitch_link_material">
                <color rgba="0.647059 0.647059 0.647059 1.0"/>
            </material>
        </visual>
        <collision>
            <origin rpy="0 -0 0" xyz="0 0 0"/>
            <geometry>
                <mesh filename="package://alpha_lite_model_meshes/meshes/pdr_v2/l_shoulder_l2i_pitch_link_collision_hull.stl"/>
            </geometry>
            <material name="l_shoulder_l2i_pitch_link_material">
                <color rgba="0.5 0.5 0.5 1.0"/>
            </material>
        </collision>
        <inertial>
            <origin rpy="0 0 0" xyz="0.0721686 -9.72709e-08 0.000423139"/>
            <mass value="0.464999"/>
            <inertia ixx="0.0001157" ixy="-3.88685e-09" ixz="1.27075e-05" iyy="0.000889385" iyz="1.06918e-09" izz="0.000887036"/>
        </inertial>
    </link>
    <!--=============================== l_shoulder_l2 (l_shoulder_l2_link) ===========================-->
    <joint name="l_shoulder_l2" type="fixed">
        <origin rpy="3.14159 8.18832e-17 -8.58319e-18" xyz="0.1775 0 -9.65412e-05"/>
        <parent link="l_shoulder_l2i_pitch_link"/>
        <child link="l_shoulder_l2_link"/>
    </joint>
    <link name="l_shoulder_l2_link">
        <visual>
            <origin rpy="0 -0 0" xyz="0 0 0"/>
            <geometry>
                <mesh filename="package://alpha_lite_model_meshes/meshes/pdr_v2/l_shoulder_l2_link_collision_hull.stl"/>
            </geometry>
            <material name="l_shoulder_l2_link_material">
                <color rgba="0.647059 0.647059 0.647059 1.0"/>
            </material>
        </visual>
        <collision>
            <origin rpy="0 -0 0" xyz="0 0 0"/>
            <geometry>
                <mesh filename="package://alpha_lite_model_meshes/meshes/pdr_v2/l_shoulder_l2_link_collision_hull.stl"/>
            </geometry>
            <material name="l_shoulder_l2_link_material">
                <color rgba="0.5 0.5 0.5 1.0"/>
            </material>
        </collision>
        <inertial>
            <origin rpy="0 0 0" xyz="-0.0465845 -2.91316e-06 9.65401e-05"/>
            <mass value="0.052"/>
            <inertia ixx="9.28093e-07" ixy="-4.88361e-09" ixz="1.78019e-12" iyy="3.84625e-05" iyz="2.6656e-13" izz="3.84087e-05"/>
        </inertial>
    </link>
    <!--=============================== l_shoulder_l2o_roll (l_shoulder_l2o_roll_link) ===========================-->
    <joint name="l_shoulder_l2o_roll" type="fixed">
        <origin rpy="-2.90349 1.5708 0" xyz="-5.55112e-17 2.55351e-15 0"/>
        <parent link="l_shoulder_l2_link"/>
        <child link="l_shoulder_l2o_roll_link"/>
    </joint>
    <link name="l_shoulder_l2o_roll_link">
        <inertial>
            <origin rpy="0 0 0" xyz="0 0 0"/>
            <mass value="0.0001"/>
            <inertia ixx="9.9999999999999995e-07" ixy="0" ixz="0" iyy="9.9999999999999995e-07" iyz="0" izz="9.9999999999999995e-07"/>
        </inertial>
    </link>
    <!--=============================== l_shoulder_l1i_roll (l_shoulder_l1i_roll_link) ===========================-->
    <joint name="l_shoulder_l1i_roll" type="fixed">
        <origin rpy="-3.00758 -1.26386 -1.5708" xyz="0.005 0.009 0.232"/>
        <parent link="torso_link"/>
        <child link="l_shoulder_l1i_roll_link"/>
    </joint>
    <link name="l_shoulder_l1i_roll_link">
        <inertial>
            <origin rpy="0 0 0" xyz="0 0 0"/>
            <mass value="0.0001"/>
            <inertia ixx="9.9999999999999995e-07" ixy="0" ixz="0" iyy="9.9999999999999995e-07" iyz="0" izz="9.9999999999999995e-07"/>
        </inertial>
    </link>
    <!--=============================== l_shoulder_l1i_pitch (l_shoulder_l1i_pitch_link) ===========================-->
    <joint name="l_shoulder_l1i_pitch" type="fixed">
        <origin rpy="9.67331e-14 1.56976 -3.14159" xyz="0 1.9082e-17 -1.38778e-17"/>
        <parent link="l_shoulder_l1i_roll_link"/>
        <child link="l_shoulder_l1i_pitch_link"/>
    </joint>
    <link name="l_shoulder_l1i_pitch_link">
        <visual>
            <origin rpy="0 -0 0" xyz="0 0 0"/>
            <geometry>
                <mesh filename="package://alpha_lite_model_meshes/meshes/pdr_v2/l_shoulder_l1i_pitch_link_collision_hull.stl"/>
            </geometry>
            <material name="l_shoulder_l1i_pitch_link_material">
                <color rgba="0.647059 0.647059 0.647059 1.0"/>
            </material>
        </visual>
        <collision>
            <origin rpy="0 -0 0" xyz="0 0 0"/>
            <geometry>
                <mesh filename="package://alpha_lite_model_meshes/meshes/pdr_v2/l_shoulder_l1i_pitch_link_collision_hull.stl"/>
            </geometry>
            <material name="l_shoulder_l1i_pitch_link_material">
                <color rgba="0.5 0.5 0.5 1.0"/>
            </material>
        </collision>
        <inertial>
            <origin rpy="0 0 0" xyz="0.0721686 -9.72709e-08 0.000423139"/>
            <mass value="0.464999"/>
            <inertia ixx="0.0001157" ixy="-3.88685e-09" ixz="1.27075e-05" iyy="0.000889385" iyz="1.06918e-09" izz="0.000887036"/>
        </inertial>
    </link>
    <!--=============================== l_shoulder_l1 (l_shoulder_l1_link) ===========================-->
    <joint name="l_shoulder_l1" type="fixed">
        <origin rpy="-3.14159 -1.83594e-15 -1.31764e-17" xyz="0.1775 1.73472e-18 -9.65412e-05"/>
        <parent link="l_shoulder_l1i_pitch_link"/>
        <child link="l_shoulder_l1_link"/>
    </joint>
    <link name="l_shoulder_l1_link">
        <visual>
            <origin rpy="0 -0 0" xyz="0 0 0"/>
            <geometry>
                <mesh filename="package://alpha_lite_model_meshes/meshes/pdr_v2/l_shoulder_l1_link_collision_hull.stl"/>
            </geometry>
            <material name="l_shoulder_l1_link_material">
                <color rgba="0.647059 0.647059 0.647059 1.0"/>
            </material>
        </visual>
        <collision>
            <origin rpy="0 -0 0" xyz="0 0 0"/>
            <geometry>
                <mesh filename="package://alpha_lite_model_meshes/meshes/pdr_v2/l_shoulder_l1_link_collision_hull.stl"/>
            </geometry>
            <material name="l_shoulder_l1_link_material">
                <color rgba="0.5 0.5 0.5 1.0"/>
            </material>
        </collision>
        <inertial>
            <origin rpy="0 0 0" xyz="-0.0465845 -2.91316e-06 9.65401e-05"/>
            <mass value="0.052"/>
            <inertia ixx="9.28093e-07" ixy="-4.88361e-09" ixz="1.78019e-12" iyy="3.84625e-05" iyz="2.6656e-13" izz="3.84087e-05"/>
        </inertial>
    </link>
    <!--=============================== l_shoulder_l1o_roll (l_shoulder_l1o_roll_link) ===========================-->
    <joint name="l_shoulder_l1o_roll" type="fixed">
        <origin rpy="-2.25384 1.5708 0" xyz="0 2.54137e-15 -5.55112e-17"/>
        <parent link="l_shoulder_l1_link"/>
        <child link="l_shoulder_l1o_roll_link"/>
    </joint>
    <link name="l_shoulder_l1o_roll_link">
        <inertial>
            <origin rpy="0 0 0" xyz="0 0 0"/>
            <mass value="0.0001"/>
            <inertia ixx="9.9999999999999995e-07" ixy="0" ixz="0" iyy="9.9999999999999995e-07" iyz="0" izz="9.9999999999999995e-07"/>
        </inertial>
    </link>
    <!--=============================== l_shoulder_aa (l_shoulder_aa_link) ===========================-->
    <joint name="l_shoulder_aa" type="revolute">
        <origin rpy="5.55112e-17 3.74325e-16 -2.92467e-18" xyz="-0.05 0.2 0.32"/>
        <parent link="torso_link"/>
        <child link="l_shoulder_aa_link"/>
        <axis xyz="1 0 0"/>
        <limit effort="78.0" lower="-0.17453292519943295" upper="1.6580627893946132" velocity="9.4"/>
    </joint>
    <link name="l_shoulder_aa_link">
        <visual>
            <origin rpy="0 -0 0" xyz="0 0 0"/>
            <geometry>
                <mesh filename="package://alpha_lite_model_meshes/meshes/pdr_v2/l_shoulder_aa_link_collision_hull.stl"/>
            </geometry>
            <material name="l_shoulder_aa_link_material">
                <color rgba="0.473021 0.475321 0.471935 1.0"/>
            </material>
        </visual>
        <collision>
            <origin rpy="0 -0 0" xyz="0 0 0"/>
            <geometry>
                <mesh filename="package://alpha_lite_model_meshes/meshes/pdr_v2/l_shoulder_aa_link_collision_hull.stl"/>
            </geometry>
            <material name="l_shoulder_aa_link_material">
                <color rgba="0.5 0.5 0.5 1.0"/>
            </material>
        </collision>
        <inertial>
            <origin rpy="0 0 0" xyz="0.00156066 -2.63043e-17 -0.0182312"/>
            <mass value="0.0864662"/>
            <inertia ixx="2.64218e-05" ixy="6.1913e-10" ixz="-2.461e-06" iyy="3.56128e-05" iyz="1.86011e-09" izz="1.24461e-05"/>
        </inertial>
    </link>
    <!--=============================== l_shoulder_ie (l_shoulder_ie_link) ===========================-->
    <joint name="l_shoulder_ie" type="revolute">
        <origin rpy="-2.22045e-16 -3.52263e-16 9.57994e-17" xyz="0 0 0"/>
        <parent link="l_shoulder_aa_link"/>
        <child link="l_shoulder_ie_link"/>
        <axis xyz="0 0 1"/>
        <limit effort="67.0" lower="-0.5235987755982988" upper="0.5235987755982988" velocity="11.0"/>
    </joint>
    <link name="l_shoulder_ie_link">
        <visual>
            <origin rpy="0 -0 0" xyz="0 0 0"/>
            <geometry>
                <mesh filename="package://alpha_lite_model_meshes/meshes/pdr_v2/l_shoulder_ie_link_collision_hull.stl"/>
            </geometry>
            <material name="l_shoulder_ie_link_material">
                <color rgba="0.431877 0.432112 0.432984 1.0"/>
            </material>
        </visual>
        <collision>
            <origin rpy="0 -0 0" xyz="0 0 0"/>
            <geometry>
                <mesh filename="package://alpha_lite_model_meshes/meshes/pdr_v2/l_shoulder_ie_link_collision_hull.stl"/>
            </geometry>
            <material name="l_shoulder_ie_link_material">
                <color rgba="0.5 0.5 0.5 1.0"/>
            </material>
        </collision>
        <inertial>
            <origin rpy="0 0 0" xyz="-9.00963e-05 0.00844074 -0.0257918"/>
            <mass value="0.271256"/>
            <inertia ixx="0.000233543" ixy="1.99924e-05" ixz="-1.48263e-05" iyy="0.000306642" iyz="-4.58375e-05" izz="0.000198441"/>
        </inertial>
    </link>
    <!--=============================== l_shoulder_l2_fix (l_shoulder_l2_fix_link) ===========================-->
    <joint name="l_shoulder_l2_fix" type="fixed">
        <origin rpy="-0.474476 -0.0641212 -0.124117" xyz="-0.03 -0.0142358 -0.0319741"/>
        <parent link="l_shoulder_ie_link"/>
        <child link="l_shoulder_l2_fix_link"/>
    </joint>
    <link name="l_shoulder_l2_fix_link">
        <inertial>
            <origin rpy="0 0 0" xyz="0 0 0"/>
            <mass value="0.0001"/>
            <inertia ixx="9.9999999999999995e-07" ixy="0" ixz="0" iyy="9.9999999999999995e-07" iyz="0" izz="9.9999999999999995e-07"/>
        </inertial>
    </link>
    <!--=============================== l_shoulder_l1_fix (l_shoulder_l1_fix_link) ===========================-->
    <joint name="l_shoulder_l1_fix" type="fixed">
        <origin rpy="-0.474476 0.0641212 0.124117" xyz="0.03 -0.0142358 -0.0319741"/>
        <parent link="l_shoulder_ie_link"/>
        <child link="l_shoulder_l1_fix_link"/>
    </joint>
    <link name="l_shoulder_l1_fix_link">
        <inertial>
            <origin rpy="0 0 0" xyz="0 0 0"/>
            <mass value="0.0001"/>
            <inertia ixx="9.9999999999999995e-07" ixy="0" ixz="0" iyy="9.9999999999999995e-07" iyz="0" izz="9.9999999999999995e-07"/>
        </inertial>
    </link>
    <!--=============================== l_shoulder_fe (l_shoulder_fe_link) ===========================-->
    <joint name="l_shoulder_fe" type="revolute">
        <origin rpy="1.09743e-30 -3.35618e-16 -0.261799" xyz="0.0104822 0.03912 0"/>
        <parent link="l_shoulder_ie_link"/>
        <child link="l_shoulder_fe_link"/>
        <axis xyz="0 1 0"/>
        <limit effort="114.0" lower="-2.181661564992912" upper="0.6108652381980153" velocity="6.3"/>
    </joint>
    <link name="l_shoulder_fe_link">
        <visual>
            <origin rpy="0 -0 0" xyz="0 0 0"/>
            <geometry>
                <mesh filename="package://alpha_lite_model_meshes/meshes/pdr_v2/l_shoulder_fe_link_collision_hull.stl"/>
            </geometry>
            <material name="l_shoulder_fe_link_material">
                <color rgba="0.420728 0.421714 0.42242 1.0"/>
            </material>
        </visual>
        <collision>
            <origin rpy="0 -0 0" xyz="0 0 0"/>
            <geometry>
                <mesh filename="package://alpha_lite_model_meshes/meshes/pdr_v2/l_shoulder_fe_link_collision_hull.stl"/>
            </geometry>
            <material name="l_shoulder_fe_link_material">
                <color rgba="0.5 0.5 0.5 1.0"/>
            </material>
        </collision>
        <inertial>
            <origin rpy="0 0 0" xyz="-0.00944273 -0.000207581 -0.135062"/>
            <mass value="1.70632"/>
            <inertia ixx="0.0141931" ixy="-0.000134492" ixz="0.000768075" iyy="0.0165657" iyz="7.63702e-05" izz="0.00377857"/>
        </inertial>
    </link>
    <!--=============================== l_shoulder_l3_fix (l_shoulder_l3_fix_link) ===========================-->
    <joint name="l_shoulder_l3_fix" type="fixed">
        <origin rpy="-3.14159 5.91646e-31 -3.28048e-17" xyz="-0.0290751 0 -0.282383"/>
        <parent link="l_shoulder_fe_link"/>
        <child link="l_shoulder_l3_fix_link"/>
    </joint>
    <link name="l_shoulder_l3_fix_link">
        <inertial>
            <origin rpy="0 0 0" xyz="0 0 0"/>
            <mass value="0.0001"/>
            <inertia ixx="9.9999999999999995e-07" ixy="0" ixz="0" iyy="9.9999999999999995e-07" iyz="0" izz="9.9999999999999995e-07"/>
        </inertial>
    </link>
    <!--=============================== l_elbow_fe (l_elbow_fe_link) ===========================-->
    <joint name="l_elbow_fe" type="revolute">
        <origin rpy="2.46519e-32 -0 2.54143e-15" xyz="0.025 0 -0.315"/>
        <parent link="l_shoulder_fe_link"/>
        <child link="l_elbow_fe_link"/>
        <axis xyz="0 1 0"/>
        <limit effort="114.0" lower="-2.6179938779914944" upper="0.17453292519943295" velocity="6.3"/>
    </joint>
    <link name="l_elbow_fe_link">
        <visual>
            <origin rpy="0 -0 0" xyz="0 0 0"/>
            <geometry>
                <mesh filename="package://alpha_lite_model_meshes/meshes/pdr_v2/l_elbow_fe_link_collision_hull.stl"/>
            </geometry>
            <material name="l_elbow_fe_link_material">
                <color rgba="0.41197 0.410881 0.407796 1.0"/>
            </material>
        </visual>
        <collision>
            <origin rpy="0 -0 0" xyz="0 0 0"/>
            <geometry>
                <mesh filename="package://alpha_lite_model_meshes/meshes/pdr_v2/l_elbow_fe_link_collision_hull.stl"/>
            </geometry>
            <material name="l_elbow_fe_link_material">
                <color rgba="0.5 0.5 0.5 1.0"/>
            </material>
        </collision>
        <inertial>
            <origin rpy="0 0 0" xyz="-0.0118949 1.64517e-08 -0.142016"/>
            <mass value="0.646999"/>
            <inertia ixx="0.0108257" ixy="1.38756e-10" ixz="-0.000636073" iyy="0.0108076" iyz="2.77586e-08" izz="0.000283499"/>
        </inertial>
    </link>
    <!--=============================== l_elbow_l1_fix (l_elbow_l1_fix_link) ===========================-->
    <joint name="l_elbow_l1_fix" type="fixed">
        <origin rpy="3.14159 1.03806e-14 -1.5708" xyz="0.0105423 -5.55112e-17 -0.0365084"/>
        <parent link="l_elbow_fe_link"/>
        <child link="l_elbow_l1_fix_link"/>
    </joint>
    <link name="l_elbow_l1_fix_link">
        <inertial>
            <origin rpy="0 0 0" xyz="0 0 0"/>
            <mass value="0.0001"/>
            <inertia ixx="9.9999999999999995e-07" ixy="0" ixz="0" iyy="9.9999999999999995e-07" iyz="0" izz="9.9999999999999995e-07"/>
        </inertial>
    </link>
    <!--=============================== l_hand (l_hand_link) ===========================-->
    <joint name="l_hand" type="fixed">
        <origin rpy="1.5708 1.5708 0" xyz="-0.025 -5.55112e-17 -0.36"/>
        <parent link="l_elbow_fe_link"/>
        <child link="l_hand_link"/>
    </joint>
    <link name="l_hand_link">
        <inertial>
            <origin rpy="0 0 0" xyz="0 0 0"/>
            <mass value="0.0001"/>
            <inertia ixx="9.9999999999999995e-07" ixy="0" ixz="0" iyy="9.9999999999999995e-07" iyz="0" izz="9.9999999999999995e-07"/>
        </inertial>
    </link>
    <!--=============================== l_elbow_l1i_pitch (l_elbow_l1i_pitch_link) ===========================-->
    <joint name="l_elbow_l1i_pitch" type="fixed">
        <origin rpy="3.14159 1.51275 3.14159" xyz="0.0540751 0 -0.0326173"/>
        <parent link="l_shoulder_fe_link"/>
        <child link="l_elbow_l1i_pitch_link"/>
    </joint>
    <link name="l_elbow_l1i_pitch_link">
        <visual>
            <origin rpy="0 -0 0" xyz="0 0 0"/>
            <geometry>
                <mesh filename="package://alpha_lite_model_meshes/meshes/pdr_v2/l_elbow_l1i_pitch_link_collision_hull.stl"/>
            </geometry>
            <material name="l_elbow_l1i_pitch_link_material">
                <color rgba="0.647059 0.647059 0.647059 1.0"/>
            </material>
        </visual>
        <collision>
            <origin rpy="0 -0 0" xyz="0 0 0"/>
            <geometry>
                <mesh filename="package://alpha_lite_model_meshes/meshes/pdr_v2/l_elbow_l1i_pitch_link_collision_hull.stl"/>
            </geometry>
            <material name="l_elbow_l1i_pitch_link_material">
                <color rgba="0.5 0.5 0.5 1.0"/>
            </material>
        </collision>
        <inertial>
            <origin rpy="0 0 0" xyz="0.103018 9.28819e-06 0.00025801"/>
            <mass value="0.785"/>
            <inertia ixx="0.000287605" ixy="6.41759e-07" ixz="1.44488e-05" iyy="0.00245437" iyz="-1.21859e-07" izz="0.00245075"/>
        </inertial>
    </link>
    <!--=============================== l_elbow_l1 (l_elbow_l1_link) ===========================-->
    <joint name="l_elbow_l1" type="fixed">
        <origin rpy="3.5579e-15 1.09244e-17 -1.2002e-18" xyz="0.2449 1.11022e-16 -2.77556e-17"/>
        <parent link="l_elbow_l1i_pitch_link"/>
        <child link="l_elbow_l1_link"/>
        <axis xyz="1 3.27098e-16 0"/>
        <limit effort="1131" lower="0.0" upper="0.0775" velocity="0.237538753"/>
    </joint>
    <link name="l_elbow_l1_link">
        <visual>
            <origin rpy="0 -0 0" xyz="0 0 0"/>
            <geometry>
                <mesh filename="package://alpha_lite_model_meshes/meshes/pdr_v2/l_elbow_l1_link_collision_hull.stl"/>
            </geometry>
            <material name="l_elbow_l1_link_material">
                <color rgba="0.647059 0.647059 0.647059 1.0"/>
            </material>
        </visual>
        <collision>
            <origin rpy="0 -0 0" xyz="0 0 0"/>
            <geometry>
                <mesh filename="package://alpha_lite_model_meshes/meshes/pdr_v2/l_elbow_l1_link_collision_hull.stl"/>
            </geometry>
            <material name="l_elbow_l1_link_material">
                <color rgba="0.5 0.5 0.5 1.0"/>
            </material>
        </collision>
        <inertial>
            <origin rpy="0 0 0" xyz="-0.064709 -1.12912e-16 -1.74518e-16"/>
            <mass value="0.122"/>
            <inertia ixx="3.75405e-06" ixy="-1.90853e-22" ixz="-8.12456e-22" iyy="0.000142764" iyz="1.29857e-12" izz="0.000142587"/>
        </inertial>
    </link>
    <!--=============================== l_shoulder_l3i_pitch (l_shoulder_l3i_pitch_link) ===========================-->
    <joint name="l_shoulder_l3i_pitch" type="fixed">
        <origin rpy="-1.03799e-13 -1.56908 -0.261799" xyz="-0.0171746 0.0465306 -0.0249837"/>
        <parent link="l_shoulder_ie_link"/>
        <child link="l_shoulder_l3i_pitch_link"/>
    </joint>
    <link name="l_shoulder_l3i_pitch_link">
        <visual>
            <origin rpy="0 -0 0" xyz="0 0 0"/>
            <geometry>
                <mesh filename="package://alpha_lite_model_meshes/meshes/pdr_v2/l_shoulder_l3i_pitch_link_collision_hull.stl"/>
            </geometry>
            <material name="l_shoulder_l3i_pitch_link_material">
                <color rgba="0.647059 0.647059 0.647059 1.0"/>
            </material>
        </visual>
        <collision>
            <origin rpy="0 -0 0" xyz="0 0 0"/>
            <geometry>
                <mesh filename="package://alpha_lite_model_meshes/meshes/pdr_v2/l_shoulder_l3i_pitch_link_collision_hull.stl"/>
            </geometry>
            <material name="l_shoulder_l3i_pitch_link_material">
                <color rgba="0.5 0.5 0.5 1.0"/>
            </material>
        </collision>
        <inertial>
            <origin rpy="0 0 0" xyz="-0.064709 2.61017e-17 -2.56778e-16"/>
            <mass value="0.122"/>
            <inertia ixx="3.75405e-06" ixy="-4.67869e-24" ixz="1.71004e-23" iyy="0.000142764" iyz="1.29857e-12" izz="0.000142587"/>
        </inertial>
    </link>
    <!--=============================== l_shoulder_l3 (l_shoulder_l3_link) ===========================-->
    <joint name="l_shoulder_l3" type="fixed">
        <origin rpy="6.50038e-16 -5.45906e-18 -3.77659e-16" xyz="-0.2449 1.38778e-16 -8.32667e-17"/>
        <parent link="l_shoulder_l3i_pitch_link"/>
        <child link="l_shoulder_l3_link"/>
    </joint>
    <link name="l_shoulder_l3_link">
        <visual>
            <origin rpy="0 -0 0" xyz="0 0 0"/>
            <geometry>
                <mesh filename="package://alpha_lite_model_meshes/meshes/pdr_v2/l_shoulder_l3_link_collision_hull.stl"/>
            </geometry>
            <material name="l_shoulder_l3_link_material">
                <color rgba="0.647059 0.647059 0.647059 1.0"/>
            </material>
        </visual>
        <collision>
            <origin rpy="0 -0 0" xyz="0 0 0"/>
            <geometry>
                <mesh filename="package://alpha_lite_model_meshes/meshes/pdr_v2/l_shoulder_l3_link_collision_hull.stl"/>
            </geometry>
            <material name="l_shoulder_l3_link_material">
                <color rgba="0.5 0.5 0.5 1.0"/>
            </material>
        </collision>
        <inertial>
            <origin rpy="0 0 0" xyz="0.103018 9.28819e-06 0.00025801"/>
            <mass value="0.785"/>
            <inertia ixx="0.000287605" ixy="6.41759e-07" ixz="1.44488e-05" iyy="0.00245437" iyz="-1.21859e-07" izz="0.00245075"/>
        </inertial>
    </link>
    <!--=============================== r_shoulder_aa (r_shoulder_aa_link) ===========================-->
    <joint name="r_shoulder_aa" type="revolute">
        <origin rpy="-1.11022e-16 2.83178e-16 1.2063e-16" xyz="-0.05 -0.2 0.32"/>
        <parent link="torso_link"/>
        <child link="r_shoulder_aa_link"/>
        <axis xyz="1 0 0"/>
        <limit effort="78.0" lower="-1.6580627893946132" upper="0.17453292519943295" velocity="9.4"/>
    </joint>
    <link name="r_shoulder_aa_link">
        <visual>
            <origin rpy="0 -0 0" xyz="0 0 0"/>
            <geometry>
                <mesh filename="package://alpha_lite_model_meshes/meshes/pdr_v2/r_shoulder_aa_link_collision_hull.stl"/>
            </geometry>
            <material name="r_shoulder_aa_link_material">
                <color rgba="0.473021 0.475321 0.471935 1.0"/>
            </material>
        </visual>
        <collision>
            <origin rpy="0 -0 0" xyz="0 0 0"/>
            <geometry>
                <mesh filename="package://alpha_lite_model_meshes/meshes/pdr_v2/r_shoulder_aa_link_collision_hull.stl"/>
            </geometry>
            <material name="r_shoulder_aa_link_material">
                <color rgba="0.5 0.5 0.5 1.0"/>
            </material>
        </collision>
        <inertial>
            <origin rpy="0 0 0" xyz="0.00156066 2.28537e-17 -0.0182312"/>
            <mass value="0.0864662"/>
            <inertia ixx="2.64218e-05" ixy="6.1913e-10" ixz="-2.461e-06" iyy="3.56128e-05" iyz="1.86011e-09" izz="1.24461e-05"/>
        </inertial>
    </link>
    <!--=============================== r_shoulder_ie (r_shoulder_ie_link) ===========================-->
    <joint name="r_shoulder_ie" type="revolute">
        <origin rpy="-1.11022e-15 -2.88871e-16 -3.73636e-17" xyz="-4.16334e-17 0 5.55112e-17"/>
        <parent link="r_shoulder_aa_link"/>
        <child link="r_shoulder_ie_link"/>
        <axis xyz="0 0 1"/>
        <limit effort="67.0" lower="-0.5235987755982988" upper="0.5235987755982988" velocity="11.0"/>
    </joint>
    <link name="r_shoulder_ie_link">
        <visual>
            <origin rpy="0 -0 0" xyz="0 0 0"/>
            <geometry>
                <mesh filename="package://alpha_lite_model_meshes/meshes/pdr_v2/r_shoulder_ie_link_collision_hull.stl"/>
            </geometry>
            <material name="r_shoulder_ie_link_material">
                <color rgba="0.431877 0.432113 0.432984 1.0"/>
            </material>
        </visual>
        <collision>
            <origin rpy="0 -0 0" xyz="0 0 0"/>
            <geometry>
                <mesh filename="package://alpha_lite_model_meshes/meshes/pdr_v2/r_shoulder_ie_link_collision_hull.stl"/>
            </geometry>
            <material name="r_shoulder_ie_link_material">
                <color rgba="0.5 0.5 0.5 1.0"/>
            </material>
        </collision>
        <inertial>
            <origin rpy="0 0 0" xyz="-9.01814e-05 -0.00843926 -0.0258017"/>
            <mass value="0.271255"/>
            <inertia ixx="0.000233767" ixy="-1.99935e-05" ixz="-1.48282e-05" iyy="0.000306599" iyz="4.58651e-05" izz="0.000198447"/>
        </inertial>
    </link>
    <!--=============================== r_shoulder_l1_fix (r_shoulder_l1_fix_link) ===========================-->
    <joint name="r_shoulder_l1_fix" type="fixed">
        <origin rpy="-9.4369e-16 -4.16334e-17 -2.56739e-16" xyz="0.03 0.0142358 -0.0319741"/>
        <parent link="r_shoulder_ie_link"/>
        <child link="r_shoulder_l1_fix_link"/>
    </joint>
    <link name="r_shoulder_l1_fix_link">
        <inertial>
            <origin rpy="0 0 0" xyz="0 0 0"/>
            <mass value="0.0001"/>
            <inertia ixx="9.9999999999999995e-07" ixy="0" ixz="0" iyy="9.9999999999999995e-07" iyz="0" izz="9.9999999999999995e-07"/>
        </inertial>
    </link>
    <!--=============================== r_shoulder_l2_fix (r_shoulder_l2_fix_link) ===========================-->
    <joint name="r_shoulder_l2_fix" type="fixed">
        <origin rpy="-4.44089e-16 -6.93889e-17 -1.45717e-16" xyz="-0.03 0.0142358 -0.0319741"/>
        <parent link="r_shoulder_ie_link"/>
        <child link="r_shoulder_l2_fix_link"/>
    </joint>
    <link name="r_shoulder_l2_fix_link">
        <inertial>
            <origin rpy="0 0 0" xyz="0 0 0"/>
            <mass value="0.0001"/>
            <inertia ixx="9.9999999999999995e-07" ixy="0" ixz="0" iyy="9.9999999999999995e-07" iyz="0" izz="9.9999999999999995e-07"/>
        </inertial>
    </link>
    <!--=============================== r_shoulder_fe (r_shoulder_fe_link) ===========================-->
    <joint name="r_shoulder_fe" type="revolute">
        <origin rpy="1.78438e-31 -2.82827e-16 0.261799" xyz="0.0104822 -0.03912 0"/>
        <parent link="r_shoulder_ie_link"/>
        <child link="r_shoulder_fe_link"/>
        <axis xyz="0 1 0"/>
        <limit effort="114.0" lower="-2.181661564992912" upper="0.6108652381980153" velocity="6.3"/>
    </joint>
    <link name="r_shoulder_fe_link">
        <visual>
            <origin rpy="0 -0 0" xyz="0 0 0"/>
            <geometry>
                <mesh filename="package://alpha_lite_model_meshes/meshes/pdr_v2/r_shoulder_fe_link_collision_hull.stl"/>
            </geometry>
            <material name="r_shoulder_fe_link_material">
                <color rgba="0.420633 0.422371 0.423313 1.0"/>
            </material>
        </visual>
        <collision>
            <origin rpy="0 -0 0" xyz="0 0 0"/>
            <geometry>
                <mesh filename="package://alpha_lite_model_meshes/meshes/pdr_v2/r_shoulder_fe_link_collision_hull.stl"/>
            </geometry>
            <material name="r_shoulder_fe_link_material">
                <color rgba="0.5 0.5 0.5 1.0"/>
            </material>
        </collision>
        <inertial>
            <origin rpy="0 0 0" xyz="-0.00918662 -0.000298561 -0.132935"/>
            <mass value="1.70678"/>
            <inertia ixx="0.0140809" ixy="4.02173e-05" ixz="0.000738178" iyy="0.0164814" iyz="-7.46488e-06" izz="0.00378927"/>
        </inertial>
    </link>
    <!--=============================== r_shoulder_l3_fix (r_shoulder_l3_fix_link) ===========================-->
    <joint name="r_shoulder_l3_fix" type="fixed">
        <origin rpy="-3.14159 -5.68989e-16 -2.26025e-16" xyz="-0.0290751 0 -0.282383"/>
        <parent link="r_shoulder_fe_link"/>
        <child link="r_shoulder_l3_fix_link"/>
    </joint>
    <link name="r_shoulder_l3_fix_link">
        <inertial>
            <origin rpy="0 0 0" xyz="0 0 0"/>
            <mass value="0.0001"/>
            <inertia ixx="9.9999999999999995e-07" ixy="0" ixz="0" iyy="9.9999999999999995e-07" iyz="0" izz="9.9999999999999995e-07"/>
        </inertial>
    </link>
    <!--=============================== r_elbow_fe (r_elbow_fe_link) ===========================-->
    <joint name="r_elbow_fe" type="revolute">
        <origin rpy="1.33669e-30 1.249e-16 1.20908e-15" xyz="0.025 0 -0.315"/>
        <parent link="r_shoulder_fe_link"/>
        <child link="r_elbow_fe_link"/>
        <axis xyz="0 1 0"/>
        <limit effort="114.0" lower="-2.6179938779914944" upper="0.17453292519943295" velocity="6.3"/>
    </joint>
    <link name="r_elbow_fe_link">
        <visual>
            <origin rpy="0 -0 0" xyz="0 0 0"/>
            <geometry>
                <mesh filename="package://alpha_lite_model_meshes/meshes/pdr_v2/r_elbow_fe_link_collision_hull.stl"/>
            </geometry>
            <material name="r_elbow_fe_link_material">
                <color rgba="0.41197 0.410881 0.407796 1.0"/>
            </material>
        </visual>
        <collision>
            <origin rpy="0 -0 0" xyz="0 0 0"/>
            <geometry>
                <mesh filename="package://alpha_lite_model_meshes/meshes/pdr_v2/r_elbow_fe_link_collision_hull.stl"/>
            </geometry>
            <material name="r_elbow_fe_link_material">
                <color rgba="0.5 0.5 0.5 1.0"/>
            </material>
        </collision>
        <inertial>
            <origin rpy="0 0 0" xyz="-0.0118949 1.64517e-08 -0.142016"/>
            <mass value="0.646999"/>
            <inertia ixx="0.0108257" ixy="1.38756e-10" ixz="-0.000636073" iyy="0.0108076" iyz="2.77586e-08" izz="0.000283499"/>
        </inertial>
    </link>
    <!--=============================== r_elbow_l1_fix (r_elbow_l1_fix_link) ===========================-->
    <joint name="r_elbow_l1_fix" type="fixed">
        <origin rpy="3.14159 2.35406e-30 -1.5708" xyz="0.0105423 1.11022e-15 -0.0365084"/>
        <parent link="r_elbow_fe_link"/>
        <child link="r_elbow_l1_fix_link"/>
    </joint>
    <link name="r_elbow_l1_fix_link">
        <inertial>
            <origin rpy="0 0 0" xyz="0 0 0"/>
            <mass value="0.0001"/>
            <inertia ixx="9.9999999999999995e-07" ixy="0" ixz="0" iyy="9.9999999999999995e-07" iyz="0" izz="9.9999999999999995e-07"/>
        </inertial>
    </link>
    <!--=============================== r_hand (r_hand_link) ===========================-->
    <joint name="r_hand" type="fixed">
        <origin rpy="-1.5708 1.5708 0" xyz="-0.025 -1.60982e-15 -0.36"/>
        <parent link="r_elbow_fe_link"/>
        <child link="r_hand_link"/>
    </joint>
    <link name="r_hand_link">
        <inertial>
            <origin rpy="0 0 0" xyz="0 0 0"/>
            <mass value="0.0001"/>
            <inertia ixx="9.9999999999999995e-07" ixy="0" ixz="0" iyy="9.9999999999999995e-07" iyz="0" izz="9.9999999999999995e-07"/>
        </inertial>
    </link>
    <!--=============================== r_elbow_l1i_pitch (r_elbow_l1i_pitch_link) ===========================-->
    <joint name="r_elbow_l1i_pitch" type="fixed">
        <origin rpy="-3.14159 1.51275 -3.14159" xyz="0.0540751 -2.77556e-17 -0.0326173"/>
        <parent link="r_shoulder_fe_link"/>
        <child link="r_elbow_l1i_pitch_link"/>
    </joint>
    <link name="r_elbow_l1i_pitch_link">
        <visual>
            <origin rpy="0 -0 0" xyz="0 0 0"/>
            <geometry>
                <mesh filename="package://alpha_lite_model_meshes/meshes/pdr_v2/r_elbow_l1i_pitch_link_collision_hull.stl"/>
            </geometry>
            <material name="r_elbow_l1i_pitch_link_material">
                <color rgba="0.647059 0.647059 0.647059 1.0"/>
            </material>
        </visual>
        <collision>
            <origin rpy="0 -0 0" xyz="0 0 0"/>
            <geometry>
                <mesh filename="package://alpha_lite_model_meshes/meshes/pdr_v2/r_elbow_l1i_pitch_link_collision_hull.stl"/>
            </geometry>
            <material name="r_elbow_l1i_pitch_link_material">
                <color rgba="0.5 0.5 0.5 1.0"/>
            </material>
        </collision>
        <inertial>
            <origin rpy="0 0 0" xyz="0.103018 9.28819e-06 0.00025801"/>
            <mass value="0.785"/>
            <inertia ixx="0.000287605" ixy="6.41759e-07" ixz="1.44488e-05" iyy="0.00245437" iyz="-1.21859e-07" izz="0.00245075"/>
        </inertial>
    </link>
    <!--=============================== r_elbow_l1 (r_elbow_l1_link) ===========================-->
    <joint name="r_elbow_l1" type="fixed">
        <origin rpy="-9.22776e-15 4.79601e-18 -1.35493e-16" xyz="0.2449 2.498e-16 1.38778e-17"/>
        <parent link="r_elbow_l1i_pitch_link"/>
        <child link="r_elbow_l1_link"/>
    </joint>
    <link name="r_elbow_l1_link">
        <visual>
            <origin rpy="0 -0 0" xyz="0 0 0"/>
            <geometry>
                <mesh filename="package://alpha_lite_model_meshes/meshes/pdr_v2/r_elbow_l1_link_collision_hull.stl"/>
            </geometry>
            <material name="r_elbow_l1_link_material">
                <color rgba="0.647059 0.647059 0.647059 1.0"/>
            </material>
        </visual>
        <collision>
            <origin rpy="0 -0 0" xyz="0 0 0"/>
            <geometry>
                <mesh filename="package://alpha_lite_model_meshes/meshes/pdr_v2/r_elbow_l1_link_collision_hull.stl"/>
            </geometry>
            <material name="r_elbow_l1_link_material">
                <color rgba="0.5 0.5 0.5 1.0"/>
            </material>
        </collision>
        <inertial>
            <origin rpy="0 0 0" xyz="-0.064709 -1.12266e-16 -1.72818e-16"/>
            <mass value="0.122"/>
            <inertia ixx="3.75405e-06" ixy="3.20004e-22" ixz="5.7054e-22" iyy="0.000142764" iyz="1.29857e-12" izz="0.000142587"/>
        </inertial>
    </link>
    <!--=============================== r_shoulder_l3i_pitch (r_shoulder_l3i_pitch_link) ===========================-->
    <joint name="r_shoulder_l3i_pitch" type="fixed">
        <origin rpy="1.99634e-14 -1.56908 0.261799" xyz="-0.0171746 -0.0465306 -0.0249837"/>
        <parent link="r_shoulder_ie_link"/>
        <child link="r_shoulder_l3i_pitch_link"/>
    </joint>
    <link name="r_shoulder_l3i_pitch_link">
        <visual>
            <origin rpy="0 -0 0" xyz="0 0 0"/>
            <geometry>
                <mesh filename="package://alpha_lite_model_meshes/meshes/pdr_v2/r_shoulder_l3i_pitch_link_collision_hull.stl"/>
            </geometry>
            <material name="r_shoulder_l3i_pitch_link_material">
                <color rgba="0.647059 0.647059 0.647059 1.0"/>
            </material>
        </visual>
        <collision>
            <origin rpy="0 -0 0" xyz="0 0 0"/>
            <geometry>
                <mesh filename="package://alpha_lite_model_meshes/meshes/pdr_v2/r_shoulder_l3i_pitch_link_collision_hull.stl"/>
            </geometry>
            <material name="r_shoulder_l3i_pitch_link_material">
                <color rgba="0.5 0.5 0.5 1.0"/>
            </material>
        </collision>
        <inertial>
            <origin rpy="0 0 0" xyz="-0.064709 -1.65082e-18 -2.84607e-16"/>
            <mass value="0.122"/>
            <inertia ixx="3.75405e-06" ixy="-2.42429e-24" ixz="-4.19746e-23" iyy="0.000142764" iyz="1.29857e-12" izz="0.000142587"/>
        </inertial>
    </link>
    <!--=============================== r_shoulder_l3 (r_shoulder_l3_link) ===========================-->
    <joint name="r_shoulder_l3" type="fixed">
        <origin rpy="-1.7553e-17 1.93875e-19 -1.20491e-19" xyz="-0.2449 -2.77556e-17 -8.32667e-17"/>
        <parent link="r_shoulder_l3i_pitch_link"/>
        <child link="r_shoulder_l3_link"/>
    </joint>
    <link name="r_shoulder_l3_link">
        <visual>
            <origin rpy="0 -0 0" xyz="0 0 0"/>
            <geometry>
                <mesh filename="package://alpha_lite_model_meshes/meshes/pdr_v2/r_shoulder_l3_link_collision_hull.stl"/>
            </geometry>
            <material name="r_shoulder_l3_link_material">
                <color rgba="0.647059 0.647059 0.647059 1.0"/>
            </material>
        </visual>
        <collision>
            <origin rpy="0 -0 0" xyz="0 0 0"/>
            <geometry>
                <mesh filename="package://alpha_lite_model_meshes/meshes/pdr_v2/r_shoulder_l3_link_collision_hull.stl"/>
            </geometry>
            <material name="r_shoulder_l3_link_material">
                <color rgba="0.5 0.5 0.5 1.0"/>
            </material>
        </collision>
        <inertial>
            <origin rpy="0 0 0" xyz="0.103018 9.28819e-06 0.00025801"/>
            <mass value="0.785"/>
            <inertia ixx="0.000287605" ixy="6.41759e-07" ixz="1.44488e-05" iyy="0.00245437" iyz="-1.21859e-07" izz="0.00245075"/>
        </inertial>
    </link>
    <!--=============================== torso_pitch (torso_pitch_link) ===========================-->
    <joint name="torso_pitch" type="revolute">
        <origin rpy="5.54042e-16 -1.11022e-16 3.69779e-32" xyz="0 6.16298e-33 3.08149e-33"/>
        <parent link="torso_link"/>
        <child link="torso_pitch_link"/>
        <axis xyz="0 1 0"/>
        <limit effort="315.0" lower="-1.3962634015954636" upper="0.3490658503988659" velocity="4.5"/>
    </joint>
    <link name="torso_pitch_link">
        <visual>
            <origin rpy="0 -0 0" xyz="0 0 0"/>
            <geometry>
                <mesh filename="package://alpha_lite_model_meshes/meshes/pdr_v2/torso_pitch_link_collision_hull.stl"/>
            </geometry>
            <material name="torso_pitch_link_material">
                <color rgba="0.460491 0.460865 0.460314 1.0"/>
            </material>
        </visual>
        <collision>
            <origin rpy="0 -0 0" xyz="0 0 0"/>
            <geometry>
                <mesh filename="package://alpha_lite_model_meshes/meshes/pdr_v2/torso_pitch_link_collision_hull.stl"/>
            </geometry>
            <material name="torso_pitch_link_material">
                <color rgba="0.5 0.5 0.5 1.0"/>
            </material>
        </collision>
        <inertial>
            <origin rpy="0 0 0" xyz="-0.0212713 -3.56064e-05 -2.11131e-09"/>
            <mass value="0.531683"/>
            <inertia ixx="0.000444896" ixy="3.91335e-07" ixz="-4.01825e-11" iyy="0.000211048" iyz="3.99699e-14" izz="0.000611842"/>
        </inertial>
    </link>
    <!--=============================== torso_roll (torso_roll_link) ===========================-->
    <joint name="torso_roll" type="revolute">
        <origin rpy="-1.20333e-16 1.66533e-16 1.50213e-16" xyz="9.24446e-33 -5.21155e-34 5.77779e-34"/>
        <parent link="torso_pitch_link"/>
        <child link="torso_roll_link"/>
        <axis xyz="1 0 0"/>
        <limit effort="414.0" lower="-0.2617993877991494" upper="0.2617993877991494" velocity="4.5"/>
    </joint>
    <link name="torso_roll_link">
        <visual>
            <origin rpy="0 -0 0" xyz="0 0 0"/>
            <geometry>
                <mesh filename="package://alpha_lite_model_meshes/meshes/pdr_v2/torso_roll_link_collision_hull.stl"/>
            </geometry>
            <material name="torso_roll_link_material">
                <color rgba="0.411194 0.411194 0.411194 1.0"/>
            </material>
        </visual>
        <collision>
            <origin rpy="0 -0 0" xyz="0 0 0"/>
            <geometry>
                <mesh filename="package://alpha_lite_model_meshes/meshes/pdr_v2/torso_roll_link_collision_hull.stl"/>
            </geometry>
            <material name="torso_roll_link_material">
                <color rgba="0.5 0.5 0.5 1.0"/>
            </material>
        </collision>
        <inertial>
            <origin rpy="0 0 0" xyz="-0.0362789 -2.86102e-07 -0.0242095"/>
            <mass value="0.557362"/>
            <inertia ixx="0.0010449" ixy="5.03241e-07" ixz="3.20775e-05" iyy="0.000510316" iyz="1.20721e-05" izz="0.00139982"/>
        </inertial>
    </link>
    <!--=============================== torso_l1_fix (torso_l1_fix_link) ===========================-->
    <joint name="torso_l1_fix" type="fixed">
        <origin rpy="-3.14159 -6.02387e-16 -1.5708" xyz="-0.0525 0.07 -1.38602e-16"/>
        <parent link="torso_roll_link"/>
        <child link="torso_l1_fix_link"/>
    </joint>
    <link name="torso_l1_fix_link">
        <inertial>
            <origin rpy="0 0 0" xyz="0 0 0"/>
            <mass value="0.0001"/>
            <inertia ixx="9.9999999999999995e-07" ixy="0" ixz="0" iyy="9.9999999999999995e-07" iyz="0" izz="9.9999999999999995e-07"/>
        </inertial>
    </link>
    <!--=============================== torso_l2_fix (torso_l2_fix_link) ===========================-->
    <joint name="torso_l2_fix" type="fixed">
        <origin rpy="-3.14159 -9.35454e-16 -1.5708" xyz="-0.0525 -0.07 5.89272e-20"/>
        <parent link="torso_roll_link"/>
        <child link="torso_l2_fix_link"/>
    </joint>
    <link name="torso_l2_fix_link">
        <inertial>
            <origin rpy="0 0 0" xyz="0 0 0"/>
            <mass value="0.0001"/>
            <inertia ixx="9.9999999999999995e-07" ixy="0" ixz="0" iyy="9.9999999999999995e-07" iyz="0" izz="9.9999999999999995e-07"/>
        </inertial>
    </link>
    <!--=============================== torso_yaw (torso_yaw_link) ===========================-->
    <joint name="torso_yaw" type="revolute">
        <origin rpy="3.50481e-16 1.00929e-16 3.01929e-31" xyz="-0.03 -4.3892e-33 -0.03125"/>
        <parent link="torso_roll_link"/>
        <child link="torso_yaw_link"/>
        <axis xyz="-1.00929e-16 0 1"/>
        <limit effort="120.0" lower="-0.8726646259971648" upper="0.8726646259971648" velocity="8.5"/>
    </joint>
    <link name="torso_yaw_link">
        <visual>
            <origin rpy="0 -0 0" xyz="0 0 0"/>
            <geometry>
                <mesh filename="package://alpha_lite_model_meshes/meshes/pdr_v2/torso_yaw_link_collision_hull.stl"/>
            </geometry>
            <material name="torso_yaw_link_material">
                <color rgba="0.587238 0.594423 0.598495 1.0"/>
            </material>
        </visual>
        <collision>
            <origin rpy="0 -0 0" xyz="0 0 0"/>
            <geometry>
                <mesh filename="package://alpha_lite_model_meshes/meshes/pdr_v2/torso_yaw_link_collision_hull.stl"/>
            </geometry>
            <material name="torso_yaw_link_material">
                <color rgba="0.5 0.5 0.5 1.0"/>
            </material>
        </collision>
        <inertial>
            <origin rpy="0 0 0" xyz="-0.0477475 -9.36584e-05 -0.0741693"/>
            <mass value="6.17863"/>
            <inertia ixx="0.0410404" ixy="-7.20916e-05" ixz="-0.00326502" iyy="0.0217714" iyz="2.87827e-05" izz="0.0420175"/>
        </inertial>
    </link>
    <!--=============================== l_hip_ie (l_hip_ie_link) ===========================-->
    <joint name="l_hip_ie" type="revolute">
        <origin rpy="0.261799 -0.523599 9.29e-16" xyz="-0.02 0.11 -0.16875"/>
        <parent link="torso_yaw_link"/>
        <child link="l_hip_ie_link"/>
        <axis xyz="-1.22465e-16 0 1"/>
        <limit effort="120.0" lower="-0.6108652381980153" upper="1.1344640137963142" velocity="8.5"/>
    </joint>
    <link name="l_hip_ie_link">
        <visual>
            <origin rpy="0 -0 0" xyz="0 0 0"/>
            <geometry>
                <mesh filename="package://alpha_lite_model_meshes/meshes/pdr_v2/l_hip_ie_link_collision_hull.stl"/>
            </geometry>
            <material name="l_hip_ie_link_material">
                <color rgba="0.409974 0.409974 0.409974 1.0"/>
            </material>
        </visual>
        <collision>
            <origin rpy="0 -0 0" xyz="0 0 0"/>
            <geometry>
                <mesh filename="package://alpha_lite_model_meshes/meshes/pdr_v2/l_hip_ie_link_collision_hull.stl"/>
            </geometry>
            <material name="l_hip_ie_link_material">
                <color rgba="0.5 0.5 0.5 1.0"/>
            </material>
        </collision>
        <inertial>
            <origin rpy="0 0 0" xyz="-0.0327034 -6.50886e-05 0.0245921"/>
            <mass value="1.12184"/>
            <inertia ixx="0.00209342" ixy="9.07225e-05" ixz="-0.000832127" iyy="0.00279257" iyz="-1.8397e-05" izz="0.00252095"/>
        </inertial>
    </link>
    <!--=============================== l_hip_l2i_roll (l_hip_l2i_roll_link) ===========================-->
    <joint name="l_hip_l2i_roll" type="fixed">
        <origin rpy="-0.17905 -0.101371 -2.06728e-15" xyz="-0.0450057 -0.065 -0.00793572"/>
        <parent link="l_hip_ie_link"/>
        <child link="l_hip_l2i_roll_link"/>
    </joint>
    <link name="l_hip_l2i_roll_link">
        <inertial>
            <origin rpy="0 0 0" xyz="0 0 0"/>
            <mass value="0.0001"/>
            <inertia ixx="9.9999999999999995e-07" ixy="0" ixz="0" iyy="9.9999999999999995e-07" iyz="0" izz="9.9999999999999995e-07"/>
        </inertial>
    </link>
    <!--=============================== l_hip_l2i_pitch (l_hip_l2i_pitch_link) ===========================-->
    <joint name="l_hip_l2i_pitch" type="fixed">
        <origin rpy="3.14159 0.858084 3.14159" xyz="-2.22045e-16 6.93889e-18 -1.11022e-16"/>
        <parent link="l_hip_l2i_roll_link"/>
        <child link="l_hip_l2i_pitch_link"/>
    </joint>
    <link name="l_hip_l2i_pitch_link">
        <visual>
            <origin rpy="0 -0 0" xyz="0 0 0"/>
            <geometry>
                <mesh filename="package://alpha_lite_model_meshes/meshes/pdr_v2/l_hip_l2i_pitch_link_collision_hull.stl"/>
            </geometry>
            <material name="l_hip_l2i_pitch_link_material">
                <color rgba="0.647059 0.647059 0.647059 1.0"/>
            </material>
        </visual>
        <collision>
            <origin rpy="0 -0 0" xyz="0 0 0"/>
            <geometry>
                <mesh filename="package://alpha_lite_model_meshes/meshes/pdr_v2/l_hip_l2i_pitch_link_collision_hull.stl"/>
            </geometry>
            <material name="l_hip_l2i_pitch_link_material">
                <color rgba="0.5 0.5 0.5 1.0"/>
            </material>
        </collision>
        <inertial>
            <origin rpy="0 0 0" xyz="0.153146 6.36171e-06 0.000176718"/>
            <mass value="1.34968"/>
            <inertia ixx="0.000543096" ixy="8.77055e-07" ixz="2.02473e-05" iyy="0.0060456" iyz="-1.44202e-07" izz="0.00604093"/>
        </inertial>
    </link>
    <!--=============================== l_hip_l2 (l_hip_l2_link) ===========================-->
    <joint name="l_hip_l2" type="fixed">
        <origin rpy="3.14159 -2.82928e-16 9.08281e-16" xyz="0.33 6.93889e-18 1.38778e-17"/>
        <parent link="l_hip_l2i_pitch_link"/>
        <child link="l_hip_l2_link"/>
    </joint>
    <link name="l_hip_l2_link">
        <visual>
            <origin rpy="0 -0 0" xyz="0 0 0"/>
            <geometry>
                <mesh filename="package://alpha_lite_model_meshes/meshes/pdr_v2/l_hip_l2_link_collision_hull.stl"/>
            </geometry>
            <material name="l_hip_l2_link_material">
                <color rgba="0.647059 0.647059 0.647059 1.0"/>
            </material>
        </visual>
        <collision>
            <origin rpy="0 -0 0" xyz="0 0 0"/>
            <geometry>
                <mesh filename="package://alpha_lite_model_meshes/meshes/pdr_v2/l_hip_l2_link_collision_hull.stl"/>
            </geometry>
            <material name="l_hip_l2_link_material">
                <color rgba="0.5 0.5 0.5 1.0"/>
            </material>
        </collision>
        <inertial>
            <origin rpy="0 0 0" xyz="-0.0690753 -1.81678e-06 -2.77244e-11"/>
            <mass value="0.136"/>
            <inertia ixx="4.19507e-06" ixy="-1.3868e-08" ixz="-1.75041e-13" iyy="0.000181669" iyz="1.45095e-12" izz="0.000181484"/>
        </inertial>
    </link>
    <!--=============================== l_hip_l2o_roll (l_hip_l2o_roll_link) ===========================-->
    <joint name="l_hip_l2o_roll" type="fixed">
        <origin rpy="0.464236 1.5708 0" xyz="0 -1.38778e-17 -6.93889e-18"/>
        <parent link="l_hip_l2_link"/>
        <child link="l_hip_l2o_roll_link"/>
    </joint>
    <link name="l_hip_l2o_roll_link">
        <inertial>
            <origin rpy="0 0 0" xyz="0 0 0"/>
            <mass value="0.0001"/>
            <inertia ixx="9.9999999999999995e-07" ixy="0" ixz="0" iyy="9.9999999999999995e-07" iyz="0" izz="9.9999999999999995e-07"/>
        </inertial>
    </link>
    <!--=============================== l_hip_l1i_roll (l_hip_l1i_roll_link) ===========================-->
    <joint name="l_hip_l1i_roll" type="fixed">
        <origin rpy="2.75501 -0.101371 -2.08173e-15" xyz="-0.0450057 0.065 -0.00793572"/>
        <parent link="l_hip_ie_link"/>
        <child link="l_hip_l1i_roll_link"/>
    </joint>
    <link name="l_hip_l1i_roll_link">
        <inertial>
            <origin rpy="0 0 0" xyz="0 0 0"/>
            <mass value="0.0001"/>
            <inertia ixx="9.9999999999999995e-07" ixy="0" ixz="0" iyy="9.9999999999999995e-07" iyz="0" izz="9.9999999999999995e-07"/>
        </inertial>
    </link>
    <!--=============================== l_hip_l1i_pitch (l_hip_l1i_pitch_link) ===========================-->
    <joint name="l_hip_l1i_pitch" type="fixed">
        <origin rpy="3.14159 -0.918452 -3.14159" xyz="-5.55112e-17 2.77556e-17 1.38778e-17"/>
        <parent link="l_hip_l1i_roll_link"/>
        <child link="l_hip_l1i_pitch_link"/>
    </joint>
    <link name="l_hip_l1i_pitch_link">
        <visual>
            <origin rpy="0 -0 0" xyz="0 0 0"/>
            <geometry>
                <mesh filename="package://alpha_lite_model_meshes/meshes/pdr_v2/l_hip_l1i_pitch_link_collision_hull.stl"/>
            </geometry>
            <material name="l_hip_l1i_pitch_link_material">
                <color rgba="0.647059 0.647059 0.647059 1.0"/>
            </material>
        </visual>
        <collision>
            <origin rpy="0 -0 0" xyz="0 0 0"/>
            <geometry>
                <mesh filename="package://alpha_lite_model_meshes/meshes/pdr_v2/l_hip_l1i_pitch_link_collision_hull.stl"/>
            </geometry>
            <material name="l_hip_l1i_pitch_link_material">
                <color rgba="0.5 0.5 0.5 1.0"/>
            </material>
        </collision>
        <inertial>
            <origin rpy="0 0 0" xyz="0.153146 6.36171e-06 0.000176718"/>
            <mass value="1.34968"/>
            <inertia ixx="0.000543096" ixy="8.77055e-07" ixz="2.02473e-05" iyy="0.0060456" iyz="-1.44202e-07" izz="0.00604093"/>
        </inertial>
    </link>
    <!--=============================== l_hip_l1 (l_hip_l1_link) ===========================-->
    <joint name="l_hip_l1" type="fixed">
        <origin rpy="-3.10729e-15 1.69519e-17 -1.96327e-17" xyz="0.33 -5.55112e-17 0"/>
        <parent link="l_hip_l1i_pitch_link"/>
        <child link="l_hip_l1_link"/>
    </joint>
    <link name="l_hip_l1_link">
        <visual>
            <origin rpy="0 -0 0" xyz="0 0 0"/>
            <geometry>
                <mesh filename="package://alpha_lite_model_meshes/meshes/pdr_v2/l_hip_l1_link_collision_hull.stl"/>
            </geometry>
            <material name="l_hip_l1_link_material">
                <color rgba="0.647059 0.647059 0.647059 1.0"/>
            </material>
        </visual>
        <collision>
            <origin rpy="0 -0 0" xyz="0 0 0"/>
            <geometry>
                <mesh filename="package://alpha_lite_model_meshes/meshes/pdr_v2/l_hip_l1_link_collision_hull.stl"/>
            </geometry>
            <material name="l_hip_l1_link_material">
                <color rgba="0.5 0.5 0.5 1.0"/>
            </material>
        </collision>
        <inertial>
            <origin rpy="0 0 0" xyz="-0.0690753 -1.81678e-06 -2.77244e-11"/>
            <mass value="0.136"/>
            <inertia ixx="4.19507e-06" ixy="-1.3868e-08" ixz="-1.75041e-13" iyy="0.000181669" iyz="1.45095e-12" izz="0.000181484"/>
        </inertial>
    </link>
    <!--=============================== l_hip_l1o_roll (l_hip_l1o_roll_link) ===========================-->
    <joint name="l_hip_l1o_roll" type="fixed">
        <origin rpy="-3.04975 -1.5708 0" xyz="-2.22045e-16 -2.77556e-17 -1.38778e-17"/>
        <parent link="l_hip_l1_link"/>
        <child link="l_hip_l1o_roll_link"/>
    </joint>
    <link name="l_hip_l1o_roll_link">
        <inertial>
            <origin rpy="0 0 0" xyz="0 0 0"/>
            <mass value="0.0001"/>
            <inertia ixx="9.9999999999999995e-07" ixy="0" ixz="0" iyy="9.9999999999999995e-07" iyz="0" izz="9.9999999999999995e-07"/>
        </inertial>
    </link>
    <!--=============================== l_hip_aa (l_hip_aa_link) ===========================-->
    <joint name="l_hip_aa" type="revolute">
        <origin rpy="-3.70144e-16 9.08449e-16 -1.48445e-15" xyz="-1.94289e-16 -4.16334e-17 0"/>
        <parent link="l_hip_ie_link"/>
        <child link="l_hip_aa_link"/>
        <axis xyz="1 0 0"/>
        <limit effort="494.0" lower="-0.3490658503988659" upper="0.8726646259971648" velocity="7.8"/>
    </joint>
    <link name="l_hip_aa_link">
        <visual>
            <origin rpy="0 -0 0" xyz="0 0 0"/>
            <geometry>
                <mesh filename="package://alpha_lite_model_meshes/meshes/pdr_v2/l_hip_aa_link_collision_hull.stl"/>
            </geometry>
            <material name="l_hip_aa_link_material">
                <color rgba="0.520793 0.521404 0.520977 1.0"/>
            </material>
        </visual>
        <collision>
            <origin rpy="0 -0 0" xyz="0 0 0"/>
            <geometry>
                <mesh filename="package://alpha_lite_model_meshes/meshes/pdr_v2/l_hip_aa_link_collision_hull.stl"/>
            </geometry>
            <material name="l_hip_aa_link_material">
                <color rgba="0.5 0.5 0.5 1.0"/>
            </material>
        </collision>
        <inertial>
            <origin rpy="0 0 0" xyz="0.00023159 0.00118232 0.00424759"/>
            <mass value="0.412623"/>
            <inertia ixx="0.000304177" ixy="1.12987e-07" ixz="-2.08801e-06" iyy="0.000129814" iyz="3.30373e-05" izz="0.000335799"/>
        </inertial>
    </link>
    <!--=============================== l_hip_fe (l_hip_fe_link) ===========================-->
    <joint name="l_hip_fe" type="revolute">
        <origin rpy="-0.300059 0.504035 -0.148332" xyz="2.77556e-17 1.38778e-17 5.55112e-17"/>
        <parent link="l_hip_aa_link"/>
        <child link="l_hip_fe_link"/>
        <axis xyz="0 1 0"/>
        <limit effort="342.0" lower="-1.9198621771937625" upper="0.6108652381980153" velocity="11.3"/>
    </joint>
    <link name="l_hip_fe_link">
        <visual>
            <origin rpy="0 -0 0" xyz="0 0 0"/>
            <geometry>
                <mesh filename="package://alpha_lite_model_meshes/meshes/pdr_v2/l_hip_fe_link_collision_hull.stl"/>
            </geometry>
            <material name="l_hip_fe_link_material">
                <color rgba="0.40683 0.406843 0.406896 1.0"/>
            </material>
        </visual>
        <collision>
            <origin rpy="0 -0 0" xyz="0 0 0"/>
            <geometry>
                <mesh filename="package://alpha_lite_model_meshes/meshes/pdr_v2/l_hip_fe_link_collision_hull.stl"/>
            </geometry>
            <material name="l_hip_fe_link_material">
                <color rgba="0.5 0.5 0.5 1.0"/>
            </material>
        </collision>
        <inertial>
            <origin rpy="0 0 0" xyz="0.0177667 0.00513066 -0.240432"/>
            <mass value="4.32108"/>
            <inertia ixx="0.0694424" ixy="-0.000336023" ixz="-0.00676651" iyy="0.0679844" iyz="-0.00115716" izz="0.0221405"/>
        </inertial>
    </link>
    <!--=============================== l_hip_l2_fix (l_hip_l2_fix_link) ===========================-->
    <joint name="l_hip_l2_fix" type="fixed">
        <origin rpy="2.47025e-15 8.32667e-16 3.14159" xyz="-0.0565 -0.035 -0.3684"/>
        <parent link="l_hip_fe_link"/>
        <child link="l_hip_l2_fix_link"/>
    </joint>
    <link name="l_hip_l2_fix_link">
        <inertial>
            <origin rpy="0 0 0" xyz="0 0 0"/>
            <mass value="0.0001"/>
            <inertia ixx="9.9999999999999995e-07" ixy="0" ixz="0" iyy="9.9999999999999995e-07" iyz="0" izz="9.9999999999999995e-07"/>
        </inertial>
    </link>
    <!--=============================== l_hip_l1_fix (l_hip_l1_fix_link) ===========================-->
    <joint name="l_hip_l1_fix" type="fixed">
        <origin rpy="2.86923e-15 4.71845e-15 -3.14159" xyz="-0.0565 0.035 -0.3684"/>
        <parent link="l_hip_fe_link"/>
        <child link="l_hip_l1_fix_link"/>
    </joint>
    <link name="l_hip_l1_fix_link">
        <inertial>
            <origin rpy="0 0 0" xyz="0 0 0"/>
            <mass value="0.0001"/>
            <inertia ixx="9.9999999999999995e-07" ixy="0" ixz="0" iyy="9.9999999999999995e-07" iyz="0" izz="9.9999999999999995e-07"/>
        </inertial>
    </link>
    <!--=============================== l_knee_fe (l_knee_fe_link) ===========================-->
    <joint name="l_knee_fe" type="revolute">
        <origin rpy="-5.14936e-31 -1.88773e-29 2.76168e-15" xyz="-0.05 0 -0.425"/>
        <parent link="l_hip_fe_link"/>
        <child link="l_knee_fe_link"/>
        <axis xyz="0 1 0"/>
        <limit effort="336.0" lower="0.0" upper="2.6179938779914944" velocity="9.7"/>
    </joint>
    <link name="l_knee_fe_link">
        <visual>
            <origin rpy="0 -0 0" xyz="0 0 0"/>
            <geometry>
                <mesh filename="package://alpha_lite_model_meshes/meshes/pdr_v2/l_knee_fe_link_collision_hull.stl"/>
            </geometry>
            <material name="l_knee_fe_link_material">
                <color rgba="0.408495 0.407441 0.405951 1.0"/>
            </material>
        </visual>
        <collision>
            <origin rpy="0 -0 0" xyz="0 0 0"/>
            <geometry>
                <mesh filename="package://alpha_lite_model_meshes/meshes/pdr_v2/l_knee_fe_link_collision_hull.stl"/>
            </geometry>
            <material name="l_knee_fe_link_material">
                <color rgba="0.5 0.5 0.5 1.0"/>
            </material>
        </collision>
        <inertial>
            <origin rpy="0 0 0" xyz="0.061533 0.000533576 -0.131616"/>
            <mass value="1.98038"/>
            <inertia ixx="0.0343384" ixy="4.99919e-05" ixz="-0.000388005" iyy="0.0354259" iyz="6.619e-05" izz="0.00347855"/>
        </inertial>
    </link>
    <!--=============================== l_knee_l1_fix (l_knee_l1_fix_link) ===========================-->
    <joint name="l_knee_l1_fix" type="fixed">
        <origin rpy="4.44089e-16 -2.98372e-16 1.5708" xyz="0.0221875 1.38778e-15 0.0475812"/>
        <parent link="l_knee_fe_link"/>
        <child link="l_knee_l1_fix_link"/>
    </joint>
    <link name="l_knee_l1_fix_link">
        <inertial>
            <origin rpy="0 0 0" xyz="0 0 0"/>
            <mass value="0.0001"/>
            <inertia ixx="9.9999999999999995e-07" ixy="0" ixz="0" iyy="9.9999999999999995e-07" iyz="0" izz="9.9999999999999995e-07"/>
        </inertial>
    </link>
    <!--=============================== l_ankle_l2i_roll (l_ankle_l2i_roll_link) ===========================-->
    <joint name="l_ankle_l2i_roll" type="fixed">
        <origin rpy="-3.12447 -0.0062405 6.12335e-17" xyz="0.025 -0.03 -0.0391"/>
        <parent link="l_knee_fe_link"/>
        <child link="l_ankle_l2i_roll_link"/>
    </joint>
    <link name="l_ankle_l2i_roll_link">
        <inertial>
            <origin rpy="0 0 0" xyz="0 0 0"/>
            <mass value="0.0001"/>
            <inertia ixx="9.9999999999999995e-07" ixy="0" ixz="0" iyy="9.9999999999999995e-07" iyz="0" izz="9.9999999999999995e-07"/>
        </inertial>
    </link>
    <!--=============================== l_ankle_l2i_pitch (l_ankle_l2i_pitch_link) ===========================-->
    <joint name="l_ankle_l2i_pitch" type="fixed">
        <origin rpy="2.49217e-13 -1.567 8.23168e-14" xyz="-1.38778e-17 0 -1.11022e-16"/>
        <parent link="l_ankle_l2i_roll_link"/>
        <child link="l_ankle_l2i_pitch_link"/>
    </joint>
    <link name="l_ankle_l2i_pitch_link">
        <visual>
            <origin rpy="0 -0 0" xyz="0 0 0"/>
            <geometry>
                <mesh filename="package://alpha_lite_model_meshes/meshes/pdr_v2/l_ankle_l2i_pitch_link_collision_hull.stl"/>
            </geometry>
            <material name="l_ankle_l2i_pitch_link_material">
                <color rgba="0.647059 0.647059 0.647059 1.0"/>
            </material>
        </visual>
        <collision>
            <origin rpy="0 -0 0" xyz="0 0 0"/>
            <geometry>
                <mesh filename="package://alpha_lite_model_meshes/meshes/pdr_v2/l_ankle_l2i_pitch_link_collision_hull.stl"/>
            </geometry>
            <material name="l_ankle_l2i_pitch_link_material">
                <color rgba="0.5 0.5 0.5 1.0"/>
            </material>
        </collision>
        <inertial>
            <origin rpy="0 0 0" xyz="0.103018 9.28819e-06 0.00025801"/>
            <mass value="0.785"/>
            <inertia ixx="0.000287605" ixy="6.41759e-07" ixz="1.44488e-05" iyy="0.00245437" iyz="-1.21859e-07" izz="0.00245075"/>
        </inertial>
    </link>
    <!--=============================== l_ankle_l2 (l_ankle_l2_link) ===========================-->
    <joint name="l_ankle_l2" type="fixed">
        <origin rpy="1.63254e-15 7.37514e-16 1.11956e-18" xyz="0.3612 6.93889e-17 0"/>
        <parent link="l_ankle_l2i_pitch_link"/>
        <child link="l_ankle_l2_link"/>
    </joint>
    <link name="l_ankle_l2_link">
        <visual>
            <origin rpy="0 -0 0" xyz="0 0 0"/>
            <geometry>
                <mesh filename="package://alpha_lite_model_meshes/meshes/pdr_v2/l_ankle_l2_link_collision_hull.stl"/>
            </geometry>
            <material name="l_ankle_l2_link_material">
                <color rgba="0.647059 0.647059 0.647059 1.0"/>
            </material>
        </visual>
        <collision>
            <origin rpy="0 -0 0" xyz="0 0 0"/>
            <geometry>
                <mesh filename="package://alpha_lite_model_meshes/meshes/pdr_v2/l_ankle_l2_link_collision_hull.stl"/>
            </geometry>
            <material name="l_ankle_l2_link_material">
                <color rgba="0.5 0.5 0.5 1.0"/>
            </material>
        </collision>
        <inertial>
            <origin rpy="0 0 0" xyz="-0.123353 1.34347e-17 3.86796e-17"/>
            <mass value="0.248858"/>
            <inertia ixx="7.81352e-06" ixy="1.21217e-21" ixz="-2.36231e-21" iyy="0.00111084" iyz="2.46967e-12" izz="0.00111067"/>
        </inertial>
    </link>
    <!--=============================== l_ankle_l2o_roll (l_ankle_l2o_roll_link) ===========================-->
    <joint name="l_ankle_l2o_roll" type="fixed">
        <origin rpy="-0.153875 -1.5708 0" xyz="2.22045e-16 0 0"/>
        <parent link="l_ankle_l2_link"/>
        <child link="l_ankle_l2o_roll_link"/>
    </joint>
    <link name="l_ankle_l2o_roll_link">
        <inertial>
            <origin rpy="0 0 0" xyz="0 0 0"/>
            <mass value="0.0001"/>
            <inertia ixx="9.9999999999999995e-07" ixy="0" ixz="0" iyy="9.9999999999999995e-07" iyz="0" izz="9.9999999999999995e-07"/>
        </inertial>
    </link>
    <!--=============================== l_ankle_l1i_roll (l_ankle_l1i_roll_link) ===========================-->
    <joint name="l_ankle_l1i_roll" type="fixed">
        <origin rpy="-0.0936697 -0.0062405 6.12335e-17" xyz="0.025 0.05 -0.0391"/>
        <parent link="l_knee_fe_link"/>
        <child link="l_ankle_l1i_roll_link"/>
    </joint>
    <link name="l_ankle_l1i_roll_link">
        <inertial>
            <origin rpy="0 0 0" xyz="0 0 0"/>
            <mass value="0.0001"/>
            <inertia ixx="9.9999999999999995e-07" ixy="0" ixz="0" iyy="9.9999999999999995e-07" iyz="0" izz="9.9999999999999995e-07"/>
        </inertial>
    </link>
    <!--=============================== l_ankle_l1i_pitch (l_ankle_l1i_pitch_link) ===========================-->
    <joint name="l_ankle_l1i_pitch" type="fixed">
        <origin rpy="-3.14159 1.56766 -3.14159" xyz="-4.16334e-17 -2.77556e-17 1.11022e-16"/>
        <parent link="l_ankle_l1i_roll_link"/>
        <child link="l_ankle_l1i_pitch_link"/>
    </joint>
    <link name="l_ankle_l1i_pitch_link">
        <visual>
            <origin rpy="0 -0 0" xyz="0 0 0"/>
            <geometry>
                <mesh filename="package://alpha_lite_model_meshes/meshes/pdr_v2/l_ankle_l1i_pitch_link_collision_hull.stl"/>
            </geometry>
            <material name="l_ankle_l1i_pitch_link_material">
                <color rgba="0.647059 0.647059 0.647059 1.0"/>
            </material>
        </visual>
        <collision>
            <origin rpy="0 -0 0" xyz="0 0 0"/>
            <geometry>
                <mesh filename="package://alpha_lite_model_meshes/meshes/pdr_v2/l_ankle_l1i_pitch_link_collision_hull.stl"/>
            </geometry>
            <material name="l_ankle_l1i_pitch_link_material">
                <color rgba="0.5 0.5 0.5 1.0"/>
            </material>
        </collision>
        <inertial>
            <origin rpy="0 0 0" xyz="0.103018 9.28819e-06 0.00025801"/>
            <mass value="0.785"/>
            <inertia ixx="0.000287605" ixy="6.41759e-07" ixz="1.44488e-05" iyy="0.00245437" iyz="-1.21859e-07" izz="0.00245075"/>
        </inertial>
    </link>
    <!--=============================== l_ankle_l1 (l_ankle_l1_link) ===========================-->
    <joint name="l_ankle_l1" type="fixed">
        <origin rpy="-1.22006e-15 8.95479e-19 5.98889e-18" xyz="0.3612 8.32667e-17 0"/>
        <parent link="l_ankle_l1i_pitch_link"/>
        <child link="l_ankle_l1_link"/>
    </joint>
    <link name="l_ankle_l1_link">
        <visual>
            <origin rpy="0 -0 0" xyz="0 0 0"/>
            <geometry>
                <mesh filename="package://alpha_lite_model_meshes/meshes/pdr_v2/l_ankle_l1_link_collision_hull.stl"/>
            </geometry>
            <material name="l_ankle_l1_link_material">
                <color rgba="0.647059 0.647059 0.647059 1.0"/>
            </material>
        </visual>
        <collision>
            <origin rpy="0 -0 0" xyz="0 0 0"/>
            <geometry>
                <mesh filename="package://alpha_lite_model_meshes/meshes/pdr_v2/l_ankle_l1_link_collision_hull.stl"/>
            </geometry>
            <material name="l_ankle_l1_link_material">
                <color rgba="0.5 0.5 0.5 1.0"/>
            </material>
        </collision>
        <inertial>
            <origin rpy="0 0 0" xyz="-0.123353 -2.799e-17 3.90854e-17"/>
            <mass value="0.248858"/>
            <inertia ixx="7.81352e-06" ixy="2.52648e-21" ixz="1.62692e-25" iyy="0.00111084" iyz="2.46967e-12" izz="0.00111067"/>
        </inertial>
    </link>
    <!--=============================== l_ankle_l1o_roll (l_ankle_l1o_roll_link) ===========================-->
    <joint name="l_ankle_l1o_roll" type="fixed">
        <origin rpy="-0.597913 -1.5708 0" xyz="0 -5.55112e-17 1.38778e-17"/>
        <parent link="l_ankle_l1_link"/>
        <child link="l_ankle_l1o_roll_link"/>
    </joint>
    <link name="l_ankle_l1o_roll_link">
        <inertial>
            <origin rpy="0 0 0" xyz="0 0 0"/>
            <mass value="0.0001"/>
            <inertia ixx="9.9999999999999995e-07" ixy="0" ixz="0" iyy="9.9999999999999995e-07" iyz="0" izz="9.9999999999999995e-07"/>
        </inertial>
    </link>
    <!--=============================== l_ankle_ie (l_ankle_ie_link) ===========================-->
    <joint name="l_ankle_ie" type="revolute">
        <origin rpy="0.261799 -0.261799 4.1231e-15" xyz="0.05 -1.38778e-17 -0.425"/>
        <parent link="l_knee_fe_link"/>
        <child link="l_ankle_ie_link"/>
        <axis xyz="1 0 0"/>
        <limit effort="120.0" lower="-0.8726646259971648" upper="0.3490658503988659" velocity="8.5"/>
    </joint>
    <link name="l_ankle_ie_link">
        <visual>
            <origin rpy="0 -0 0" xyz="0 0 0"/>
            <geometry>
                <mesh filename="package://alpha_lite_model_meshes/meshes/pdr_v2/l_ankle_ie_link_collision_hull.stl"/>
            </geometry>
            <material name="l_ankle_ie_link_material">
                <color rgba="0.762236 0.856794 0.708978 1.0"/>
            </material>
        </visual>
        <collision>
            <origin rpy="0 -0 0" xyz="0 0 0"/>
            <geometry>
                <mesh filename="package://alpha_lite_model_meshes/meshes/pdr_v2/l_ankle_ie_link_collision_hull.stl"/>
            </geometry>
            <material name="l_ankle_ie_link_material">
                <color rgba="0.5 0.5 0.5 1.0"/>
            </material>
        </collision>
        <inertial>
            <origin rpy="0 0 0" xyz="0.00829519 0.000111769 0.000562784"/>
            <mass value="0.115963"/>
            <inertia ixx="4.58056e-05" ixy="1.07522e-07" ixz="-3.42697e-06" iyy="1.65718e-05" iyz="7.3104e-09" izz="4.14371e-05"/>
        </inertial>
    </link>
    <!--=============================== l_ankle_pd (l_ankle_pd_link) ===========================-->
    <joint name="l_ankle_pd" type="revolute">
        <origin rpy="-7.93098e-16 0.523599 -2.76764e-17" xyz="0 -2.77556e-17 -1.11022e-16"/>
        <parent link="l_ankle_ie_link"/>
        <child link="l_ankle_pd_link"/>
        <axis xyz="0 1 0"/>
        <limit effort="150.0" lower="-1.5707963267948966" upper="0.7853981633974483" velocity="9.5"/>
    </joint>
    <link name="l_ankle_pd_link">
        <visual>
            <origin rpy="0 -0 0" xyz="0 0 0"/>
            <geometry>
                <mesh filename="package://alpha_lite_model_meshes/meshes/pdr_v2/l_ankle_pd_link_collision_hull.stl"/>
            </geometry>
            <material name="l_ankle_pd_link_material">
                <color rgba="0.736632 0.721794 0.682563 1.0"/>
            </material>
        </visual>
        <collision>
            <origin rpy="0 0 0" xyz="0 0 0"/>
            <geometry>
                <mesh filename="package://alpha_lite_model_meshes/meshes/pdr_v2/l_ankle_pd_link_collision_hull.stl"/>
            </geometry>
            <material name="l_ankle_pd_link_material">
                <color rgba="0.5 0.5 0.5 1.0"/>
            </material>
        </collision>
        <inertial>
            <origin rpy="0 0 0" xyz="0.0308482 -0.00841239 -0.0292348"/>
            <mass value="0.65952"/>
            <inertia ixx="0.000774031" ixy="4.37872e-05" ixz="-0.000198678" iyy="0.00197829" iyz="6.0516e-05" izz="0.00227913"/>
        </inertial>
    </link>
    <!--=============================== l_ankle_l2_fix (l_ankle_l2_fix_link) ===========================-->
    <joint name="l_ankle_l2_fix" type="fixed">
        <origin rpy="-1.5708 4.34352e-17 -1.09779e-16" xyz="-0.0246202 -0.02 0.0043412"/>
        <parent link="l_ankle_pd_link"/>
        <child link="l_ankle_l2_fix_link"/>
    </joint>
    <link name="l_ankle_l2_fix_link">
        <inertial>
            <origin rpy="0 0 0" xyz="0 0 0"/>
            <mass value="0.00001"/>
            <inertia ixx="0" ixy="0" ixz="0" iyy="0" iyz="0" izz="0"/>
        </inertial>
    </link>
    <!--=============================== l_ankle_l1_fix (l_ankle_l1_fix_link) ===========================-->
    <joint name="l_ankle_l1_fix" type="fixed">
        <origin rpy="1.5708 1.0242e-16 -2.65122e-17" xyz="-0.0246202 0.02 0.0043412"/>
        <parent link="l_ankle_pd_link"/>
        <child link="l_ankle_l1_fix_link"/>
    </joint>
    <link name="l_ankle_l1_fix_link">
        <inertial>
            <origin rpy="0 0 0" xyz="0 0 0"/>
            <mass value="0.00001"/>
            <inertia ixx="0" ixy="0" ixz="0" iyy="0" iyz="0" izz="0"/>
        </inertial>
    </link>
    <!--=============================== l_sole (l_sole_link) ===========================-->
    <joint name="l_sole" type="fixed">
        <origin rpy="-0.277793 -0.234899 0.0662738" xyz="0.0483726 -0.0156082 -0.0473442"/>
        <parent link="l_ankle_pd_link"/>
        <child link="l_sole_link"/>
    </joint>
    <link name="l_sole_link">
        <inertial>
            <origin rpy="0 0 0" xyz="0 0 0"/>
            <mass value="0.00001"/>
            <inertia ixx="0" ixy="0" ixz="0" iyy="0" iyz="0" izz="0"/>
        </inertial>
    </link>
    <!--=============================== l_knee_l1i_pitch (l_knee_l1i_pitch_link) ===========================-->
    <joint name="l_knee_l1i_pitch" type="fixed">
        <origin rpy="-3.14159 1.22834 3.14159" xyz="0.08 0 -0.075"/>
        <parent link="l_hip_fe_link"/>
        <child link="l_knee_l1i_pitch_link"/>
    </joint>
    <link name="l_knee_l1i_pitch_link">
        <visual>
            <origin rpy="0 -0 0" xyz="0 0 0"/>
            <geometry>
                <mesh filename="package://alpha_lite_model_meshes/meshes/pdr_v2/l_knee_l1i_pitch_link_collision_hull.stl"/>
            </geometry>
            <material name="l_knee_l1i_pitch_link_material">
                <color rgba="0.647059 0.647059 0.647059 1.0"/>
            </material>
        </visual>
        <collision>
            <origin rpy="0 -0 0" xyz="0 0 0"/>
            <geometry>
                <mesh filename="package://alpha_lite_model_meshes/meshes/pdr_v2/l_knee_l1i_pitch_link_collision_hull.stl"/>
            </geometry>
            <material name="l_knee_l1i_pitch_link_material">
                <color rgba="0.5 0.5 0.5 1.0"/>
            </material>
        </collision>
        <inertial>
            <origin rpy="0 0 0" xyz="0.113742 -1.79001e-05 0.000101143"/>
            <mass value="3.34415"/>
            <inertia ixx="0.00368832" ixy="-5.55699e-06" ixz="2.97262e-05" iyy="0.0149308" iyz="9.73239e-07" izz="0.0149109"/>
        </inertial>
    </link>
    <!--=============================== l_knee_l1 (l_knee_l1_link) ===========================-->
    <joint name="l_knee_l1" type="fixed">
        <origin rpy="-9.22868e-15 1.10229e-16 7.32696e-30" xyz="0.3147 3.27516e-15 -6.66134e-16"/>
        <parent link="l_knee_l1i_pitch_link"/>
        <child link="l_knee_l1_link"/>
    </joint>
    <link name="l_knee_l1_link">
        <visual>
            <origin rpy="0 -0 0" xyz="0 0 0"/>
            <geometry>
                <mesh filename="package://alpha_lite_model_meshes/meshes/pdr_v2/l_knee_l1_link_collision_hull.stl"/>
            </geometry>
            <material name="l_knee_l1_link_material">
                <color rgba="0.647059 0.647059 0.647059 1.0"/>
            </material>
        </visual>
        <collision>
            <origin rpy="0 -0 0" xyz="0 0 0"/>
            <geometry>
                <mesh filename="package://alpha_lite_model_meshes/meshes/pdr_v2/l_knee_l1_link_collision_hull.stl"/>
            </geometry>
            <material name="l_knee_l1_link_material">
                <color rgba="0.5 0.5 0.5 1.0"/>
            </material>
        </collision>
        <inertial>
            <origin rpy="0 0 0" xyz="-0.0910004 1.33225e-09 5.82722e-10"/>
            <mass value="0.323454"/>
            <inertia ixx="6.93665e-06" ixy="-1.02011e-11" ixz="-5.23564e-12" iyy="0.000289524" iyz="4.20558e-13" izz="0.000289235"/>
        </inertial>
    </link>
    <!--=============================== r_hip_ie (r_hip_ie_link) ===========================-->
    <joint name="r_hip_ie" type="revolute">
        <origin rpy="-0.261799 -0.523599 -3.85288e-16" xyz="-0.02 -0.11 -0.16875"/>
        <parent link="torso_yaw_link"/>
        <child link="r_hip_ie_link"/>
        <axis xyz="-1.22465e-16 0 1"/>
        <limit effort="120.0" lower="-1.1344640137963142" upper="0.6108652381980153" velocity="8.5"/>
    </joint>
    <link name="r_hip_ie_link">
        <visual>
            <origin rpy="0 -0 0" xyz="0 0 0"/>
            <geometry>
                <mesh filename="package://alpha_lite_model_meshes/meshes/pdr_v2/r_hip_ie_link_collision_hull.stl"/>
            </geometry>
            <material name="r_hip_ie_link_material">
                <color rgba="0.409985 0.409985 0.409985 1.0"/>
            </material>
        </visual>
        <collision>
            <origin rpy="0 -0 0" xyz="0 0 0"/>
            <geometry>
                <mesh filename="package://alpha_lite_model_meshes/meshes/pdr_v2/r_hip_ie_link_collision_hull.stl"/>
            </geometry>
            <material name="r_hip_ie_link_material">
                <color rgba="0.5 0.5 0.5 1.0"/>
            </material>
        </collision>
        <inertial>
            <origin rpy="0 0 0" xyz="-0.0325648 0.000118701 0.0245677"/>
            <mass value="1.12062"/>
            <inertia ixx="0.00210649" ixy="-0.000100902" ixz="-0.000837725" iyy="0.00278228" iyz="2.48432e-05" izz="0.00248073"/>
        </inertial>
    </link>
    <!--=============================== r_hip_l2i_roll (r_hip_l2i_roll_link) ===========================-->
    <joint name="r_hip_l2i_roll" type="fixed">
        <origin rpy="0.386363 -0.101371 -8.84851e-16" xyz="-0.0450057 -0.065 -0.00793572"/>
        <parent link="r_hip_ie_link"/>
        <child link="r_hip_l2i_roll_link"/>
    </joint>
    <link name="r_hip_l2i_roll_link">
        <inertial>
            <origin rpy="0 0 0" xyz="0 0 0"/>
            <mass value="0.0001"/>
            <inertia ixx="9.9999999999999995e-07" ixy="0" ixz="0" iyy="9.9999999999999995e-07" iyz="0" izz="9.9999999999999995e-07"/>
        </inertial>
    </link>
    <!--=============================== r_hip_l2i_pitch (r_hip_l2i_pitch_link) ===========================-->
    <joint name="r_hip_l2i_pitch" type="fixed">
        <origin rpy="3.14159 0.918508 3.14159" xyz="0 0 -2.77556e-17"/>
        <parent link="r_hip_l2i_roll_link"/>
        <child link="r_hip_l2i_pitch_link"/>
    </joint>
    <link name="r_hip_l2i_pitch_link">
        <visual>
            <origin rpy="0 -0 0" xyz="0 0 0"/>
            <geometry>
                <mesh filename="package://alpha_lite_model_meshes/meshes/pdr_v2/r_hip_l2i_pitch_link_collision_hull.stl"/>
            </geometry>
            <material name="r_hip_l2i_pitch_link_material">
                <color rgba="0.647059 0.647059 0.647059 1.0"/>
            </material>
        </visual>
        <collision>
            <origin rpy="0 -0 0" xyz="0 0 0"/>
            <geometry>
                <mesh filename="package://alpha_lite_model_meshes/meshes/pdr_v2/r_hip_l2i_pitch_link_collision_hull.stl"/>
            </geometry>
            <material name="r_hip_l2i_pitch_link_material">
                <color rgba="0.5 0.5 0.5 1.0"/>
            </material>
        </collision>
        <inertial>
            <origin rpy="0 0 0" xyz="0.153146 6.36171e-06 0.000176718"/>
            <mass value="1.34968"/>
            <inertia ixx="0.000543096" ixy="8.77055e-07" ixz="2.02473e-05" iyy="0.0060456" iyz="-1.44202e-07" izz="0.00604093"/>
        </inertial>
    </link>
    <!--=============================== r_hip_l2 (r_hip_l2_link) ===========================-->
    <joint name="r_hip_l2" type="fixed">
        <origin rpy="-3.14159 9.09031e-16 1.10615e-15" xyz="0.33 0 2.77556e-17"/>
        <parent link="r_hip_l2i_pitch_link"/>
        <child link="r_hip_l2_link"/>
    </joint>
    <link name="r_hip_l2_link">
        <visual>
            <origin rpy="0 -0 0" xyz="0 0 0"/>
            <geometry>
                <mesh filename="package://alpha_lite_model_meshes/meshes/pdr_v2/r_hip_l2_link_collision_hull.stl"/>
            </geometry>
            <material name="r_hip_l2_link_material">
                <color rgba="0.647059 0.647059 0.647059 1.0"/>
            </material>
        </visual>
        <collision>
            <origin rpy="0 -0 0" xyz="0 0 0"/>
            <geometry>
                <mesh filename="package://alpha_lite_model_meshes/meshes/pdr_v2/r_hip_l2_link_collision_hull.stl"/>
            </geometry>
            <material name="r_hip_l2_link_material">
                <color rgba="0.5 0.5 0.5 1.0"/>
            </material>
        </collision>
        <inertial>
            <origin rpy="0 0 0" xyz="-0.0690753 -1.81678e-06 -2.77244e-11"/>
            <mass value="0.136"/>
            <inertia ixx="4.19507e-06" ixy="-1.3868e-08" ixz="-1.75041e-13" iyy="0.000181669" iyz="1.45095e-12" izz="0.000181484"/>
        </inertial>
    </link>
    <!--=============================== r_hip_l2o_roll (r_hip_l2o_roll_link) ===========================-->
    <joint name="r_hip_l2o_roll" type="fixed">
        <origin rpy="-0.712777 1.5708 0" xyz="-1.11022e-16 0 0"/>
        <parent link="r_hip_l2_link"/>
        <child link="r_hip_l2o_roll_link"/>
    </joint>
    <link name="r_hip_l2o_roll_link">
        <inertial>
            <origin rpy="0 0 0" xyz="0 0 0"/>
            <mass value="0.0001"/>
            <inertia ixx="9.9999999999999995e-07" ixy="0" ixz="0" iyy="9.9999999999999995e-07" iyz="0" izz="9.9999999999999995e-07"/>
        </inertial>
    </link>
    <!--=============================== r_hip_l1i_roll (r_hip_l1i_roll_link) ===========================-->
    <joint name="r_hip_l1i_roll" type="fixed">
        <origin rpy="0.17928 -0.101371 -8.00334e-16" xyz="-0.0450057 0.065 -0.00793572"/>
        <parent link="r_hip_ie_link"/>
        <child link="r_hip_l1i_roll_link"/>
    </joint>
    <link name="r_hip_l1i_roll_link">
        <inertial>
            <origin rpy="0 0 0" xyz="0 0 0"/>
            <mass value="0.0001"/>
            <inertia ixx="9.9999999999999995e-07" ixy="0" ixz="0" iyy="9.9999999999999995e-07" iyz="0" izz="9.9999999999999995e-07"/>
        </inertial>
    </link>
    <!--=============================== r_hip_l1i_pitch (r_hip_l1i_pitch_link) ===========================-->
    <joint name="r_hip_l1i_pitch" type="fixed">
        <origin rpy="3.14159 0.858273 -3.14159" xyz="2.77556e-17 6.93889e-18 0"/>
        <parent link="r_hip_l1i_roll_link"/>
        <child link="r_hip_l1i_pitch_link"/>
    </joint>
    <link name="r_hip_l1i_pitch_link">
        <visual>
            <origin rpy="0 -0 0" xyz="0 0 0"/>
            <geometry>
                <mesh filename="package://alpha_lite_model_meshes/meshes/pdr_v2/r_hip_l1i_pitch_link_collision_hull.stl"/>
            </geometry>
            <material name="r_hip_l1i_pitch_link_material">
                <color rgba="0.647059 0.647059 0.647059 1.0"/>
            </material>
        </visual>
        <collision>
            <origin rpy="0 -0 0" xyz="0 0 0"/>
            <geometry>
                <mesh filename="package://alpha_lite_model_meshes/meshes/pdr_v2/r_hip_l1i_pitch_link_collision_hull.stl"/>
            </geometry>
            <material name="r_hip_l1i_pitch_link_material">
                <color rgba="0.5 0.5 0.5 1.0"/>
            </material>
        </collision>
        <inertial>
            <origin rpy="0 0 0" xyz="0.153146 6.36171e-06 0.000176718"/>
            <mass value="1.34968"/>
            <inertia ixx="0.000543096" ixy="8.77055e-07" ixz="2.02473e-05" iyy="0.0060456" iyz="-1.44202e-07" izz="0.00604093"/>
        </inertial>
    </link>
    <!--=============================== r_hip_l1 (r_hip_l1_link) ===========================-->
    <joint name="r_hip_l1" type="fixed">
        <origin rpy="1.00042e-17 1.56089e-17 -1.33875e-17" xyz="0.33 4.16334e-17 2.08167e-17"/>
        <parent link="r_hip_l1i_pitch_link"/>
        <child link="r_hip_l1_link"/>
    </joint>
    <link name="r_hip_l1_link">
        <visual>
            <origin rpy="0 -0 0" xyz="0 0 0"/>
            <geometry>
                <mesh filename="package://alpha_lite_model_meshes/meshes/pdr_v2/r_hip_l1_link_collision_hull.stl"/>
            </geometry>
            <material name="r_hip_l1_link_material">
                <color rgba="0.647059 0.647059 0.647059 1.0"/>
            </material>
        </visual>
        <collision>
            <origin rpy="0 -0 0" xyz="0 0 0"/>
            <geometry>
                <mesh filename="package://alpha_lite_model_meshes/meshes/pdr_v2/r_hip_l1_link_collision_hull.stl"/>
            </geometry>
            <material name="r_hip_l1_link_material">
                <color rgba="0.5 0.5 0.5 1.0"/>
            </material>
        </collision>
        <inertial>
            <origin rpy="0 0 0" xyz="-0.0690753 -1.81678e-06 -2.77244e-11"/>
            <mass value="0.136"/>
            <inertia ixx="4.19507e-06" ixy="-1.3868e-08" ixz="-1.75041e-13" iyy="0.000181669" iyz="1.45095e-12" izz="0.000181484"/>
        </inertial>
    </link>
    <!--=============================== r_hip_l1o_roll (r_hip_l1o_roll_link) ===========================-->
    <joint name="r_hip_l1o_roll" type="fixed">
        <origin rpy="-1.39711 -1.5708 0" xyz="0 -2.08167e-17 -6.93889e-18"/>
        <parent link="r_hip_l1_link"/>
        <child link="r_hip_l1o_roll_link"/>
    </joint>
    <link name="r_hip_l1o_roll_link">
        <inertial>
            <origin rpy="0 0 0" xyz="0 0 0"/>
            <mass value="0.0001"/>
            <inertia ixx="9.9999999999999995e-07" ixy="0" ixz="0" iyy="9.9999999999999995e-07" iyz="0" izz="9.9999999999999995e-07"/>
        </inertial>
    </link>
    <!--=============================== r_hip_aa (r_hip_aa_link) ===========================-->
    <joint name="r_hip_aa" type="revolute">
        <origin rpy="1.84101e-15 2.92182e-15 1.12458e-15" xyz="-1.66533e-16 1.38778e-17 5.55112e-17"/>
        <parent link="r_hip_ie_link"/>
        <child link="r_hip_aa_link"/>
        <axis xyz="1 0 0"/>
        <limit effort="494.0" lower="-0.8726646259971648" upper="0.3490658503988659" velocity="7.8"/>
    </joint>
    <link name="r_hip_aa_link">
        <visual>
            <origin rpy="0 -0 0" xyz="0 0 0"/>
            <geometry>
                <mesh filename="package://alpha_lite_model_meshes/meshes/pdr_v2/r_hip_aa_link_collision_hull.stl"/>
            </geometry>
            <material name="r_hip_aa_link_material">
                <color rgba="0.520793 0.521404 0.520977 1.0"/>
            </material>
        </visual>
        <collision>
            <origin rpy="0 -0 0" xyz="0 0 0"/>
            <geometry>
                <mesh filename="package://alpha_lite_model_meshes/meshes/pdr_v2/r_hip_aa_link_collision_hull.stl"/>
            </geometry>
            <material name="r_hip_aa_link_material">
                <color rgba="0.5 0.5 0.5 1.0"/>
            </material>
        </collision>
        <inertial>
            <origin rpy="0 0 0" xyz="0.00023159 -0.00118253 0.00424753"/>
            <mass value="0.412623"/>
            <inertia ixx="0.000324134" ixy="-1.12997e-07" ixz="-2.10253e-06" iyy="0.000138637" iyz="-3.33434e-05" izz="0.000309464"/>
        </inertial>
    </link>
    <!--=============================== r_hip_fe (r_hip_fe_link) ===========================-->
    <joint name="r_hip_fe" type="revolute">
        <origin rpy="0.300059 0.504035 0.148332" xyz="0 -1.38778e-17 -2.77556e-17"/>
        <parent link="r_hip_aa_link"/>
        <child link="r_hip_fe_link"/>
        <axis xyz="0 1 0"/>
        <limit effort="342.0" lower="-1.9198621771937625" upper="0.6108652381980153" velocity="11.3"/>
    </joint>
    <link name="r_hip_fe_link">
        <visual>
            <origin rpy="0 -0 0" xyz="0 0 0"/>
            <geometry>
                <mesh filename="package://alpha_lite_model_meshes/meshes/pdr_v2/r_hip_fe_link_collision_hull.stl"/>
            </geometry>
            <material name="r_hip_fe_link_material">
                <color rgba="0.407127 0.407165 0.407186 1.0"/>
            </material>
        </visual>
        <collision>
            <origin rpy="0 -0 0" xyz="0 0 0"/>
            <geometry>
                <mesh filename="package://alpha_lite_model_meshes/meshes/pdr_v2/r_hip_fe_link_collision_hull.stl"/>
            </geometry>
            <material name="r_hip_fe_link_material">
                <color rgba="0.5 0.5 0.5 1.0"/>
            </material>
        </collision>
        <inertial>
            <origin rpy="0 0 0" xyz="0.0173337 -0.00546411 -0.241799"/>
            <mass value="4.32778"/>
            <inertia ixx="0.0696356" ixy="0.000256976" ixz="-0.00692679" iyy="0.0681946" iyz="0.00105902" izz="0.0221608"/>
        </inertial>
    </link>
    <!--=============================== r_hip_l2_fix (r_hip_l2_fix_link) ===========================-->
    <joint name="r_hip_l2_fix" type="fixed">
        <origin rpy="1.21292e-14 -6.57807e-15 3.14159" xyz="-0.0565 -0.035 -0.3691"/>
        <parent link="r_hip_fe_link"/>
        <child link="r_hip_l2_fix_link"/>
    </joint>
    <link name="r_hip_l2_fix_link">
        <inertial>
            <origin rpy="0 0 0" xyz="0 0 0"/>
            <mass value="0.0001"/>
            <inertia ixx="9.9999999999999995e-07" ixy="0" ixz="0" iyy="9.9999999999999995e-07" iyz="0" izz="9.9999999999999995e-07"/>
        </inertial>
    </link>
    <!--=============================== r_hip_l1_fix (r_hip_l1_fix_link) ===========================-->
    <joint name="r_hip_l1_fix" type="fixed">
        <origin rpy="1.15186e-14 -6.57807e-15 3.14159" xyz="-0.0565 0.035 -0.3691"/>
        <parent link="r_hip_fe_link"/>
        <child link="r_hip_l1_fix_link"/>
    </joint>
    <link name="r_hip_l1_fix_link">
        <inertial>
            <origin rpy="0 0 0" xyz="0 0 0"/>
            <mass value="0.0001"/>
            <inertia ixx="9.9999999999999995e-07" ixy="0" ixz="0" iyy="9.9999999999999995e-07" iyz="0" izz="9.9999999999999995e-07"/>
        </inertial>
    </link>
    <!--=============================== r_knee_fe (r_knee_fe_link) ===========================-->
    <joint name="r_knee_fe" type="revolute">
        <origin rpy="-1.91862e-31 -5.08979e-31 3.30977e-15" xyz="-0.05 0 -0.425"/>
        <parent link="r_hip_fe_link"/>
        <child link="r_knee_fe_link"/>
        <axis xyz="0 1 0"/>
        <limit effort="336.0" lower="0.0" upper="2.6179938779914944" velocity="9.7"/>
    </joint>
    <link name="r_knee_fe_link">
        <visual>
            <origin rpy="0 -0 0" xyz="0 0 0"/>
            <geometry>
                <mesh filename="package://alpha_lite_model_meshes/meshes/pdr_v2/r_knee_fe_link_collision_hull.stl"/>
            </geometry>
            <material name="r_knee_fe_link_material">
                <color rgba="0.408495 0.407441 0.405951 1.0"/>
            </material>
        </visual>
        <collision>
            <origin rpy="0 -0 0" xyz="0 0 0"/>
            <geometry>
                <mesh filename="package://alpha_lite_model_meshes/meshes/pdr_v2/r_knee_fe_link_collision_hull.stl"/>
            </geometry>
            <material name="r_knee_fe_link_material">
                <color rgba="0.5 0.5 0.5 1.0"/>
            </material>
        </collision>
        <inertial>
            <origin rpy="0 0 0" xyz="0.0615338 -0.000406809 -0.131614"/>
            <mass value="1.98037"/>
            <inertia ixx="0.0343381" ixy="-5.22481e-05" ixz="-0.000388148" iyy="0.0354249" iyz="-3.13402e-05" izz="0.00347843"/>
        </inertial>
    </link>
    <!--=============================== r_ankle_l1i_roll (r_ankle_l1i_roll_link) ===========================-->
    <joint name="r_ankle_l1i_roll" type="fixed">
        <origin rpy="-0.0171227 -0.0062405 6.3484e-17" xyz="0.025 0.03 -0.0391"/>
        <parent link="r_knee_fe_link"/>
        <child link="r_ankle_l1i_roll_link"/>
    </joint>
    <link name="r_ankle_l1i_roll_link">
        <inertial>
            <origin rpy="0 0 0" xyz="0 0 0"/>
            <mass value="0.00001"/>
            <inertia ixx="0" ixy="0" ixz="0" iyy="0" iyz="0" izz="0"/>
        </inertial>
    </link>
    <!--=============================== r_ankle_l1i_pitch (r_ankle_l1i_pitch_link) ===========================-->
    <joint name="r_ankle_l1i_pitch" type="fixed">
        <origin rpy="1.10025e-14 1.567 9.19989e-13" xyz="-1.73472e-15 1.11022e-16 1.44329e-15"/>
        <parent link="r_ankle_l1i_roll_link"/>
        <child link="r_ankle_l1i_pitch_link"/>
    </joint>
    <link name="r_ankle_l1i_pitch_link">
        <visual>
            <origin rpy="0 -0 0" xyz="0 0 0"/>
            <geometry>
                <mesh filename="package://alpha_lite_model_meshes/meshes/pdr_v2/r_ankle_l1i_pitch_link_collision_hull.stl"/>
            </geometry>
            <material name="r_ankle_l1i_pitch_link_material">
                <color rgba="0.647059 0.647059 0.647059 1.0"/>
            </material>
        </visual>
        <collision>
            <origin rpy="0 -0 0" xyz="0 0 0"/>
            <geometry>
                <mesh filename="package://alpha_lite_model_meshes/meshes/pdr_v2/r_ankle_l1i_pitch_link_collision_hull.stl"/>
            </geometry>
            <material name="r_ankle_l1i_pitch_link_material">
                <color rgba="0.5 0.5 0.5 1.0"/>
            </material>
        </collision>
        <inertial>
            <origin rpy="0 0 0" xyz="0.103018 9.28819e-06 0.00025801"/>
            <mass value="0.785"/>
            <inertia ixx="0.000287605" ixy="6.41759e-07" ixz="1.44488e-05" iyy="0.00245437" iyz="-1.21859e-07" izz="0.00245075"/>
        </inertial>
    </link>
    <!--=============================== r_ankle_l1 (r_ankle_l1_link) ===========================-->
    <joint name="r_ankle_l1" type="fixed">
        <origin rpy="9.26787e-17 2.96557e-17 6.09368e-18" xyz="0.3612 8.32667e-17 -1.38778e-17"/>
        <parent link="r_ankle_l1i_pitch_link"/>
        <child link="r_ankle_l1_link"/>
    </joint>
    <link name="r_ankle_l1_link">
        <visual>
            <origin rpy="0 -0 0" xyz="0 0 0"/>
            <geometry>
                <mesh filename="package://alpha_lite_model_meshes/meshes/pdr_v2/r_ankle_l1_link_collision_hull.stl"/>
            </geometry>
            <material name="r_ankle_l1_link_material">
                <color rgba="0.647059 0.647059 0.647059 1.0"/>
            </material>
        </visual>
        <collision>
            <origin rpy="0 -0 0" xyz="0 0 0"/>
            <geometry>
                <mesh filename="package://alpha_lite_model_meshes/meshes/pdr_v2/r_ankle_l1_link_collision_hull.stl"/>
            </geometry>
            <material name="r_ankle_l1_link_material">
                <color rgba="0.5 0.5 0.5 1.0"/>
            </material>
        </collision>
        <inertial>
            <origin rpy="0 0 0" xyz="-0.123353 -1.4763e-18 1.09771e-17"/>
            <mass value="0.248858"/>
            <inertia ixx="7.81352e-06" ixy="-4.81989e-21" ixz="-2.09061e-21" iyy="0.00111084" iyz="2.46967e-12" izz="0.00111067"/>
        </inertial>
    </link>
    <!--=============================== r_ankle_l1o_roll (r_ankle_l1o_roll_link) ===========================-->
    <joint name="r_ankle_l1o_roll" type="fixed">
        <origin rpy="-2.29846 -1.5708 0" xyz="0 1.38778e-17 -1.38778e-17"/>
        <parent link="r_ankle_l1_link"/>
        <child link="r_ankle_l1o_roll_link"/>
    </joint>
    <link name="r_ankle_l1o_roll_link">
        <inertial>
            <origin rpy="0 0 0" xyz="0 0 0"/>
            <mass value="0.00001"/>
            <inertia ixx="0" ixy="0" ixz="0" iyy="0" iyz="0" izz="0"/>
        </inertial>
    </link>
    <!--=============================== r_knee_l1_fix (r_knee_l1_fix_link) ===========================-->
    <joint name="r_knee_l1_fix" type="fixed">
        <origin rpy="-3.14159 5.27356e-16 -1.5708" xyz="0.0221875 -2.22045e-16 0.0475812"/>
        <parent link="r_knee_fe_link"/>
        <child link="r_knee_l1_fix_link"/>
    </joint>
    <link name="r_knee_l1_fix_link">
        <inertial>
            <origin rpy="0 0 0" xyz="0 0 0"/>
            <mass value="0.00001"/>
            <inertia ixx="0" ixy="0" ixz="0" iyy="0" iyz="0" izz="0"/>
        </inertial>
    </link>
    <!--=============================== r_ankle_l2i_roll (r_ankle_l2i_roll_link) ===========================-->
    <joint name="r_ankle_l2i_roll" type="fixed">
        <origin rpy="0.0936697 -0.0062405 6.3484e-17" xyz="0.025 -0.05 -0.0391"/>
        <parent link="r_knee_fe_link"/>
        <child link="r_ankle_l2i_roll_link"/>
    </joint>
    <link name="r_ankle_l2i_roll_link">
        <inertial>
            <origin rpy="0 0 0" xyz="0 0 0"/>
            <mass value="0.00001"/>
            <inertia ixx="0" ixy="0" ixz="0" iyy="0" iyz="0" izz="0"/>
        </inertial>
    </link>
    <!--=============================== r_ankle_l2i_pitch (r_ankle_l2i_pitch_link) ===========================-->
    <joint name="r_ankle_l2i_pitch" type="fixed">
        <origin rpy="-3.14159 1.56766 3.14159" xyz="-1.45717e-15 1.66533e-16 -3.33067e-16"/>
        <parent link="r_ankle_l2i_roll_link"/>
        <child link="r_ankle_l2i_pitch_link"/>
    </joint>
    <link name="r_ankle_l2i_pitch_link">
        <visual>
            <origin rpy="0 -0 0" xyz="0 0 0"/>
            <geometry>
                <mesh filename="package://alpha_lite_model_meshes/meshes/pdr_v2/r_ankle_l2i_pitch_link_collision_hull.stl"/>
            </geometry>
            <material name="r_ankle_l2i_pitch_link_material">
                <color rgba="0.647059 0.647059 0.647059 1.0"/>
            </material>
        </visual>
        <collision>
            <origin rpy="0 -0 0" xyz="0 0 0"/>
            <geometry>
                <mesh filename="package://alpha_lite_model_meshes/meshes/pdr_v2/r_ankle_l2i_pitch_link_collision_hull.stl"/>
            </geometry>
            <material name="r_ankle_l2i_pitch_link_material">
                <color rgba="0.5 0.5 0.5 1.0"/>
            </material>
        </collision>
        <inertial>
            <origin rpy="0 0 0" xyz="0.103018 9.28819e-06 0.00025801"/>
            <mass value="0.785"/>
            <inertia ixx="0.000287605" ixy="6.41759e-07" ixz="1.44488e-05" iyy="0.00245437" iyz="-1.21859e-07" izz="0.00245075"/>
        </inertial>
    </link>
    <!--=============================== r_ankle_l2 (r_ankle_l2_link) ===========================-->
    <joint name="r_ankle_l2" type="fixed">
        <origin rpy="-2.17272e-17 -2.90006e-17 -4.19297e-18" xyz="0.3612 8.32667e-17 -1.38778e-17"/>
        <parent link="r_ankle_l2i_pitch_link"/>
        <child link="r_ankle_l2_link"/>
    </joint>
    <link name="r_ankle_l2_link">
        <visual>
            <origin rpy="0 -0 0" xyz="0 0 0"/>
            <geometry>
                <mesh filename="package://alpha_lite_model_meshes/meshes/pdr_v2/r_ankle_l2_link_collision_hull.stl"/>
            </geometry>
            <material name="r_ankle_l2_link_material">
                <color rgba="0.647059 0.647059 0.647059 1.0"/>
            </material>
        </visual>
        <collision>
            <origin rpy="0 -0 0" xyz="0 0 0"/>
            <geometry>
                <mesh filename="package://alpha_lite_model_meshes/meshes/pdr_v2/r_ankle_l2_link_collision_hull.stl"/>
            </geometry>
            <material name="r_ankle_l2_link_material">
                <color rgba="0.5 0.5 0.5 1.0"/>
            </material>
        </collision>
        <inertial>
            <origin rpy="0 0 0" xyz="-0.123353 -4.11774e-18 2.51448e-17"/>
            <mass value="0.248858"/>
            <inertia ixx="7.81352e-06" ixy="-2.02884e-20" ixz="-3.62463e-22" iyy="0.00111084" iyz="2.46967e-12" izz="0.00111067"/>
        </inertial>
    </link>
    <!--=============================== r_ankle_l2o_roll (r_ankle_l2o_roll_link) ===========================-->
    <joint name="r_ankle_l2o_roll" type="fixed">
        <origin rpy="0.254177 -1.5708 0" xyz="2.22045e-16 0 0"/>
        <parent link="r_ankle_l2_link"/>
        <child link="r_ankle_l2o_roll_link"/>
    </joint>
    <link name="r_ankle_l2o_roll_link">
        <inertial>
            <origin rpy="0 0 0" xyz="0 0 0"/>
            <mass value="0.00001"/>
            <inertia ixx="0" ixy="0" ixz="0" iyy="0" iyz="0" izz="0"/>
        </inertial>
    </link>
    <!--=============================== r_ankle_ie (r_ankle_ie_link) ===========================-->
    <joint name="r_ankle_ie" type="revolute">
        <origin rpy="-0.261799 -0.261799 -1.21001e-15" xyz="0.05 0 -0.425"/>
        <parent link="r_knee_fe_link"/>
        <child link="r_ankle_ie_link"/>
        <axis xyz="1 0 0"/>
        <limit effort="120.0" lower="-0.3490658503988659" upper="0.8726646259971648" velocity="8.5"/>
    </joint>
    <link name="r_ankle_ie_link">
        <visual>
            <origin rpy="0 -0 0" xyz="0 0 0"/>
            <geometry>
                <mesh filename="package://alpha_lite_model_meshes/meshes/pdr_v2/r_ankle_ie_link_collision_hull.stl"/>
            </geometry>
            <material name="r_ankle_ie_link_material">
                <color rgba="0.761714 0.855586 0.708841 1.0"/>
            </material>
        </visual>
        <collision>
            <origin rpy="0 -0 0" xyz="0 0 0"/>
            <geometry>
                <mesh filename="package://alpha_lite_model_meshes/meshes/pdr_v2/r_ankle_ie_link_collision_hull.stl"/>
            </geometry>
            <material name="r_ankle_ie_link_material">
                <color rgba="0.5 0.5 0.5 1.0"/>
            </material>
        </collision>
        <inertial>
            <origin rpy="0 0 0" xyz="0.00823503 9.97114e-05 0.000558702"/>
            <mass value="0.11681"/>
            <inertia ixx="4.65356e-05" ixy="9.59232e-08" ixz="-3.4309e-06" iyy="1.66479e-05" iyz="1.25695e-08" izz="4.22352e-05"/>
        </inertial>
    </link>
    <!--=============================== r_ankle_pd (r_ankle_pd_link) ===========================-->
    <joint name="r_ankle_pd" type="revolute">
        <origin rpy="3.16817e-16 0.523599 -4.52509e-17" xyz="5.55112e-17 -2.77556e-17 1.11022e-16"/>
        <parent link="r_ankle_ie_link"/>
        <child link="r_ankle_pd_link"/>
        <axis xyz="0 1 0"/>
        <limit effort="150.0" lower="-1.5707963267948966" upper="0.7853981633974483" velocity="9.5"/>
    </joint>
    <link name="r_ankle_pd_link">
        <visual>
            <origin rpy="0 -0 0" xyz="0 0 0"/>
            <geometry>
                <mesh filename="package://alpha_lite_model_meshes/meshes/pdr_v2/r_ankle_pd_link_collision_hull.stl"/>
            </geometry>
            <material name="r_ankle_pd_link_material">
                <color rgba="0.736632 0.721794 0.682563 1.0"/>
            </material>
        </visual>
        <collision>
            <origin rpy="0 -0 0" xyz="0 0 0"/>
            <geometry>
                <mesh filename="package://alpha_lite_model_meshes/meshes/pdr_v2/r_ankle_pd_link_collision_hull.stl"/>
            </geometry>
            <material name="r_ankle_pd_link_material">
                <color rgba="0.5 0.5 0.5 1.0"/>
            </material>
        </collision>
        <inertial>
            <origin rpy="0 0 0" xyz="0.0308482 0.00844065 -0.0292349"/>
            <mass value="0.65952"/>
            <inertia ixx="0.000773716" ixy="-4.28006e-05" ixz="-0.000198676" iyy="0.00197828" iyz="-6.08633e-05" izz="0.00227882"/>
        </inertial>
    </link>
    <!--=============================== r_ankle_l2_fix (r_ankle_l2_fix_link) ===========================-->
    <joint name="r_ankle_l2_fix" type="fixed">
        <origin rpy="-1.5708 9.63433e-17 2.80664e-17" xyz="-0.0246202 -0.02 0.0043412"/>
        <parent link="r_ankle_pd_link"/>
        <child link="r_ankle_l2_fix_link"/>
    </joint>
    <link name="r_ankle_l2_fix_link">
        <inertial>
            <origin rpy="0 0 0" xyz="0 0 0"/>
            <mass value="0.00001"/>
            <inertia ixx="0" ixy="0" ixz="0" iyy="0" iyz="0" izz="0"/>
        </inertial>
    </link>
    <!--=============================== r_sole (r_sole_link) ===========================-->
    <joint name="r_sole" type="fixed">
        <origin rpy="0.277793 -0.234899 -0.0662738" xyz="0.0483726 0.0156082 -0.0473442"/>
        <parent link="r_ankle_pd_link"/>
        <child link="r_sole_link"/>
    </joint>
    <link name="r_sole_link">
        <inertial>
            <origin rpy="0 0 0" xyz="0 0 0"/>
            <mass value="0.00001"/>
            <inertia ixx="0" ixy="0" ixz="0" iyy="0" iyz="0" izz="0"/>
        </inertial>
    </link>
    <!--=============================== r_ankle_l1_fix (r_ankle_l1_fix_link) ===========================-->
    <joint name="r_ankle_l1_fix" type="fixed">
        <origin rpy="1.5708 7.9009e-17 6.27609e-17" xyz="-0.0246202 0.02 0.0043412"/>
        <parent link="r_ankle_pd_link"/>
        <child link="r_ankle_l1_fix_link"/>
    </joint>
    <link name="r_ankle_l1_fix_link">
        <inertial>
            <origin rpy="0 0 0" xyz="0 0 0"/>
            <mass value="0.00001"/>
            <inertia ixx="0" ixy="0" ixz="0" iyy="0" iyz="0" izz="0"/>
        </inertial>
    </link>
    <!--=============================== r_knee_l1i_pitch (r_knee_l1i_pitch_link) ===========================-->
    <joint name="r_knee_l1i_pitch" type="fixed">
        <origin rpy="-3.14159 1.22834 3.14159" xyz="0.08 1.38778e-17 -0.075"/>
        <parent link="r_hip_fe_link"/>
        <child link="r_knee_l1i_pitch_link"/>
    </joint>
    <link name="r_knee_l1i_pitch_link">
        <visual>
            <origin rpy="0 -0 0" xyz="0 0 0"/>
            <geometry>
                <mesh filename="package://alpha_lite_model_meshes/meshes/pdr_v2/r_knee_l1i_pitch_link_collision_hull.stl"/>
            </geometry>
            <material name="r_knee_l1i_pitch_link_material">
                <color rgba="0.647059 0.647059 0.647059 1.0"/>
            </material>
        </visual>
        <collision>
            <origin rpy="0 -0 0" xyz="0 0 0"/>
            <geometry>
                <mesh filename="package://alpha_lite_model_meshes/meshes/pdr_v2/r_knee_l1i_pitch_link_collision_hull.stl"/>
            </geometry>
            <material name="r_knee_l1i_pitch_link_material">
                <color rgba="0.5 0.5 0.5 1.0"/>
            </material>
        </collision>
        <inertial>
            <origin rpy="0 0 0" xyz="0.113742 -1.79001e-05 0.000101143"/>
            <mass value="3.34415"/>
            <inertia ixx="0.00368832" ixy="-5.55699e-06" ixz="2.97262e-05" iyy="0.0149308" iyz="9.73239e-07" izz="0.0149109"/>
        </inertial>
    </link>
    <!--=============================== r_knee_l1 (r_knee_l1_link) ===========================-->
    <joint name="r_knee_l1" type="fixed">
        <origin rpy="-2.22179e-15 -3.38326e-17 5.29452e-31" xyz="0.3147 3.21965e-15 -7.21645e-16"/>
        <parent link="r_knee_l1i_pitch_link"/>
        <child link="r_knee_l1_link"/>
    </joint>
    <link name="r_knee_l1_link">
        <visual>
            <origin rpy="0 -0 0" xyz="0 0 0"/>
            <geometry>
                <mesh filename="package://alpha_lite_model_meshes/meshes/pdr_v2/r_knee_l1_link_collision_hull.stl"/>
            </geometry>
            <material name="r_knee_l1_link_material">
                <color rgba="0.647059 0.647059 0.647059 1.0"/>
            </material>
        </visual>
        <collision>
            <origin rpy="0 -0 0" xyz="0 0 0"/>
            <geometry>
                <mesh filename="package://alpha_lite_model_meshes/meshes/pdr_v2/r_knee_l1_link_collision_hull.stl"/>
            </geometry>
            <material name="r_knee_l1_link_material">
                <color rgba="0.5 0.5 0.5 1.0"/>
            </material>
        </collision>
        <inertial>
            <origin rpy="0 0 0" xyz="-0.0910004 1.33225e-09 5.82722e-10"/>
            <mass value="0.323454"/>
            <inertia ixx="6.93665e-06" ixy="-1.02011e-11" ixz="-5.23564e-12" iyy="0.000289524" iyz="4.20558e-13" izz="0.000289235"/>
        </inertial>
    </link>
    <link name="lToe">
        <inertial>
            <origin rpy="0 0 0" xyz="0 0 0"/>
            <mass value="0.0001"/>
            <inertia ixx="9.9999999999999995e-07" ixy="0" ixz="0" iyy="9.9999999999999995e-07" iyz="0" izz="9.9999999999999995e-07"/>
        </inertial>
    </link>
    <joint name="lToe" type="fixed">
        <origin rpy="0 0 0" xyz="0.1 0 -0.00"/>
        <parent link="l_sole_link"/>
        <child link="lToe"/>
    </joint>
    <link name="lHeel">
        <inertial>
            <origin rpy="0 0 0" xyz="0 0 0"/>
            <mass value="0.0001"/>
            <inertia ixx="9.9999999999999995e-07" ixy="0" ixz="0" iyy="9.9999999999999995e-07" iyz="0" izz="9.9999999999999995e-07"/>
        </inertial>
    </link>
    <joint name="lHeel" type="fixed">
        <origin rpy="0 0 0" xyz="-0.1 0 -0.00"/>
        <parent link="l_sole_link"/>
        <child link="lHeel"/>
    </joint>
    <joint name="l_foot_contact_frame" type="fixed">
        <origin rpy="0 0 0" xyz="0 0 -0.0025"/>
        <parent link="l_sole_link"/>
        <child link="lFoot"/>
    </joint>
    <link name="lFoot">
        <inertial>
            <origin rpy="0 0 0" xyz="0 0 0"/>
            <mass value="1e-9"/>
            <inertia ixx="0" ixy="0" ixz="0" iyy="0" iyz="0" izz="0"/>
        </inertial>
    </link>
    <link name="rToe">
        <inertial>
            <origin rpy="0 0 0" xyz="0 0 0"/>
            <mass value="0.0001"/>
            <inertia ixx="9.9999999999999995e-07" ixy="0" ixz="0" iyy="9.9999999999999995e-07" iyz="0" izz="9.9999999999999995e-07"/>
        </inertial>
    </link>
    <joint name="rToe" type="fixed">
        <origin rpy="0 0 0" xyz="0.1 0 -0.00"/>
        <parent link="r_sole_link"/>
        <child link="rToe"/>
    </joint>
    <link name="rHeel">
        <inertial>
            <origin rpy="0 0 0" xyz="0 0 0"/>
            <mass value="0.0001"/>
            <inertia ixx="9.9999999999999995e-07" ixy="0" ixz="0" iyy="9.9999999999999995e-07" iyz="0" izz="9.9999999999999995e-07"/>
        </inertial>
    </link>
    <joint name="rHeel" type="fixed">
        <origin rpy="0 0 0" xyz="-0.1 0 -0.00"/>
        <parent link="r_sole_link"/>
        <child link="rHeel"/>
    </joint>
    <joint name="r_foot_contact_frame" type="fixed">
        <origin rpy="0 0 0" xyz="0 0 -0.0025"/>
        <parent link="r_sole_link"/>
        <child link="rFoot"/>
    </joint>
    <link name="rFoot">
        <inertial>
            <origin rpy="0 0 0" xyz="0 0 0"/>
            <mass value="1e-9"/>
            <inertia ixx="0" ixy="0" ixz="0" iyy="0" iyz="0" izz="0"/>
        </inertial>
    </link>
    <link name="lHand">
        <inertial>
            <origin rpy="0 0 0" xyz="0 0 0"/>
            <mass value="0.000001"/>
            <inertia ixx="0" ixy="0" ixz="0" iyy="0" iyz="0" izz="0"/>
        </inertial>
    </link>
    <joint name="lHand" type="fixed">
        <origin rpy="0 0 0" xyz="0 0 -0.0"/>
        <parent link="l_hand_link"/>
        <child link="lHand"/>
    </joint>
    <link name="rHand">
        <inertial>
            <origin rpy="0 0 0" xyz="0 0 0"/>
            <mass value="0.000001"/>
            <inertia ixx="0" ixy="0" ixz="0" iyy="0" iyz="0" izz="0"/>
        </inertial>
    </link>
    <joint name="rHand" type="fixed">
        <origin rpy="0 0 0" xyz="0 0 -0.0"/>
        <parent link="r_hand_link"/>
        <child link="rHand"/>
    </joint>
</robot>
