<?xml version="1.0" ?>
<!-- =================================================================================== -->
<!-- |    This document was autogenerated by xacro from /urdf/med7.xacro | -->
<!-- |    EDITING THIS FILE BY HAND IS NOT RECOMMENDED                                 | -->
<!-- =================================================================================== -->
<!-- top level -->
<robot name="med7">
  <!-- fixed to world, see http://classic.gazebosim.org/tutorials?tut=ros_urdf&cat=connect_ros -->
  <link name="world"/>
  <!--joint
        between world and link_0-->
  <joint name="world_joint" type="fixed">
    <parent link="world"/>
    <child link="link_0"/>
  </joint>
  <!-- ros_control-plugin -->
  <gazebo>
    <plugin filename="libgazebo_ros2_control.so" name="gazebo_ros2_control">
      <parameters>/home/mk/Documents/M31/install/lbr_ros2_control/share/lbr_ros2_control/config/lbr_controllers.yaml</parameters>
      <ros>
        <namespace>/lbr</namespace>
        <!-- remapping for controller manager inside Gazebo plugin -->
        <remapping>~/robot_description:=robot_description</remapping>
      </ros>
    </plugin>
  </gazebo>
  <gazebo reference="link_0">
    <mu1>0.2</mu1>
    <mu2>0.2</mu2>
  </gazebo>
  <gazebo reference="A1">
    <implicitSpringDamper>true</implicitSpringDamper>
    <provideFeedback>true</provideFeedback>
  </gazebo>
  <gazebo reference="link_1">
    <mu1>0.2</mu1>
    <mu2>0.2</mu2>
  </gazebo>
  <gazebo reference="A2">
    <implicitSpringDamper>true</implicitSpringDamper>
    <provideFeedback>true</provideFeedback>
  </gazebo>
  <gazebo reference="link_2">
    <mu1>0.2</mu1>
    <mu2>0.2</mu2>
  </gazebo>
  <gazebo reference="A3">
    <implicitSpringDamper>true</implicitSpringDamper>
    <provideFeedback>true</provideFeedback>
  </gazebo>
  <gazebo reference="link_3">
    <mu1>0.2</mu1>
    <mu2>0.2</mu2>
  </gazebo>
  <gazebo reference="A4">
    <implicitSpringDamper>true</implicitSpringDamper>
    <provideFeedback>true</provideFeedback>
  </gazebo>
  <gazebo reference="link_4">
    <mu1>0.2</mu1>
    <mu2>0.2</mu2>
  </gazebo>
  <gazebo reference="A5">
    <implicitSpringDamper>true</implicitSpringDamper>
    <provideFeedback>true</provideFeedback>
  </gazebo>
  <gazebo reference="link_5">
    <mu1>0.2</mu1>
    <mu2>0.2</mu2>
  </gazebo>
  <gazebo reference="A6">
    <implicitSpringDamper>true</implicitSpringDamper>
    <provideFeedback>true</provideFeedback>
  </gazebo>
  <gazebo reference="link_6">
    <mu1>0.2</mu1>
    <mu2>0.2</mu2>
  </gazebo>
  <gazebo reference="A7">
    <implicitSpringDamper>true</implicitSpringDamper>
    <provideFeedback>true</provideFeedback>
  </gazebo>
  <gazebo reference="link_7">
    <mu1>0.2</mu1>
    <mu2>0.2</mu2>
  </gazebo>
  <ros2_control name="lbr_system_interface" type="system">
    <hardware>
      <plugin>gazebo_ros2_control/GazeboSystem</plugin>
    </hardware>
    <joint name="A1">
      <param name="min_position">-2.9670597283903604</param>
      <param name="max_position">2.9670597283903604</param>
      <param name="max_velocity">1.710422666954443</param>
      <param name="max_torque">200</param>
      <command_interface name="position">
        <param name="min">-2.9670597283903604</param>
        <param name="max">2.9670597283903604</param>
      </command_interface>
      <command_interface name="effort">
        <param name="min">-200</param>
        <param name="max"> 200</param>
      </command_interface>
      <state_interface name="position"/>
      <state_interface name="velocity"/>
      <state_interface name="effort"/>
    </joint>
    <joint name="A2">
      <param name="min_position">-2.0943951023931953</param>
      <param name="max_position">2.0943951023931953</param>
      <param name="max_velocity">1.710422666954443</param>
      <param name="max_torque">200</param>
      <command_interface name="position">
        <param name="min">-2.0943951023931953</param>
        <param name="max">2.0943951023931953</param>
      </command_interface>
      <command_interface name="effort">
        <param name="min">-200</param>
        <param name="max"> 200</param>
      </command_interface>
      <state_interface name="position"/>
      <state_interface name="velocity"/>
      <state_interface name="effort"/>
    </joint>
    <joint name="A3">
      <param name="min_position">-2.9670597283903604</param>
      <param name="max_position">2.9670597283903604</param>
      <param name="max_velocity">1.7453292519943295</param>
      <param name="max_torque">200</param>
      <command_interface name="position">
        <param name="min">-2.9670597283903604</param>
        <param name="max">2.9670597283903604</param>
      </command_interface>
      <command_interface name="effort">
        <param name="min">-200</param>
        <param name="max"> 200</param>
      </command_interface>
      <state_interface name="position"/>
      <state_interface name="velocity"/>
      <state_interface name="effort"/>
    </joint>
    <joint name="A4">
      <param name="min_position">-2.0943951023931953</param>
      <param name="max_position">2.0943951023931953</param>
      <param name="max_velocity">2.2689280275926285</param>
      <param name="max_torque">200</param>
      <command_interface name="position">
        <param name="min">-2.0943951023931953</param>
        <param name="max">2.0943951023931953</param>
      </command_interface>
      <command_interface name="effort">
        <param name="min">-200</param>
        <param name="max"> 200</param>
      </command_interface>
      <state_interface name="position"/>
      <state_interface name="velocity"/>
      <state_interface name="effort"/>
    </joint>
    <joint name="A5">
      <param name="min_position">-2.9670597283903604</param>
      <param name="max_position">2.9670597283903604</param>
      <param name="max_velocity">2.443460952792061</param>
      <param name="max_torque">200</param>
      <command_interface name="position">
        <param name="min">-2.9670597283903604</param>
        <param name="max">2.9670597283903604</param>
      </command_interface>
      <command_interface name="effort">
        <param name="min">-200</param>
        <param name="max"> 200</param>
      </command_interface>
      <state_interface name="position"/>
      <state_interface name="velocity"/>
      <state_interface name="effort"/>
    </joint>
    <joint name="A6">
      <param name="min_position">-2.0943951023931953</param>
      <param name="max_position">2.0943951023931953</param>
      <param name="max_velocity">3.141592653589793</param>
      <param name="max_torque">200</param>
      <command_interface name="position">
        <param name="min">-2.0943951023931953</param>
        <param name="max">2.0943951023931953</param>
      </command_interface>
      <command_interface name="effort">
        <param name="min">-200</param>
        <param name="max"> 200</param>
      </command_interface>
      <state_interface name="position"/>
      <state_interface name="velocity"/>
      <state_interface name="effort"/>
    </joint>
    <joint name="A7">
      <param name="min_position">-3.0543261909900763</param>
      <param name="max_position">3.0543261909900763</param>
      <param name="max_velocity">3.141592653589793</param>
      <param name="max_torque">200</param>
      <command_interface name="position">
        <param name="min">-3.0543261909900763</param>
        <param name="max">3.0543261909900763</param>
      </command_interface>
      <command_interface name="effort">
        <param name="min">-200</param>
        <param name="max"> 200</param>
      </command_interface>
      <state_interface name="position"/>
      <state_interface name="velocity"/>
      <state_interface name="effort"/>
    </joint>
  </ros2_control>
  <!-- properties -->
  <link name="link_0">
    <inertial>
      <origin rpy="0 0 0" xyz="-0.001896 0.0 0.076263"/>
      <mass value="7.143112"/>
      <inertia ixx="0.038694" ixy="0.0" ixz="-0.000686" iyy="0.039461" iyz="0.0" izz="0.054387"/>
    </inertial>
    <visual>
      <origin rpy="0 0 0" xyz="0 0 0"/>
      <geometry>
          <mesh filename="package://meshes/visual/link_0.dae"/>
      </geometry>
    </visual>
    <collision>
      <origin rpy="0 0 0" xyz="0 0 0"/>
      <geometry>
          <mesh filename="package://meshes/collision/link_0.stl"/>
      </geometry>
    </collision>
  </link>
  <joint name="A1" type="revolute">
    <origin rpy="0 0 0" xyz="0.0 0.0 0.1475"/>
    <parent link="link_0"/>
    <child link="link_1"/>
    <axis xyz="0.0 0.0 1.0"/>
    <limit effort="200" lower="-2.9670597283903604" upper="2.9670597283903604" velocity="1.710422666954443"/>
    <dynamics damping="10.0" friction="0.1"/>
  </joint>
  <link name="link_1">
    <inertial>
      <origin rpy="0 0 0" xyz="0.0 -0.034819  0.123299"/>
      <mass value="3.271499"/>
      <inertia ixx="0.020611" ixy="0.0" ixz="0.0" iyy="0.019667" iyz="0.00366" izz="0.00729"/>
    </inertial>
    <visual>
      <origin rpy="0 0 0" xyz="0.0 0.0 -0.1475"/>
      <geometry>
          <mesh filename="package://meshes/visual/link_1.dae"/>
      </geometry>
    </visual>
    <collision>
      <origin rpy="0 0 0" xyz="0.0 0.0 -0.1475"/>
      <geometry>
          <mesh filename="package://meshes/collision/link_1.stl"/>
      </geometry>
    </collision>
  </link>
  <joint name="A2" type="revolute">
    <origin rpy="0 0 0" xyz="0.0 -0.0105 0.1925"/>
    <parent link="link_1"/>
    <child link="link_2"/>
    <axis xyz="0.0 1.0 0.0"/>
    <limit effort="200" lower="-2.0943951023931953" upper="2.0943951023931953" velocity="1.710422666954443"/>
    <dynamics damping="10.0" friction="0.1"/>
  </joint>
  <link name="link_2">
    <inertial>
      <origin rpy="0 0 0" xyz="0.0 0.039793 0.086944"/>
      <mass value="3.886413"/>
      <inertia ixx="0.030552" ixy="0.0" ixz="0.0" iyy="0.028995" iyz="0.005676" izz="0.009317"/>
    </inertial>
    <visual>
      <origin rpy="0 0 0" xyz="0.0 0.0105 -0.34"/>
      <geometry>
          <mesh filename="package://meshes/visual/link_2.dae"/>
      </geometry>
    </visual>
    <collision>
      <origin rpy="0 0 0" xyz="0.0 0.0105 -0.34"/>
      <geometry>
          <mesh filename="package://meshes/collision/link_2.stl"/>
      </geometry>
    </collision>
  </link>
  <joint name="A3" type="revolute">
    <origin rpy="0 0 0" xyz="0.0 0.0105 0.2075"/>
    <parent link="link_2"/>
    <child link="link_3"/>
    <axis xyz="0.0 0.0 1.0"/>
    <limit effort="200" lower="-2.9670597283903604" upper="2.9670597283903604" velocity="1.7453292519943295"/>
    <dynamics damping="10.0" friction="0.1"/>
  </joint>
  <link name="link_3">
    <inertial>
      <origin rpy="0 0 0" xyz="0.0 0.034819  0.123299"/>
      <mass value="3.271499"/>
      <inertia ixx="0.020611" ixy="0.0" ixz="0.0" iyy="0.019667" iyz="-0.00366" izz="0.00729"/>
    </inertial>
    <visual>
      <origin rpy="0 0 0" xyz="0.0 0.0 -0.5475"/>
      <geometry>
          <mesh filename="package://meshes/visual/link_3.dae"/>
      </geometry>
    </visual>
    <collision>
      <origin rpy="0 0 0" xyz="0.0 0.0 -0.5475"/>
      <geometry>
          <mesh filename="package://meshes/collision/link_3.stl"/>
      </geometry>
    </collision>
  </link>
  <joint name="A4" type="revolute">
    <origin rpy="0 0 0" xyz="0.0 0.0105 0.1925"/>
    <parent link="link_3"/>
    <child link="link_4"/>
    <axis xyz="0.0 -1.0 0.0"/>
    <limit effort="200" lower="-2.0943951023931953" upper="2.0943951023931953" velocity="2.2689280275926285"/>
    <dynamics damping="10.0" friction="0.1"/>
  </joint>
  <link name="link_4">
    <inertial>
      <origin rpy="0 0 0" xyz="0.0 -0.039793  0.086944"/>
      <mass value="3.886411"/>
      <inertia ixx="0.030547" ixy="0.0" ixz="0.0" iyy="0.028993" iyz="-0.005676" izz="0.009313"/>
    </inertial>
    <visual>
      <origin rpy="0 0 0" xyz="0.0 -0.0105 -0.74"/>
      <geometry>
          <mesh filename="package://meshes/visual/link_4.dae"/>
      </geometry>
    </visual>
    <collision>
      <origin rpy="0 0 0" xyz="0.0 -0.0105 -0.74"/>
      <geometry>
          <mesh filename="package://meshes/collision/link_4.stl"/>
      </geometry>
    </collision>
  </link>
  <joint name="A5" type="revolute">
    <origin rpy="0 0 0" xyz="0.0 -0.0105 0.2075"/>
    <parent link="link_4"/>
    <child link="link_5"/>
    <axis xyz="0.0 0.0 1.0"/>
    <limit effort="200" lower="-2.9670597283903604" upper="2.9670597283903604" velocity="2.443460952792061"/>
    <dynamics damping="10.0" friction="0.1"/>
  </joint>
  <link name="link_5">
    <inertial>
      <origin rpy="0 0 0" xyz="0.0 -0.029824 0.076267"/>
      <mass value="1.474048"/>
      <inertia ixx="0.008179" ixy="0.0" ixz="0.0" iyy="0.006879" iyz="0.002704" izz="0.003709"/>
    </inertial>
    <visual>
      <origin rpy="0 0 0" xyz="0.0 0.0 -0.9475"/>
      <geometry>
          <mesh filename="package://meshes/visual/link_5.dae"/>
      </geometry>
    </visual>
    <collision>
      <origin rpy="0 0 0" xyz="0.0 0.0 -0.9475"/>
      <geometry>
          <mesh filename="package://meshes/collision/link_5.stl"/>
      </geometry>
    </collision>
  </link>
  <joint name="A6" type="revolute">
    <origin rpy="0 0 0" xyz="0.0 -0.0707 0.1925"/>
    <parent link="link_5"/>
    <child link="link_6"/>
    <axis xyz="0.0 1.0 0.0"/>
    <limit effort="200" lower="-2.0943951023931953" upper="2.0943951023931953" velocity="3.141592653589793"/>
    <dynamics damping="10.0" friction="0.1"/>
  </joint>
  <link name="link_6">
    <inertial>
      <origin rpy="0 0 0" xyz="-1.000e-06 7.102e-02 4.953e-03"/>
      <mass value="2.316911"/>
      <inertia ixx="0.006813" ixy="0.0" ixz="0.0" iyy="0.006559" iyz="0.0003" izz="0.004462"/>
    </inertial>
    <visual>
      <origin rpy="0 0 0" xyz="0.0 0.0707 -1.14"/>
      <geometry>
          <mesh filename="package://meshes/visual/link_6.dae"/>
      </geometry>
    </visual>
    <collision>
      <origin rpy="0 0 0" xyz="0.0 0.0707 -1.14"/>
      <geometry>
          <mesh filename="package://meshes/collision/link_6.stl"/>
      </geometry>
    </collision>
  </link>
  <joint name="A7" type="revolute">
    <origin rpy="0 0 0" xyz="0.0 0.0707 0.091"/>
    <parent link="link_6"/>
    <child link="link_7"/>
    <axis xyz="0.0 0.0 1.0"/>
    <limit effort="200" lower="-3.0543261909900763" upper="3.0543261909900763" velocity="3.141592653589793"/>
    <dynamics damping="10.0" friction="0.1"/>
  </joint>
  <link name="link_7">
    <inertial>
      <origin rpy="0 0 0" xyz="3.0000e-06 -2.0000e-06 1.3782e-02"/>
      <mass value="0.250108"/>
      <inertia ixx="0.000165" ixy="0.0" ixz="0.0" iyy="0.000165" iyz="0.0" izz="0.000288"/>
    </inertial>
    <visual>
      <origin rpy="0 0 0" xyz="0.0 0.0 -1.231"/>
      <geometry>
          <mesh filename="package://meshes/visual/link_7.dae"/>
      </geometry>
    </visual>
    <collision>
      <origin rpy="0 0 0" xyz="0.0 0.0 -1.231"/>
      <geometry>
          <mesh filename="package://meshes/collision/link_7.stl"/>
      </geometry>
    </collision>
  </link>
  <joint name="joint_ee" type="fixed">
    <parent link="link_7"/>
    <child link="link_ee"/>
    <origin rpy="0 0 0" xyz="0 0 0.035"/>
  </joint>
  <link name="link_ee">
        </link>
  <joint name="joint_ins" type="fixed">
    <parent link="link_ee"/>
    <child link="link_ins"/>
    <origin rpy="0 0 0" xyz="0 0 0.035"/>
  </joint>
  <link name="link_ins">
    <inertial>
      <origin rpy="0 0 0" xyz="3.0000e-06 -2.0000e-06 1.3782e-02"/>
      <mass value="0.250108"/>
      <inertia ixx="0.000165" ixy="0.0" ixz="0.0" iyy="0.000165" iyz="0.0" izz="0.000288"/>
    </inertial>
    <visual>
      <origin rpy="0 0 0.000" xyz="0.014 0.02 0.045"/>
      <geometry>
          <mesh filename="package://meshes/visual/link_inst.dae"/>
      </geometry>
    </visual>
    <collision>
      <origin rpy="0 0 -0.000" xyz="0.014 0.02 0.045"/>
      <geometry>
          <mesh filename="package://meshes/collision/link_inst.stl"/>
      </geometry>
    </collision>
  </link>
  <joint name="joint_inst_ee" type="fixed">
    <parent link="link_ee"/>
    <child link="link_inst_ee"/>
    <origin rpy="0 0 1.570796" xyz="0.018 0.084 0.4235"/>
  </joint>
  <link name="link_inst_ee">
        </link>
  <joint name="joint_ee_cam" type="fixed">
    <parent link="link_ee"/>
    <child link="link_cam"/>
    <origin rpy="-0.52359 0 1.570796" xyz="0.018 0.084 0.4235"/>
  </joint>
  <link name="link_cam">
        </link>
</robot>
