<?xml version="1.0" ?>

<robot name="optimo">

  <!-- Color Parameters -->
    <material name="white">
      <color rgba="1.0 1.0 1.0 1.0"/>
    </material>
    <material name="blue">
      <color rgba="0.5 0.5 1 1.0"/>
    </material>
    <material name="grey">
      <color rgba="0.2 0.2 0.2 1.0"/>
    </material>
    <material name="light_grey">
      <color rgba="0.3 0.3 0.3 1.0"/>
    </material>

  


  <!-- Pedestal -->
    <link name="optimo_pedestal">
      <visual>
        <geometry>
          <box size="0.3 0.3 1.0"/>
        </geometry>
        <material name="white"/>
      </visual>
      <collision>
        <geometry>
          <box size="0.3 0.3 1.0"/>
        </geometry>
      </collision>
      <inertial>
        <mass value="1.0"/>
        <inertia ixx="0.0" ixy="0.0" ixz="0.0" iyy="0.0" iyz="0.0" izz="0.0"/>
      </inertial>
    </link>

  <!-- Optimo Robot Arm -->

    <!-- Optimo Robot Arm Links -->
      <!-- Link0: optimo_base_link -->
      <link name="optimo_base_link">
        <visual>
          <geometry>
            <sphere radius="0.01"/>
          </geometry>
        </visual>
        <inertial>
          <origin xyz="0 0 0"/>
          <mass value="0.0"/>
          <inertia ixx="0.0" ixy="0.0" ixz="0.0" iyy="0.0" iyz="0.0" izz="0.0"/>
        </inertial>
      </link>

      <!-- Link1 : optimo_link0 -->
      <link name="optimo_link0">
        <visual>
          <geometry>
            <mesh filename="package://meshes/link0.stl"/>
          </geometry>
          <material name="grey"/>
        </visual>
        <collision>
          <geometry>
            <mesh filename="package://meshes/col0.stl"/>
          </geometry>
        </collision>
        <inertial>
          <!-- Doesn't matter, just placeholder values -->
          <origin xyz="0 0 0"/>
          <mass value="1"/>
          <inertia ixx="0" ixy="0.0" ixz="0.0" iyy="0" iyz="0.0" izz="0"/>
        </inertial>
      </link>

      <!-- Link2 : optimo_link1 -->
      <link name="optimo_link1">
        <inertial>
          <origin xyz="0 0 0"/>
          <mass value="0.0"/>
          <inertia ixx="0.0" ixy="0.0" ixz="0.0" iyy="0.0" iyz="0.0" izz="0.0"/>
        </inertial>
      </link>
      <!-- Link3 : optimo_link1_passive-->
      <link name="optimo_link1_passive">
        <visual>
          <geometry>
            <mesh filename="package://meshes/link1.stl"/>
          </geometry>
          <material name="light_grey"/>
        </visual>
        <collision>
          <geometry>
            <mesh filename="package://meshes/col1.stl"/>
          </geometry>
        </collision>
        <inertial>
          <origin xyz="0 -0.01635 0.01549"/>
          <mass value="4.152"/>
          <inertia ixx="0.01" ixy="0.000017" ixz="-.00001" iyy="0.007494" iyz="0.0000213" izz="0.009939"/>
        </inertial>
      </link>

      <!-- Link4 : optimo_link2 -->
      <link name="optimo_link2">
        <inertial>
          <origin xyz="0 0 0"/>
          <mass value="0.0"/>
          <inertia ixx="0.0" ixy="0.0" ixz="0.0" iyy="0.0" iyz="0.0" izz="0.0"/>
        </inertial>
      </link>
      <!-- Link5 : optimo_link2_passive -->
      <link name="optimo_link2_passive">
        <visual>
          <geometry>
            <mesh filename="package://meshes/link2.stl"/>
          </geometry>
          <material name="grey"/>
        </visual>
        <collision>
          <geometry>
            <mesh filename="package://meshes/col2.stl"/>
          </geometry>
        </collision>
        <inertial>
          <origin xyz="0 -0.05063 0.05677"/>
          <mass value="1.72"/>
          <inertia ixx="0.005694" ixy="0" ixz="0" iyy="0.005902" iyz="-0.001353" izz="0.002415"/>
        </inertial>
      </link>

      <!-- Link6 : optimo_link3 -->
      <link name="optimo_link3">
        <inertial>
          <origin xyz="0 0 0"/>
          <mass value="0.0"/>
          <inertia ixx="0.0" ixy="0.0" ixz="0.0" iyy="0.0" iyz="0.0" izz="0.0"/>
        </inertial>
      </link>
      <!-- Link7 : optimo_link3_passive -->
      <link name="optimo_link3_passive">
        <visual>
          <geometry>
            <mesh filename="package://meshes/link3.stl"/>
          </geometry>
          <material name="light_grey"/>
        </visual>
        <collision>
          <geometry>
            <mesh filename="package://meshes/col3.stl"/>
          </geometry>
        </collision>
        <inertial>
          <origin xyz="-0.000039 .098 0"/>
          <mass value="4.310"/>
          <inertia ixx="0.012989" ixy="-0.000015" ixz="-.000003" iyy="0.002584" iyz="0.000632" izz="0.01305"/>
        </inertial>
      </link>

      <!-- Link8 : optimo_link4 -->
      <link name="optimo_link4">
        <inertial>
          <origin xyz="0 0 0"/>
          <mass value="0.0"/>
          <inertia ixx="0.0" ixy="0.0" ixz="0.0" iyy="0.0" iyz="0.0" izz="0.0"/>
        </inertial>
      </link>
      <!-- Link9 : optimo_link4_passive -->
      <link name="optimo_link4_passive">
        <origin rpy="0 0 0" xyz="0 0 0"/>
        <visual>
          <geometry>
            <mesh filename="package://meshes/link4.stl"/>
          </geometry>
          <material name="grey"/>
        </visual>
        <collision>
          <geometry>
            <mesh filename="package://meshes/col4.stl"/>
          </geometry>
        </collision>
        <inertial>
          <origin rpy="0 0 0" xyz="-.00001 0.048852 0.0688"/>
          <mass value="1.09"/>
          <inertia ixx="0.004297" ixy="0" ixz="0" iyy="0.004366" iyz="0.0008" izz="0.000988"/>
        </inertial>
      </link>

      <!-- Link10 : optimo_link5 -->
      <link name="optimo_link5">
        <inertial>
          <origin xyz="0 0 0"/>
          <mass value="0.0"/>
          <inertia ixx="0.0" ixy="0.0" ixz="0.0" iyy="0.0" iyz="0.0" izz="0.0"/>
        </inertial>
      </link>
      <!-- Link11 : optimo_link5_passive -->
      <link name="optimo_link5_passive">
        <visual>
          <geometry>
            <mesh filename="package://meshes/link5.stl"/>
          </geometry>
          <material name="light_grey"/>
        </visual>
        <collision>
          <geometry>
            <mesh filename="package://meshes/col5.stl"/>
          </geometry>
        </collision>
        <inertial>
          <origin xyz=".001262 0.085 0.008"/>
          <mass value="2.23"/>
          <inertia ixx="0.005744" ixy="-0.00021" ixz="-0.000027" iyy="0.0018" iyz="0.001278" izz="0.005457"/>
        </inertial>
      </link>

      <!-- Link12 : optimo_link6 -->
      <link name="optimo_link6">
        <inertial>
          <origin xyz="0 0 0"/>
          <mass value="0.0"/>
          <inertia ixx="0.0" ixy="0.0" ixz="0.0" iyy="0.0" iyz="0.0" izz="0.0"/>
        </inertial>
      </link>
      <!-- Link13 : optimo_link6_passive -->
      <link name="optimo_link6_passive">
        <visual>
          <geometry>
            <mesh filename="package://meshes/link6.stl"/>
          </geometry>
          <material name="grey"/>
        </visual>
        <collision>
          <geometry>
            <mesh filename="package://meshes/col6.stl"/>
          </geometry>
        </collision>
        <inertial>
          <origin xyz="0 -0.00007 0.010855"/>
          <mass value="1.138"/>
          <inertia ixx="0.000634" ixy="0" ixz="0" iyy="0.000629" iyz="0" izz="0.000546"/>
        </inertial>
      </link>

      <!-- Link14 : optimo_link7 -->
      <link name="optimo_link7">
        <inertial>
          <origin xyz="0 0 0"/>
          <mass value="0.0"/>
          <inertia ixx="0.0" ixy="0.0" ixz="0.0" iyy="0.0" iyz="0.0" izz="0.0"/>
        </inertial>
      </link>
      <!-- Link15 : optimo_link7_passive -->
      <link name="optimo_link7_passive">
        <visual>
          <geometry>
            <mesh filename="package://meshes/link7.stl"/>
          </geometry>
          <material name="light_grey"/>
        </visual>
        <collision>
          <geometry>
            <mesh filename="package://meshes/col7.stl"/>
          </geometry>
        </collision>
        <inertial>
          <origin xyz="0 0 0.2"/>
          <mass value="1.246"/>
          <inertia ixx="0.005541" ixy=".000045" ixz="0.000077" iyy="0.004779" iyz="0.000043" izz="0.001723"/>
        </inertial>
      </link>

      <!-- Link16 : optimo_ee_link -->
      <link name="optimo_ee_link">
        <inertial>
          <origin xyz="0 0 0"/>
          <mass value="0.0"/>
          <inertia ixx="0.0" ixy="0.0" ixz="0.0" iyy="0.0" iyz="0.0" izz="0.0"/>
        </inertial>
      </link>

    <!-- Optimo Joints -->

      <!-- Joint0: optimo_pedestal_joint -->
      <joint name="optimo_pedestal_joint" type="fixed">
        <parent link="optimo_pedestal"/>
        <child link="optimo_base_link"/>
        <origin xyz="0 0 0.50" rpy="0 0 0"/>
      </joint>

      <!-- Joint1: optimo_base_joint -->
      <joint name="optimo_base_joint" type="fixed">
        <parent link="optimo_base_link"/>
        <child link="optimo_link0"/>
        <origin rpy="0 0 0" xyz="0.0 0.0 0.27"/>
      </joint>


      <!-- Joint2: optimo_joint1 -->
      <joint name="optimo_joint1" type="revolute">
        <origin rpy="0 0 0" xyz="0 0 0"/>
        <parent link="optimo_link0"/>
        <child link="optimo_link1"/>
        <axis xyz="0 0 1"/>
        <limit effort="79" lower="-2.86233997164" upper="2.91469984917" velocity="10"/>
        <dynamics damping="1" friction="0.1"/>
      </joint>
      <!-- Joint3: optimo_joint1_passive -->
      <joint name="optimo_joint1_passive" type="fixed">
        <origin rpy="1.5707963267948966 0 0" xyz="0 0 0"/>
        <parent link="optimo_link1"/>
        <child link="optimo_link1_passive"/>
      </joint>


      <!-- Joint4: optimo_joint2 -->
      <joint name="optimo_joint2" type="revolute">
        <origin rpy="0 0 0" xyz="0 0 0"/>
        <parent link="optimo_link1_passive"/>
        <child link="optimo_link2"/>
        <axis xyz="0 0 1"/>
        <limit effort="95" lower="1.0471975506" upper="4.3633231275" velocity="10"/>
        <dynamics damping="1" friction="0.1"/>
      </joint>
      <!-- Joint5: optimo_joint2_passive -->
      <joint name="optimo_joint2_passive" type="fixed">
        <origin rpy="1.5707963267948966 0 0" xyz="0 0 0"/>
        <parent link="optimo_link2"/>
        <child link="optimo_link2_passive"/>
      </joint>


      <!-- Joint6: optimo_joint3 -->
      <joint name="optimo_joint3" type="revolute">
        <origin rpy="0 0 0" xyz="0 0 0.4"/>
        <parent link="optimo_link2_passive"/>
        <child link="optimo_link3"/>
        <axis xyz="0 0 1"/>
        <limit effort="32" lower="-2.91469984917" upper="2.84488667913" velocity="10"/>
        <dynamics damping="1" friction="0.1"/>
      </joint>
      <!-- Joint7: optimo_joint3_passive -->
      <joint name="optimo_joint3_passive" type="fixed">
        <origin rpy="-1.5707963267948966 0 0" xyz="0 0 0"/>
        <parent link="optimo_link3"/>
        <child link="optimo_link3_passive"/>
      </joint>

      <!-- Joint8: optimo_joint4 -->
      <joint name="optimo_joint4" type="revolute">
        <origin rpy="0 0 0" xyz="0 0 0"/>
        <parent link="optimo_link3_passive"/>
        <child link="optimo_link4"/>
        <axis xyz="0 0 1"/>
        <limit effort="40" lower="-2.53072741395" upper="2.53072741395" velocity="10"/>
        <dynamics damping="1" friction="0.1"/>
      </joint>
      <!-- Joint9: optimo_joint4_passive -->
      <joint name="optimo_joint4_passive" type="fixed">
        <origin rpy="1.5707963267948966 0 0" xyz="0 0 0"/>
        <parent link="optimo_link4"/>
        <child link="optimo_link4_passive"/>
      </joint>


      <!-- Joint10: optimo_joint5 -->
      <joint name="optimo_joint5" type="revolute">
        <origin rpy="0 0 0" xyz="0 0 0.4"/>
        <parent link="optimo_link4_passive"/>
        <child link="optimo_link5"/>
        <axis xyz="0 0 1"/>
        <limit effort="15" lower="-2.9670597267" upper="2.9670597267" velocity="10"/>
        <dynamics damping="1" friction="0.1"/>
      </joint>
      <!-- Joint11: optimo_joint5_passive -->
      <joint name="optimo_joint5_passive" type="fixed">
        <origin rpy="-1.5707963267948966 0 0" xyz="0 0 0"/>
        <parent link="optimo_link5"/>
        <child link="optimo_link5_passive"/>
      </joint>

      <!-- Joint12: optimo_joint6 -->
      <joint name="optimo_joint6" type="revolute">
        <origin rpy="0 0 0" xyz="0 0 0"/>
        <parent link="optimo_link5_passive"/>
        <child link="optimo_link6"/>
        <axis xyz="0 0 1"/>
        <limit effort="15" lower="-2.0943951012" upper="2.0943951012" velocity="10"/>
        <dynamics damping="1" friction="0.1"/>
      </joint>
      <!-- Joint13: optimo_joint6_passive -->
      <joint name="optimo_joint6_passive" type="fixed">
        <origin rpy="1.5707963267948966 0 0" xyz="0 0 0"/>
        <parent link="optimo_link6"/>
        <child link="optimo_link6_passive"/>
      </joint>

      <!-- Joint14: optimo_joint7 --> 
      <joint name="optimo_joint7" type="revolute">
        <origin rpy="0 0 0" xyz="0 0 0"/>
        <parent link="optimo_link6_passive"/>
        <child link="optimo_link7"/>
        <axis xyz="0 0 1"/>
        <limit effort="15" lower="-2.65290046152" upper="3.28121899188" velocity="10"/>
        <dynamics damping="1" friction="0.1"/>
      </joint>
      <!-- Joint15: optimo_joint7_passive -->
      <joint name="optimo_joint7_passive" type="fixed">
        <origin rpy="0 0 0" xyz="0 0 0"/>
        <parent link="optimo_link7"/>
        <child link="optimo_link7_passive"/>
      </joint>

      <!-- Joint16: optimo_ee_joint -->
      <joint name="optimo_ee_joint" type="fixed">
        <parent link="optimo_link7_passive"/>
        <child link="optimo_ee_link"/>
        <origin rpy="0 -1.5707 3.14" xyz="0 0 0.15"/>
        <!-- <origin rpy="0 0 0" xyz="0 0 0"/> -->
      </joint>


  <!-- PLATO Hand -->

    <!-- Palm -->
      <!--Link 17: Hand Base Link -->
        <link name="plato_base_link">
          <visual>
            <origin rpy="0 0 0" xyz="0 0 0"/>
            <geometry>
              <mesh filename="package://meshes/plato_base_link_visual.stl"/>
            </geometry>
            <material name="grey"/>
          </visual>
          <collision>
            <origin rpy="0 0 0" xyz="0 0 0"/>
            <geometry>
              <mesh filename="package://meshes/plato_base_link_collision.stl"/>
            </geometry>
          </collision>
          <inertial>
            <origin rpy="0 0 0" xyz="0.044024972902329512214 0.00072624824425259696531 -0.01069566578635177366"/>
            <mass value="0.1615803584199397569"/>
            <inertia ixx="0.00014107640982160277654" ixy="-1.6705856892590392037e-06" ixz="2.2974647250647586648e-05" iyy="0.00020732421359090659452" iyz="2.6143219043340646574e-06" izz="0.00029225640965350557733"/>
          </inertial>
        </link>

    <!-- Finger 1: Thumb -->

      <!-- Link 18: plato_bracket_1 -->
      <link name="plato_bracket_1">
        <visual>
          <origin rpy="0 -0 0" xyz="0 0 0"/>
          <geometry>
            <mesh filename="package://meshes/plato_bracket_visual.stl"/>
          </geometry>
          <material name="plato_bracket_material">
            <color rgba="0.29588156155479994336 0.31447294875599396402 0.33306433595718798468 1.0"/>
          </material>
        </visual>
        <collision>
          <origin rpy="0 -0 0" xyz="0 0 0"/>
          <geometry>
            <mesh filename="package://meshes/plato_bracket_collision.stl"/>
          </geometry>
        </collision>
        <inertial>
          <origin rpy="0 0 0" xyz="-0.007950468555313989702 -0.013983661603934084694 -0.0095130973110596709491"/>
          <mass value="0.12656081824380857603"/>
          <inertia ixx="3.5117165939881846875e-05" ixy="-1.3052140141476195747e-05" ixz="1.9957519826332876807e-07" iyy="1.7537495218030352186e-05" iyz="-4.9180486622832108523e-07" izz="4.2451494821237245245e-05"/>
        </inertial>
      </link>

      <!-- Link 19: plato_proximal_1 -->
      <link name="plato_proximal_1">
        <visual>
          <origin rpy="0 -0 0" xyz="0 0 0"/>
          <geometry>
            <mesh filename="package://meshes/plato_proximal_visual.stl"/>
          </geometry>
          <material name="plato_proximal_material">
            <color rgba="0.34674225592475715896 0.3637734991268727347 0.38080474232898831044 1.0"/>
          </material>
        </visual>
        <collision>
          <origin rpy="0 -0 0" xyz="0 0 0"/>
          <geometry>
            <mesh filename="package://meshes/plato_proximal_collision.stl"/>
          </geometry>
        </collision>
        <inertial>
          <origin rpy="0 0 0" xyz="0.0020628634950130139356 3.9571814132102107738e-10 -0.015800949225316721775"/>
          <mass value="0.069077199724865326336"/>
          <inertia ixx="5.8838183215243567702e-06" ixy="-9.2074653187590902052e-09" ixz="-1.1499102511776846577e-06" iyy="9.6333284963110793952e-06" iyz="-9.5358114762121810647e-14" izz="9.2423803001322675e-06"/>
        </inertial>
      </link>

      <!-- Link 20: plato_distal_1 -->
      <link name="plato_distal_1">
        <visual>
          <origin rpy="0 -0 0" xyz="0 0 0"/>
          <geometry>
            <mesh filename="package://meshes/plato_distal_visual.stl"/>
          </geometry>
          <material name="plato_distal_material">
            <color rgba="0.6462146502129876291 0.65534742206524643215 0.66425012842436204075 1.0"/>
          </material>
        </visual>
        <collision>
          <origin rpy="0 -0 0" xyz="0 0 0"/>
          <geometry>
            <mesh filename="package://meshes/plato_distal_collision.stl"/>
          </geometry>
        </collision>
        <inertial>
          <origin rpy="0 0 0" xyz="0.02188265244158411893 -0.00092626544337757381418 -0.0023008125910617648058"/>
          <mass value="0.0084384550266508422112"/>
          <inertia ixx="2.2607154456154393468e-07" ixy="8.6363020365653532351e-08" ixz="-1.3958263751343117559e-10" iyy="1.4903406243236853063e-06" iyz="-2.9321372900383956756e-11" izz="1.5424304598463137095e-06"/>
        </inertial>
      </link>

      <!-- Link 21: plato_end_effector_1 -->
      <link name="plato_end_effector_1">
        <inertial>
          <mass value="0.0"/>
          <inertia ixx="0.0" ixy="0.0" ixz="0.0" iyy="0.0" iyz="0.0" izz="0.0"/>
        </inertial>
      </link>
  
    <!-- Finger 2: Index -->

      <!-- Link 22: plato_bracket_2 -->
      <link name="plato_bracket_2">
      <visual>
        <origin rpy="0 -0 0" xyz="0 0 0"/>
        <geometry>
          <mesh filename="package://meshes/plato_bracket_2_visual.stl"/>
        </geometry>
        <material name="plato_bracket_2_material">
          <color rgba="0.29588156155479994336 0.31447294875599396402 0.33306433595718798468 1.0"/>
        </material>
      </visual>
      <collision>
        <origin rpy="0 -0 0" xyz="0 0 0"/>
        <geometry>
          <mesh filename="package://meshes/plato_bracket_2_collision.stl"/>
        </geometry>
      </collision>
      <inertial>
        <origin rpy="0 0 0" xyz="-0.0079504685553137485754 0.013983661603933883466 -0.010286902688940335882"/>
        <mass value="0.12656081824380857603"/>
        <inertia ixx="3.5117165939881060828e-05" ixy="1.3052140141475585883e-05" ixz="-1.9957519826332447996e-07" iyy="1.75374952180298914e-05" iyz="-4.9180486622831886177e-07" izz="4.245149482123609328e-05"/>
      </inertial>
      </link>

      <!-- Link 23: plato_proximal_2 -->
      <link name="plato_proximal_2">
        <visual>
          <origin rpy="0 -0 0" xyz="0 0 0"/>
          <geometry>
            <mesh filename="package://meshes/plato_proximal_2_visual.stl"/>
          </geometry>
          <material name="plato_proximal_2_material">
            <color rgba="0.34674225592475710345 0.36377349912687267919 0.38080474232898825493 1.0"/>
          </material>
        </visual>
        <collision>
          <origin rpy="0 -0 0" xyz="0 0 0"/>
          <geometry>
            <mesh filename="package://meshes/plato_proximal_2_collision.stl"/>
          </geometry>
        </collision>
        <inertial>
          <origin rpy="0 0 0" xyz="0.0020628634950130178387 3.9571814177714764739e-10 -0.015800949225316659325"/>
          <mass value="0.069077199724865326336"/>
          <inertia ixx="5.8838183215243796401e-06" ixy="-9.2074653187647017985e-09" ixz="-1.1499102511776681406e-06" iyy="9.6333284963111200528e-06" iyz="-9.5358116812813355724e-14" izz="9.2423803001323522033e-06"/>
        </inertial>
      </link>

      <!-- Link 24: plato_distal_2 -->
      <link name="plato_distal_2">
        <visual>
          <origin rpy="0 -0 0" xyz="0 0 0"/>
          <geometry>
            <mesh filename="package://meshes/plato_distal_2_visual.stl"/>
          </geometry>
          <material name="plato_distal_2_material">
            <color rgba="0.64621465021298751807 0.65534742206524643215 0.66425012842436204075 1.0"/>
          </material>
        </visual>
        <collision>
          <origin rpy="0 -0 0" xyz="0 0 0"/>
          <geometry>
            <mesh filename="package://meshes/plato_distal_2_collision.stl"/>
          </geometry>
        </collision>
        <inertial>
          <origin rpy="0 0 0" xyz="0.021882652441583935049 0.00092626544337758606566 -0.0020991874089382723222"/>
          <mass value="0.0084384550266508422112"/>
          <inertia ixx="2.2607154456153689372e-07" ixy="-8.6363020365647801644e-08" ixz="1.3958263752012676321e-10" iyy="1.490340624323663707e-06" iyz="-2.9321372900131330627e-11" izz="1.542430459846286181e-06"/>
        </inertial>
      </link>

      <!-- Link 25: plato_end_effector_2 -->
      <link name="plato_end_effector_2">
        <inertial>
          <mass value="0.0"/>
          <inertia ixx="0.0" ixy="0.0" ixz="0.0" iyy="0.0" iyz="0.0" izz="0.0"/>
        </inertial>
      </link>

    <!-- Finger 3: Middle (often called pinky) -->

      <!-- Link 26: plato_bracket_3 -->
      <link name="plato_bracket_3">
        <visual>
          <origin rpy="0 -0 0" xyz="0 0 0"/>
          <geometry>
            <mesh filename="package://meshes/plato_bracket_3_visual.stl"/>
          </geometry>
          <material name="plato_bracket_3_material">
            <color rgba="0.29588156155479994336 0.31447294875599396402 0.33306433595718798468 1.0"/>
          </material>
        </visual>
        <collision>
          <origin rpy="0 -0 0" xyz="0 0 0"/>
          <geometry>
            <mesh filename="package://meshes/plato_bracket_3_collision.stl"/>
          </geometry>
        </collision>
        <inertial>
          <origin rpy="0 0 0" xyz="-0.0079504685553139723547 0.013983661603934063877 -0.010286902688940349759"/>
          <mass value="0.12656081824380857603"/>
          <inertia ixx="3.5117165939881745231e-05" ixy="1.305214014147615509e-05" ixz="-1.9957519826333954127e-07" iyy="1.7537495218030304752e-05" iyz="-4.9180486622830308578e-07" izz="4.2451494821237143601e-05"/>
        </inertial>
      </link>

      <!-- Link 27: plato_proximal_3 -->
      <link name="plato_proximal_3">
        <visual>
          <origin rpy="0 -0 0" xyz="0 0 0"/>
          <geometry>
            <mesh filename="package://meshes/plato_proximal_3_visual.stl"/>
          </geometry>
          <material name="plato_proximal_3_material">
            <color rgba="0.34674225592475710345 0.36377349912687267919 0.38080474232898825493 1.0"/>
          </material>
        </visual>
        <collision>
          <origin rpy="0 -0 0" xyz="0 0 0"/>
          <geometry>
            <mesh filename="package://meshes/plato_proximal_3_collision.stl"/>
          </geometry>
        </collision>
        <inertial>
          <origin rpy="0 0 0" xyz="0.0020628634950129892157 3.9571813297498531464e-10 -0.015800949225316596874"/>
          <mass value="0.069077199724865326336"/>
          <inertia ixx="5.8838183215242491971e-06" ixy="-9.2074653187517564219e-09" ixz="-1.149910251177736115e-06" iyy="9.6333284963105406823e-06" iyz="-9.5358108023765750655e-14" izz="9.2423803001321556917e-06"/>
        </inertial>
      </link>

      <!-- Link 28: plato_distal_3 -->
      <link name="plato_distal_3">
        <visual>
          <origin rpy="0 -0 0" xyz="0 0 0"/>
          <geometry>
            <mesh filename="package://meshes/plato_distal_3_visual.stl"/>
          </geometry>
          <material name="plato_distal_3_material">
            <color rgba="0.64621465021298751807 0.6553474220652466542 0.66425012842436204075 1.0"/>
          </material>
        </visual>
        <collision>
          <origin rpy="0 -0 0" xyz="0 0 0"/>
          <geometry>
            <mesh filename="package://meshes/plato_distal_3_collision.stl"/>
          </geometry>
        </collision>
        <inertial>
          <origin rpy="0 0 0" xyz="0.021882652441584091174 0.0009262654433776044971 -0.002099187408938216811"/>
          <mass value="0.0084384550266508422112"/>
          <inertia ixx="2.2607154456154218768e-07" ixy="-8.6363020365653373532e-08" ixz="1.3958263751464834601e-10" iyy="1.4903406243236808594e-06" iyz="-2.9321372899582573839e-11" izz="1.5424304598463096861e-06"/>
        </inertial>
      </link>

      <!-- Link 29: plato_end_effector_3 -->
      <link name="plato_end_effector_3">
        <inertial>
          <mass value="0.0"/>
          <inertia ixx="0.0" ixy="0.0" ixz="0.0" iyy="0.0" iyz="0.0" izz="0.0"/>
        </inertial>
      </link>

    <!-- Plato Joints -->

      <!-- Joint 17: plato_connector_joint -->
      <joint name="plato_connector_joint" type="fixed">
        <parent link="optimo_ee_link"/>
        <child link="plato_base_link"/>
        <origin rpy="0 0 0" xyz="0 0 0"/>
      </joint>

      <!-- Joint 18: plato_joint1 -->
      <joint name="plato_joint1" type="revolute">
        <origin rpy="1.5707963267948978903 0.00091996263300075529958 1.5707963267948956698" xyz="0.086299999999999960076 0.029999999999999440309 -0.031000000000000024064"/>
        <parent link="plato_base_link"/>
        <child link="plato_bracket_1"/>
        <axis xyz="0 0 1"/>
        <limit effort="0.06" lower="-0.1745329251994329478" upper="0.785398163397448279" velocity="0.0872665"/>
        <joint_properties friction="0.03"/>
      </joint>

      <!-- Joint 19: plato_joint2 -->
      <joint name="plato_joint2" type="revolute">
        <origin rpy="1.8618779238654332436e-18 -1.570796326794896336 0" xyz="-0.0050000000000000183187 -0.028149999999999991002 -0.0098999999999999921396"/>
        <parent link="plato_bracket_1"/>
        <child link="plato_proximal_1"/>
        <axis xyz="0 0 1"/>
        <limit effort="0.06" lower="-1.570796326794896558" upper="0.34906585039886589561" velocity="0.0872665"/>
        <joint_properties friction="0.03"/>
      </joint>

      <!-- Joint 20: plato_joint3 -->
      <joint name="plato_joint3" type="revolute">
        <origin rpy="7.3221470748390791342e-17 1.1335692351879312086e-16 -5.540689055843304715e-17" xyz="0.048000000000000000999 2.7755575615628913511e-17 -0.0027000000000001571354"/>
        <parent link="plato_proximal_1"/>
        <child link="plato_distal_1"/>
        <axis xyz="0 0 1"/>
        <limit effort="0.06" lower="0.0" upper="1.570796326794896558" velocity="0.0872665"/>
        <joint_properties friction="0.03"/>
      </joint>

      <!-- Joint 21: plato_ee_joint1 -->
      <joint name="plato_ee_joint1" type="fixed">
        <origin rpy="-1.5707 0.0 0.0" xyz="0.05060 0.0 0.0"/>
        <parent link="plato_distal_1"/>
        <child link="plato_end_effector_1"/>
      </joint>

      <!-- Joint 22: plato_joint4 -->
      <joint name="plato_joint4" type="revolute">
        <origin rpy="-3.1415926535897922278 -1.5612511283791256454e-16 1.5655578416789037721" xyz="0.08399999999999986644 0.029999999999999422962 -0.010000000000000045311"/>
        <parent link="plato_base_link"/>
        <child link="plato_bracket_2"/>
        <axis xyz="0 0 1"/>
        <limit effort="0.06" lower="-0.087266462599716473902" upper="0.087266462599716473902" velocity="0.0872665"/>
        <joint_properties friction="0.03"/>
      </joint>

      <!-- Joint 23: plato_joint5 -->
      <joint name="plato_joint5" type="revolute">
        <origin rpy="-1.5707963267948972241 4.9960036108132044319e-16 1.5707963267948961139" xyz="-0.004999999999999539535 0.028149999999999578137 -0.0098999999999999799966"/>
        <parent link="plato_bracket_2"/>
        <child link="plato_proximal_2"/>
        <axis xyz="0 0 1"/>
        <limit effort="0.06" lower="-0.87266462599716476678" upper="0.87266462599716476678" velocity="0.0872665"/>
        <joint_properties friction="0.03"/>
      </joint>

      <!-- Joint 24: plato_joint6 -->
      <joint name="plato_joint6" type="revolute">
        <origin rpy="1.280885172630899511e-14 -7.2307898014349294445e-15 -1.0713652187632538156e-14" xyz="0.04800000000000018141 4.4980837630992365206e-17 -0.0029000000000003675615"/>
        <parent link="plato_proximal_2"/>
        <child link="plato_distal_2"/>
        <axis xyz="0 0 1"/>
        <limit effort="0.06" lower="-1.570796326794896558" upper="0.0" velocity="0.0872665"/>
        <joint_properties friction="0.03"/>
      </joint>

      <!-- Joint 25: plato_ee_joint2 -->
      <joint name="plato_ee_joint2" type="fixed">
        <origin rpy="-1.5707 0.0 0.0" xyz="0.05060 0.0 0.0"/>
        <parent link="plato_distal_2"/>
        <child link="plato_end_effector_2"/>
      </joint>

      <!-- Joint 26: plato_joint7 -->
      <joint name="plato_joint7" type="revolute">
        <origin rpy="-3.1415926535897917837 -9.7144514654701000072e-17 1.5655578416789044383" xyz="0.08399999999999986644 -0.030000000000000463796 -0.010000000000000050515"/>
        <parent link="plato_base_link"/>
        <child link="plato_bracket_3"/>
        <axis xyz="0 0 1"/>
        <limit effort="0.06" lower="-0.087266462599716473902" upper="0.087266462599716473902" velocity="0.0872665"/>
        <joint_properties friction="0.03"/>
      </joint>

      <!-- Joint 27: plato_joint8 -->
      <joint name="plato_joint8" type="revolute">
        <origin rpy="-1.570796326794896558 4.9960036108133148724e-16 1.5707963267949323072" xyz="-0.0050000000000000044409 0.028149999999999952838 -0.0099000000000000112216"/>
        <parent link="plato_bracket_3"/>
        <child link="plato_proximal_3"/>
        <axis xyz="0 0 1"/>
        <limit effort="0.06" lower="-0.87266462599716476678" upper="0.87266462599716476678" velocity="0.0872665"/>
        <joint_properties friction="0.03"/>
      </joint>

      <!-- Joint 28: plato_joint9 -->
      <joint name="plato_joint9" type="revolute">
        <origin rpy="8.673424925565731141e-16 3.5169650820948147417e-14 -1.6319559976759880709e-29" xyz="0.047999999999999709566 -1.6328084717631696776e-16 -0.0029000000000011100232"/>
        <parent link="plato_proximal_3"/>
        <child link="plato_distal_3"/>
        <axis xyz="0 0 1"/>
        <limit effort="0.06" lower="-1.570796326794896558" upper="0.0" velocity="0.0872665"/>
        <joint_properties friction="0.01"/>
      </joint>

      <!-- Joint 29: plato_ee_joint3 -->
      <joint name="plato_ee_joint3" type="fixed">
        <origin rpy="-1.5707 0.0 0.0" xyz="0.05060 0.0 0.0"/>
        <parent link="plato_distal_3"/>
        <child link="plato_end_effector_3"/>
      </joint>

  </robot>



