<?xml version="1.0" ?>
<!-- =================================================================================== -->
<!-- |    This document was autogenerated by xacro from optimo.urdf.xacro              | -->
<!-- |    EDITING THIS FILE BY HAND IS NOT RECOMMENDED                                 | -->
<!-- =================================================================================== -->
<robot name="optimo">

    <!-- Color Parameters -->
  <material name="white">
    <color rgba="1.0 1.0 1.0 1.0"/>
  </material>
  <material name="blue">
    <color rgba="0.5 0.5 1 1.0"/>
  </material>

  <!-- Pedestal -->
    <link name="optimo_pedestal">
      <visual>
        <geometry>
          <box size="0.3 0.3 1.0"/>
        </geometry>
        <material name="white"/>
      </visual>
      <collision>
        <geometry>
          <box size="0.3 0.3 1.0"/>
        </geometry>
      </collision>
      <inertial>
        <mass value="1.0"/>
        <inertia ixx="0.0" ixy="0.0" ixz="0.0" iyy="0.0" iyz="0.0" izz="0.0"/>
      </inertial>
    </link>


  <!-- Optimo Robot Arm Links -->
    <!-- Link0: optimo_base_link -->
    <link name="optimo_base_link">
      <visual>
        <geometry>
          <sphere radius="0.01"/>
        </geometry>
      </visual>
      <inertial>
        <origin xyz="0 0 0"/>
        <mass value="0.0"/>
        <inertia ixx="0.0" ixy="0.0" ixz="0.0" iyy="0.0" iyz="0.0" izz="0.0"/>
      </inertial>
    </link>

    <!-- Link1 : optimo_link0 -->
    <link name="optimo_link0">
      <visual>
        <geometry>
          <mesh filename="package://meshes/link0.stl"/>
        </geometry>
        <material name="blue"/>
      </visual>
      <collision>
        <geometry>
          <mesh filename="package://meshes/col0.stl"/>
        </geometry>
      </collision>
      <inertial>
        <!-- Doesn't matter, just placeholder values -->
        <origin xyz="0 0 0"/>
        <mass value="1"/>
        <inertia ixx="0" ixy="0.0" ixz="0.0" iyy="0" iyz="0.0" izz="0"/>
      </inertial>
    </link>

    <!-- Link2 : optimo_link1 -->
    <link name="optimo_link1">
      <inertial>
        <origin xyz="0 0 0"/>
        <mass value="0.0"/>
        <inertia ixx="0.0" ixy="0.0" ixz="0.0" iyy="0.0" iyz="0.0" izz="0.0"/>
      </inertial>
    </link>
    <!-- Link3 : optimo_link1_passive-->
    <link name="optimo_link1_passive">
      <visual>
        <geometry>
          <mesh filename="package://meshes/link1.stl"/>
        </geometry>
        <material name="white"/>
      </visual>
      <collision>
        <geometry>
          <mesh filename="package://meshes/col1.stl"/>
        </geometry>
      </collision>
      <inertial>
        <origin xyz="0 -0.01635 0.01549"/>
        <mass value="4.152"/>
        <inertia ixx="0.01" ixy="0.000017" ixz="-.00001" iyy="0.007494" iyz="0.0000213" izz="0.009939"/>
      </inertial>
    </link>

    <!-- Link4 : optimo_link2 -->
    <link name="optimo_link2">
      <inertial>
        <origin xyz="0 0 0"/>
        <mass value="0.0"/>
        <inertia ixx="0.0" ixy="0.0" ixz="0.0" iyy="0.0" iyz="0.0" izz="0.0"/>
      </inertial>
    </link>
    <!-- Link5 : optimo_link2_passive -->
    <link name="optimo_link2_passive">
      <visual>
        <geometry>
          <mesh filename="package://meshes/link2.stl"/>
        </geometry>
        <material name="blue"/>
      </visual>
      <collision>
        <geometry>
          <mesh filename="package://meshes/col2.stl"/>
        </geometry>
      </collision>
      <inertial>
        <origin xyz="0 -0.05063 0.05677"/>
        <mass value="1.72"/>
        <inertia ixx="0.005694" ixy="0" ixz="0" iyy="0.005902" iyz="-0.001353" izz="0.002415"/>
      </inertial>
    </link>

    <!-- Link6 : optimo_link3 -->
    <link name="optimo_link3">
      <inertial>
        <origin xyz="0 0 0"/>
        <mass value="0.0"/>
        <inertia ixx="0.0" ixy="0.0" ixz="0.0" iyy="0.0" iyz="0.0" izz="0.0"/>
      </inertial>
    </link>
    <!-- Link7 : optimo_link3_passive -->
    <link name="optimo_link3_passive">
      <visual>
        <geometry>
          <mesh filename="package://meshes/link3.stl"/>
        </geometry>
        <material name="white"/>
      </visual>
      <collision>
        <geometry>
          <mesh filename="package://meshes/col3.stl"/>
        </geometry>
      </collision>
      <inertial>
        <origin xyz="-0.000039 .098 0"/>
        <mass value="4.310"/>
        <inertia ixx="0.012989" ixy="-0.000015" ixz="-.000003" iyy="0.002584" iyz="0.000632" izz="0.01305"/>
      </inertial>
    </link>

    <!-- Link8 : optimo_link4 -->
    <link name="optimo_link4">
      <inertial>
        <origin xyz="0 0 0"/>
        <mass value="0.0"/>
        <inertia ixx="0.0" ixy="0.0" ixz="0.0" iyy="0.0" iyz="0.0" izz="0.0"/>
      </inertial>
    </link>
    <!-- Link9 : optimo_link4_passive -->
    <link name="optimo_link4_passive">
      <origin rpy="0 0 0" xyz="0 0 0"/>
      <visual>
        <geometry>
          <mesh filename="package://meshes/link4.stl"/>
        </geometry>
        <material name="blue"/>
      </visual>
      <collision>
        <geometry>
          <mesh filename="package://meshes/col4.stl"/>
        </geometry>
      </collision>
      <inertial>
        <origin rpy="0 0 0" xyz="-.00001 0.048852 0.0688"/>
        <mass value="1.09"/>
        <inertia ixx="0.004297" ixy="0" ixz="0" iyy="0.004366" iyz="0.0008" izz="0.000988"/>
      </inertial>
    </link>

    <!-- Link10 : optimo_link5 -->
    <link name="optimo_link5">
      <inertial>
        <origin xyz="0 0 0"/>
        <mass value="0.0"/>
        <inertia ixx="0.0" ixy="0.0" ixz="0.0" iyy="0.0" iyz="0.0" izz="0.0"/>
      </inertial>
    </link>
    <!-- Link11 : optimo_link5_passive -->
    <link name="optimo_link5_passive">
      <visual>
        <geometry>
          <mesh filename="package://meshes/link5.stl"/>
        </geometry>
        <material name="white"/>
      </visual>
      <collision>
        <geometry>
          <mesh filename="package://meshes/col5.stl"/>
        </geometry>
      </collision>
      <inertial>
        <origin xyz=".001262 0.085 0.008"/>
        <mass value="2.23"/>
        <inertia ixx="0.005744" ixy="-0.00021" ixz="-0.000027" iyy="0.0018" iyz="0.001278" izz="0.005457"/>
      </inertial>
    </link>

    <!-- Link12 : optimo_link6 -->
    <link name="optimo_link6">
      <inertial>
        <origin xyz="0 0 0"/>
        <mass value="0.0"/>
        <inertia ixx="0.0" ixy="0.0" ixz="0.0" iyy="0.0" iyz="0.0" izz="0.0"/>
      </inertial>
    </link>
    <!-- Link13 : optimo_link6_passive -->
    <link name="optimo_link6_passive">
      <visual>
        <geometry>
          <mesh filename="package://meshes/link6.stl"/>
        </geometry>
        <material name="blue"/>
      </visual>
      <collision>
        <geometry>
          <mesh filename="package://meshes/col6.stl"/>
        </geometry>
      </collision>
      <inertial>
        <origin xyz="0 -0.00007 0.010855"/>
        <mass value="1.138"/>
        <inertia ixx="0.000634" ixy="0" ixz="0" iyy="0.000629" iyz="0" izz="0.000546"/>
      </inertial>
    </link>

    <!-- Link14 : optimo_link7 -->
    <link name="optimo_link7">
      <inertial>
        <origin xyz="0 0 0"/>
        <mass value="0.0"/>
        <inertia ixx="0.0" ixy="0.0" ixz="0.0" iyy="0.0" iyz="0.0" izz="0.0"/>
      </inertial>
    </link>
    <!-- Link15 : optimo_link7_passive -->
    <link name="optimo_link7_passive">
      <visual>
        <geometry>
          <mesh filename="package://meshes/link7.stl"/>
        </geometry>
        <material name="white"/>
      </visual>
      <collision>
        <geometry>
          <mesh filename="package://meshes/col7.stl"/>
        </geometry>
      </collision>
      <inertial>
        <origin xyz="0 0 0.2"/>
        <mass value="1.246"/>
        <inertia ixx="0.005541" ixy=".000045" ixz="0.000077" iyy="0.004779" iyz="0.000043" izz="0.001723"/>
      </inertial>
    </link>

    <!-- Link16 : optimo_ee_link -->
    <link name="optimo_ee_link">
      <inertial>
        <origin xyz="0 0 0"/>
        <mass value="0.0"/>
        <inertia ixx="0.0" ixy="0.0" ixz="0.0" iyy="0.0" iyz="0.0" izz="0.0"/>
      </inertial>
    </link>



  <!-- Optimo Joints -->

    <!-- Joint0: optimo_pedestal_joint -->
    <joint name="optimo_pedestal_joint" type="fixed">
      <parent link="optimo_pedestal"/>
      <child link="optimo_base_link"/>
      <origin xyz="0 0 0.50" rpy="0 0 0"/>
    </joint>

    <!-- Joint1: optimo_base_joint -->
    <joint name="optimo_base_joint" type="fixed">
      <parent link="optimo_base_link"/>
      <child link="optimo_link0"/>
      <origin rpy="0 0 0" xyz="0.0 0.0 0.27"/>
    </joint>


    <!-- Joint2: optimo_joint1 -->
    <joint name="optimo_joint1" type="revolute">
      <origin rpy="0 0 0" xyz="0 0 0"/>
      <parent link="optimo_link0"/>
      <child link="optimo_link1"/>
      <axis xyz="0 0 1"/>
      <limit effort="79" lower="-2.86233997164" upper="2.91469984917" velocity="10"/>
      <dynamics damping="1" friction="0.1"/>
    </joint>
    <!-- Joint3: optimo_joint1_passive -->
    <joint name="optimo_joint1_passive" type="fixed">
      <origin rpy="1.5707963267948966 0 0" xyz="0 0 0"/>
      <parent link="optimo_link1"/>
      <child link="optimo_link1_passive"/>
    </joint>


    <!-- Joint4: optimo_joint2 -->
    <joint name="optimo_joint2" type="revolute">
      <origin rpy="0 0 0" xyz="0 0 0"/>
      <parent link="optimo_link1_passive"/>
      <child link="optimo_link2"/>
      <axis xyz="0 0 1"/>
      <limit effort="95" lower="1.0471975506" upper="4.3633231275" velocity="10"/>
      <dynamics damping="1" friction="0.1"/>
    </joint>
    <!-- Joint5: optimo_joint2_passive -->
    <joint name="optimo_joint2_passive" type="fixed">
      <origin rpy="1.5707963267948966 0 0" xyz="0 0 0"/>
      <parent link="optimo_link2"/>
      <child link="optimo_link2_passive"/>
    </joint>


    <!-- Joint6: optimo_joint3 -->
    <joint name="optimo_joint3" type="revolute">
      <origin rpy="0 0 0" xyz="0 0 0.4"/>
      <parent link="optimo_link2_passive"/>
      <child link="optimo_link3"/>
      <axis xyz="0 0 1"/>
      <limit effort="32" lower="-2.91469984917" upper="2.84488667913" velocity="10"/>
      <dynamics damping="1" friction="0.1"/>
    </joint>
    <!-- Joint7: optimo_joint3_passive -->
    <joint name="optimo_joint3_passive" type="fixed">
      <origin rpy="-1.5707963267948966 0 0" xyz="0 0 0"/>
      <parent link="optimo_link3"/>
      <child link="optimo_link3_passive"/>
    </joint>

    <!-- Joint8: optimo_joint4 -->
    <joint name="optimo_joint4" type="revolute">
      <origin rpy="0 0 0" xyz="0 0 0"/>
      <parent link="optimo_link3_passive"/>
      <child link="optimo_link4"/>
      <axis xyz="0 0 1"/>
      <limit effort="40" lower="-2.53072741395" upper="2.53072741395" velocity="10"/>
      <dynamics damping="1" friction="0.1"/>
    </joint>
    <!-- Joint9: optimo_joint4_passive -->
    <joint name="optimo_joint4_passive" type="fixed">
      <origin rpy="1.5707963267948966 0 0" xyz="0 0 0"/>
      <parent link="optimo_link4"/>
      <child link="optimo_link4_passive"/>
    </joint>


    <!-- Joint10: optimo_joint5 -->
    <joint name="optimo_joint5" type="revolute">
      <origin rpy="0 0 0" xyz="0 0 0.4"/>
      <parent link="optimo_link4_passive"/>
      <child link="optimo_link5"/>
      <axis xyz="0 0 1"/>
      <limit effort="15" lower="-2.9670597267" upper="2.9670597267" velocity="10"/>
      <dynamics damping="1" friction="0.1"/>
    </joint>
    <!-- Joint11: optimo_joint5_passive -->
    <joint name="optimo_joint5_passive" type="fixed">
      <origin rpy="-1.5707963267948966 0 0" xyz="0 0 0"/>
      <parent link="optimo_link5"/>
      <child link="optimo_link5_passive"/>
    </joint>

    <!-- Joint12: optimo_joint6 -->
    <joint name="optimo_joint6" type="revolute">
      <origin rpy="0 0 0" xyz="0 0 0"/>
      <parent link="optimo_link5_passive"/>
      <child link="optimo_link6"/>
      <axis xyz="0 0 1"/>
      <limit effort="15" lower="-2.0943951012" upper="2.0943951012" velocity="10"/>
      <dynamics damping="1" friction="0.1"/>
    </joint>
    <!-- Joint13: optimo_joint6_passive -->
    <joint name="optimo_joint6_passive" type="fixed">
      <origin rpy="1.5707963267948966 0 0" xyz="0 0 0"/>
      <parent link="optimo_link6"/>
      <child link="optimo_link6_passive"/>
    </joint>

    <!-- Joint14: optimo_joint7 --> 
    <joint name="optimo_joint7" type="revolute">
      <origin rpy="0 0 0" xyz="0 0 0"/>
      <parent link="optimo_link6_passive"/>
      <child link="optimo_link7"/>
      <axis xyz="0 0 1"/>
      <limit effort="15" lower="-2.65290046152" upper="3.28121899188" velocity="10"/>
      <dynamics damping="1" friction="0.1"/>
    </joint>
    <!-- Joint15: optimo_joint7_passive -->
    <joint name="optimo_joint7_passive" type="fixed">
      <origin rpy="0 0 0" xyz="0 0 0"/>
      <parent link="optimo_link7"/>
      <child link="optimo_link7_passive"/>
    </joint>

    <!-- Joint16: optimo_ee_joint -->
    <joint name="optimo_ee_joint" type="fixed">
      <parent link="optimo_link7_passive"/>
      <child link="optimo_ee_link"/>
      <!-- <origin rpy="0 -1.5707 3.14" xyz="0 0 0.15"/> -->
      <origin rpy="0 0 0" xyz="0 0 0"/>
    </joint>

  </robot>



